Workbook
Name WebWps_Form: 报名表!$A$1:$M$123
Name WebWps_Form: #REF!
Name WebWps_Form: #REF!
Name WebWps_Form: #REF!
Name WebWps_Form: #REF!
Name WebWps_Form: #REF!
Name WebWps_Form: #REF!

Sheet 转会市场
A1: 2024年第二届梦幻联赛转会市场
A2: 队伍名称 | B2: 队伍资金 | C2: 剩余资金（单位：W） | D2: 账户状态 | E2: 队长名
A3: 【CbHz】吃饱喝足就是玩 | B3: ='队伍收入状况 '!D2 -> 2250 | C3: =B3-SUMIFS(交易历史!B:B,交易历史!C:C,A3,交易历史!E:E,"首轮交易")+SUMIFS(交易历史!B:B,交易历史!D:D,A3,交易历史!E:E,"首轮交易")-SUMIFS(交易历史!B:B,交易历史!C:C,A3,交易历史!E:E,"二轮交易")+SUMIFS(交易历史!B:B,交易历史!D:D,A3,交易历史!E:E,"二轮交易")-SUMIFS(交易历史!B:B,交易历史!C:C,A3,交易历史!E:E,"三轮交易")+SUMIFS(交易历史!B:B,交易历史!D:D,A3,交易历史!E:E,"三轮交易")-SUMIFS(交易历史!B:B,交易历史!C:C,A3,交易历史!E:E,"四轮交易")+SUMIFS(交易历史!B:B,交易历史!D:D,A3,交易历史!E:E,"四轮交易") -> 20 | D3: =IF(C3<=0,"超支",IF(C3<=500,"即将超支，剩余"&TEXT(C3,"0")&"W第纳尔","资金状况良好")) -> 即将超支，剩余20W第纳尔 | E3: 冲锋
A4: 【SSR】Superior Super Rare | B4: ='队伍收入状况 '!D3 -> 2550 | C4: =B4-SUMIFS(交易历史!B:B,交易历史!C:C,A4,交易历史!E:E,"首轮交易")+SUMIFS(交易历史!B:B,交易历史!D:D,A4,交易历史!E:E,"首轮交易")-SUMIFS(交易历史!B:B,交易历史!C:C,A4,交易历史!E:E,"二轮交易")+SUMIFS(交易历史!B:B,交易历史!D:D,A4,交易历史!E:E,"二轮交易")-SUMIFS(交易历史!B:B,交易历史!C:C,A4,交易历史!E:E,"三轮交易")+SUMIFS(交易历史!B:B,交易历史!D:D,A4,交易历史!E:E,"三轮交易")-SUMIFS(交易历史!B:B,交易历史!C:C,A4,交易历史!E:E,"四轮交易")+SUMIFS(交易历史!B:B,交易历史!D:D,A4,交易历史!E:E,"四轮交易") -> 0 | D4: =IF(C4<=0,"超支",IF(C4<=500,"即将超支，剩余"&TEXT(C4,"0")&"W第纳尔","资金状况良好")) -> 超支 | E4: 图派克
A5: 【OldH】老H犟嘴 | B5: ='队伍收入状况 '!D4 -> 2100 | C5: =B5-SUMIFS(交易历史!B:B,交易历史!C:C,A5,交易历史!E:E,"首轮交易")+SUMIFS(交易历史!B:B,交易历史!D:D,A5,交易历史!E:E,"首轮交易")-SUMIFS(交易历史!B:B,交易历史!C:C,A5,交易历史!E:E,"二轮交易")+SUMIFS(交易历史!B:B,交易历史!D:D,A5,交易历史!E:E,"二轮交易")-SUMIFS(交易历史!B:B,交易历史!C:C,A5,交易历史!E:E,"三轮交易")+SUMIFS(交易历史!B:B,交易历史!D:D,A5,交易历史!E:E,"三轮交易")-SUMIFS(交易历史!B:B,交易历史!C:C,A5,交易历史!E:E,"四轮交易")+SUMIFS(交易历史!B:B,交易历史!D:D,A5,交易历史!E:E,"四轮交易") -> 30 | D5: =IF(C5<=0,"超支",IF(C5<=500,"即将超支，剩余"&TEXT(C5,"0")&"W第纳尔","资金状况良好")) -> 即将超支，剩余30W第纳尔 | E5: 凯撒
A6: 【AWO】逃出生天 | B6: ='队伍收入状况 '!D5 -> 2200 | C6: =B6-SUMIFS(交易历史!B:B,交易历史!C:C,A6,交易历史!E:E,"首轮交易")+SUMIFS(交易历史!B:B,交易历史!D:D,A6,交易历史!E:E,"首轮交易")-SUMIFS(交易历史!B:B,交易历史!C:C,A6,交易历史!E:E,"二轮交易")+SUMIFS(交易历史!B:B,交易历史!D:D,A6,交易历史!E:E,"二轮交易")-SUMIFS(交易历史!B:B,交易历史!C:C,A6,交易历史!E:E,"三轮交易")+SUMIFS(交易历史!B:B,交易历史!D:D,A6,交易历史!E:E,"三轮交易")-SUMIFS(交易历史!B:B,交易历史!C:C,A6,交易历史!E:E,"四轮交易")+SUMIFS(交易历史!B:B,交易历史!D:D,A6,交易历史!E:E,"四轮交易") -> 630 | D6: =IF(C6<=0,"超支",IF(C6<=500,"即将超支，剩余"&TEXT(C6,"0")&"W第纳尔","资金状况良好")) -> 资金状况良好 | E6: 小山楂
A7: 【G2】G2‭ | B7: ='队伍收入状况 '!D6 -> 2200 | C7: =B7-SUMIFS(交易历史!B:B,交易历史!C:C,A7,交易历史!E:E,"首轮交易")+SUMIFS(交易历史!B:B,交易历史!D:D,A7,交易历史!E:E,"首轮交易")-SUMIFS(交易历史!B:B,交易历史!C:C,A7,交易历史!E:E,"二轮交易")+SUMIFS(交易历史!B:B,交易历史!D:D,A7,交易历史!E:E,"二轮交易")-SUMIFS(交易历史!B:B,交易历史!C:C,A7,交易历史!E:E,"三轮交易")+SUMIFS(交易历史!B:B,交易历史!D:D,A7,交易历史!E:E,"三轮交易")-SUMIFS(交易历史!B:B,交易历史!C:C,A7,交易历史!E:E,"四轮交易")+SUMIFS(交易历史!B:B,交易历史!D:D,A7,交易历史!E:E,"四轮交易") -> 90 | D7: =IF(C7<=0,"超支",IF(C7<=500,"即将超支，剩余"&TEXT(C7,"0")&"W第纳尔","资金状况良好")) -> 即将超支，剩余90W第纳尔 | E7: 米子
A8: 【TV】Team Vitality | B8: ='队伍收入状况 '!D7 -> 2200 | C8: =B8-SUMIFS(交易历史!B:B,交易历史!C:C,A8,交易历史!E:E,"首轮交易")+SUMIFS(交易历史!B:B,交易历史!D:D,A8,交易历史!E:E,"首轮交易")-SUMIFS(交易历史!B:B,交易历史!C:C,A8,交易历史!E:E,"二轮交易")+SUMIFS(交易历史!B:B,交易历史!D:D,A8,交易历史!E:E,"二轮交易")-SUMIFS(交易历史!B:B,交易历史!C:C,A8,交易历史!E:E,"三轮交易")+SUMIFS(交易历史!B:B,交易历史!D:D,A8,交易历史!E:E,"三轮交易")-SUMIFS(交易历史!B:B,交易历史!C:C,A8,交易历史!E:E,"四轮交易")+SUMIFS(交易历史!B:B,交易历史!D:D,A8,交易历史!E:E,"四轮交易") -> 90 | D8: =IF(C8<=0,"超支",IF(C8<=500,"即将超支，剩余"&TEXT(C8,"0")&"W第纳尔","资金状况良好")) -> 即将超支，剩余90W第纳尔 | E8: 赵毅
A9: 【Miniworld】迷你世界 | B9: ='队伍收入状况 '!D8 -> 2750 | C9: =B9-SUMIFS(交易历史!B:B,交易历史!C:C,A9,交易历史!E:E,"首轮交易")+SUMIFS(交易历史!B:B,交易历史!D:D,A9,交易历史!E:E,"首轮交易")-SUMIFS(交易历史!B:B,交易历史!C:C,A9,交易历史!E:E,"二轮交易")+SUMIFS(交易历史!B:B,交易历史!D:D,A9,交易历史!E:E,"二轮交易")-SUMIFS(交易历史!B:B,交易历史!C:C,A9,交易历史!E:E,"三轮交易")+SUMIFS(交易历史!B:B,交易历史!D:D,A9,交易历史!E:E,"三轮交易")-SUMIFS(交易历史!B:B,交易历史!C:C,A9,交易历史!E:E,"四轮交易")+SUMIFS(交易历史!B:B,交易历史!D:D,A9,交易历史!E:E,"四轮交易") -> 650 | D9: =IF(C9<=0,"超支",IF(C9<=500,"即将超支，剩余"&TEXT(C9,"0")&"W第纳尔","资金状况良好")) -> 资金状况良好 | E9: nane
A10: 【NikoFC】NikoCN Fanclub | B10: ='队伍收入状况 '!D9 -> 2700 | C10: =B10-SUMIFS(交易历史!B:B,交易历史!C:C,A10,交易历史!E:E,"首轮交易")+SUMIFS(交易历史!B:B,交易历史!D:D,A10,交易历史!E:E,"首轮交易")-SUMIFS(交易历史!B:B,交易历史!C:C,A10,交易历史!E:E,"二轮交易")+SUMIFS(交易历史!B:B,交易历史!D:D,A10,交易历史!E:E,"二轮交易")-SUMIFS(交易历史!B:B,交易历史!C:C,A10,交易历史!E:E,"三轮交易")+SUMIFS(交易历史!B:B,交易历史!D:D,A10,交易历史!E:E,"三轮交易")-SUMIFS(交易历史!B:B,交易历史!C:C,A10,交易历史!E:E,"四轮交易")+SUMIFS(交易历史!B:B,交易历史!D:D,A10,交易历史!E:E,"四轮交易") -> 360 | D10: =IF(C10<=0,"超支",IF(C10<=500,"即将超支，剩余"&TEXT(C10,"0")&"W第纳尔","资金状况良好")) -> 即将超支，剩余360W第纳尔 | E10: 梅森
A11: 常用昵称 | B11: 报名ID | C11: 最高身价（单位：W） | D11: 当前队伍 | E11: 球员目前状态
A12: xiaoliyu | B12: JackeyLove | C12: =_xlfn.MAXIFS(交易历史!B:B,交易历史!A:A,A12) -> 0 | D12: =INDEX(交易历史!C:C,MATCH(A12,交易历史!A:A,0)) -> 【G2】G2‭ | E12: =IF(AND(NOT(ISBLANK(C12)),NOT(ISBLANK(D12)),ISERROR(SEARCH("流拍待定",D12))),"球员已拍定",IF(ISNUMBER(SEARCH("流拍待定",D12)),"流拍待定",IF(AND(OR(ISBLANK(C12),ISBLANK(D12)),NOT(ISBLANK(C11)),NOT(ISBLANK(D11))),"正在竞拍",""))) -> 球员已拍定
A13: 小鱼 | B13: 18SadYu | C13: =_xlfn.MAXIFS(交易历史!B:B,交易历史!A:A,A13) -> 80 | D13: =INDEX(交易历史!C:C,MATCH(A13,交易历史!A:A,0)) -> 【SSR】Superior Super Rare | E13: =IF(AND(NOT(ISBLANK(C13)),NOT(ISBLANK(D13)),ISERROR(SEARCH("流拍待定",D13))),"球员已拍定",IF(ISNUMBER(SEARCH("流拍待定",D13)),"流拍待定",IF(AND(OR(ISBLANK(C13),ISBLANK(D13)),NOT(ISBLANK(C12)),NOT(ISBLANK(D12))),"正在竞拍",""))) -> 球员已拍定
A14: Mengdong | B14: Mengdong | C14: =_xlfn.MAXIFS(交易历史!B:B,交易历史!A:A,A14) -> 0 | D14: =INDEX(交易历史!C:C,MATCH(A14,交易历史!A:A,0)) -> 【AWO】逃出生天 | E14: =IF(AND(NOT(ISBLANK(C14)),NOT(ISBLANK(D14)),ISERROR(SEARCH("流拍待定",D14))),"球员已拍定",IF(ISNUMBER(SEARCH("流拍待定",D14)),"流拍待定",IF(AND(OR(ISBLANK(C14),ISBLANK(D14)),NOT(ISBLANK(C13)),NOT(ISBLANK(D13))),"正在竞拍",""))) -> 球员已拍定
A15: awe23 | B15: Lezafans | C15: =_xlfn.MAXIFS(交易历史!B:B,交易历史!A:A,A15) -> 320 | D15: =INDEX(交易历史!C:C,MATCH(A15,交易历史!A:A,0)) -> 【NikoFC】NikoCN Fanclub | E15: =IF(AND(NOT(ISBLANK(C15)),NOT(ISBLANK(D15)),ISERROR(SEARCH("流拍待定",D15))),"球员已拍定",IF(ISNUMBER(SEARCH("流拍待定",D15)),"流拍待定",IF(AND(OR(ISBLANK(C15),ISBLANK(D15)),NOT(ISBLANK(C14)),NOT(ISBLANK(D14))),"正在竞拍",""))) -> 球员已拍定
A16: 史蒂夫 | B16: [Vinland]Steve | C16: =_xlfn.MAXIFS(交易历史!B:B,交易历史!A:A,A16) -> 400 | D16: =INDEX(交易历史!C:C,MATCH(A16,交易历史!A:A,0)) -> 【SSR】Superior Super Rare | E16: =IF(AND(NOT(ISBLANK(C16)),NOT(ISBLANK(D16)),ISERROR(SEARCH("流拍待定",D16))),"球员已拍定",IF(ISNUMBER(SEARCH("流拍待定",D16)),"流拍待定",IF(AND(OR(ISBLANK(C16),ISBLANK(D16)),NOT(ISBLANK(C15)),NOT(ISBLANK(D15))),"正在竞拍",""))) -> 球员已拍定
A17: f4 | B17: quandouwushILing | C17: =_xlfn.MAXIFS(交易历史!B:B,交易历史!A:A,A17) -> 600 | D17: =INDEX(交易历史!C:C,MATCH(A17,交易历史!A:A,0)) -> 【TV】Team Vitality | E17: =IF(AND(NOT(ISBLANK(C17)),NOT(ISBLANK(D17)),ISERROR(SEARCH("流拍待定",D17))),"球员已拍定",IF(ISNUMBER(SEARCH("流拍待定",D17)),"流拍待定",IF(AND(OR(ISBLANK(C17),ISBLANK(D17)),NOT(ISBLANK(C16)),NOT(ISBLANK(D16))),"正在竞拍",""))) -> 球员已拍定
A18: Bonaoart | B18: Bonapart | C18: =_xlfn.MAXIFS(交易历史!B:B,交易历史!A:A,A18) -> 100 | D18: =INDEX(交易历史!C:C,MATCH(A18,交易历史!A:A,0)) -> 【NikoFC】NikoCN Fanclub | E18: =IF(AND(NOT(ISBLANK(C18)),NOT(ISBLANK(D18)),ISERROR(SEARCH("流拍待定",D18))),"球员已拍定",IF(ISNUMBER(SEARCH("流拍待定",D18)),"流拍待定",IF(AND(OR(ISBLANK(C18),ISBLANK(D18)),NOT(ISBLANK(C17)),NOT(ISBLANK(D17))),"正在竞拍",""))) -> 球员已拍定
A19: 哭丧 | B19: KUSANAGE | C19: =_xlfn.MAXIFS(交易历史!B:B,交易历史!A:A,A19) -> 80 | D19: =INDEX(交易历史!C:C,MATCH(A19,交易历史!A:A,0)) -> 【Miniworld】迷你世界 | E19: =IF(AND(NOT(ISBLANK(C19)),NOT(ISBLANK(D19)),ISERROR(SEARCH("流拍待定",D19))),"球员已拍定",IF(ISNUMBER(SEARCH("流拍待定",D19)),"流拍待定",IF(AND(OR(ISBLANK(C19),ISBLANK(D19)),NOT(ISBLANK(#REF!)),NOT(ISBLANK(#REF!))),"正在竞拍",""))) -> 球员已拍定
A20: abin | B20: abin | C20: =_xlfn.MAXIFS(交易历史!B:B,交易历史!A:A,A20) -> 10 | D20: =INDEX(交易历史!C:C,MATCH(A20,交易历史!A:A,0)) -> 【TV】Team Vitality | E20: =IF(AND(NOT(ISBLANK(C20)),NOT(ISBLANK(D20)),ISERROR(SEARCH("流拍待定",D20))),"球员已拍定",IF(ISNUMBER(SEARCH("流拍待定",D20)),"流拍待定",IF(AND(OR(ISBLANK(C20),ISBLANK(D20)),NOT(ISBLANK(C19)),NOT(ISBLANK(D19))),"正在竞拍",""))) -> 球员已拍定
A21: GJY | B21: Ak King | C21: =_xlfn.MAXIFS(交易历史!B:B,交易历史!A:A,A21) -> 0 | D21: =INDEX(交易历史!C:C,MATCH(A21,交易历史!A:A,0)) -> 【CbHz】吃饱喝足就是玩 | E21: =IF(AND(NOT(ISBLANK(C21)),NOT(ISBLANK(D21)),ISERROR(SEARCH("流拍待定",D21))),"球员已拍定",IF(ISNUMBER(SEARCH("流拍待定",D21)),"流拍待定",IF(AND(OR(ISBLANK(C21),ISBLANK(D21)),NOT(ISBLANK(C20)),NOT(ISBLANK(D20))),"正在竞拍",""))) -> 球员已拍定
A22: AP-20 | B22: AP-20 | C22: =_xlfn.MAXIFS(交易历史!B:B,交易历史!A:A,A22) -> 20 | D22: =INDEX(交易历史!C:C,MATCH(A22,交易历史!A:A,0)) -> 【TV】Team Vitality | E22: =IF(AND(NOT(ISBLANK(C22)),NOT(ISBLANK(D22)),ISERROR(SEARCH("流拍待定",D22))),"球员已拍定",IF(ISNUMBER(SEARCH("流拍待定",D22)),"流拍待定",IF(AND(OR(ISBLANK(C22),ISBLANK(D22)),NOT(ISBLANK(C21)),NOT(ISBLANK(D21))),"正在竞拍",""))) -> 球员已拍定
A23: 王水灵 | B23: wsl | C23: =_xlfn.MAXIFS(交易历史!B:B,交易历史!A:A,A23) -> 10 | D23: =INDEX(交易历史!C:C,MATCH(A23,交易历史!A:A,0)) -> 【SSR】Superior Super Rare | E23: =IF(AND(NOT(ISBLANK(C23)),NOT(ISBLANK(D23)),ISERROR(SEARCH("流拍待定",D23))),"球员已拍定",IF(ISNUMBER(SEARCH("流拍待定",D23)),"流拍待定",IF(AND(OR(ISBLANK(C23),ISBLANK(D23)),NOT(ISBLANK(C22)),NOT(ISBLANK(D22))),"正在竞拍",""))) -> 球员已拍定
A24: 豆子 | B24: HeiAnZhiWang | C24: =_xlfn.MAXIFS(交易历史!B:B,交易历史!A:A,A24) -> 660 | D24: =INDEX(交易历史!C:C,MATCH(A24,交易历史!A:A,0)) -> 【CbHz】吃饱喝足就是玩 | E24: =IF(AND(NOT(ISBLANK(C24)),NOT(ISBLANK(D24)),ISERROR(SEARCH("流拍待定",D24))),"球员已拍定",IF(ISNUMBER(SEARCH("流拍待定",D24)),"流拍待定",IF(AND(OR(ISBLANK(C24),ISBLANK(D24)),NOT(ISBLANK(C23)),NOT(ISBLANK(D23))),"正在竞拍",""))) -> 球员已拍定
A25: 果猫 | B25: sichuanmei | C25: =_xlfn.MAXIFS(交易历史!B:B,交易历史!A:A,A25) -> 540 | D25: =INDEX(交易历史!C:C,MATCH(A25,交易历史!A:A,0)) -> 【NikoFC】NikoCN Fanclub | E25: =IF(AND(NOT(ISBLANK(C25)),NOT(ISBLANK(D25)),ISERROR(SEARCH("流拍待定",D25))),"球员已拍定",IF(ISNUMBER(SEARCH("流拍待定",D25)),"流拍待定",IF(AND(OR(ISBLANK(C25),ISBLANK(D25)),NOT(ISBLANK(C24)),NOT(ISBLANK(D24))),"正在竞拍",""))) -> 球员已拍定
A26: 233laoye | B26: Super_Seal | C26: =_xlfn.MAXIFS(交易历史!B:B,交易历史!A:A,A26) -> 1000 | D26: =INDEX(交易历史!C:C,MATCH(A26,交易历史!A:A,0)) -> 【G2】G2‭ | E26: =IF(AND(NOT(ISBLANK(C26)),NOT(ISBLANK(D26)),ISERROR(SEARCH("流拍待定",D26))),"球员已拍定",IF(ISNUMBER(SEARCH("流拍待定",D26)),"流拍待定",IF(AND(OR(ISBLANK(C26),ISBLANK(D26)),NOT(ISBLANK(C25)),NOT(ISBLANK(D25))),"正在竞拍",""))) -> 球员已拍定
A27: Tatum | B27: Tatum | C27: =_xlfn.MAXIFS(交易历史!B:B,交易历史!A:A,A27) -> 350 | D27: =INDEX(交易历史!C:C,MATCH(A27,交易历史!A:A,0)) -> 【Miniworld】迷你世界 | E27: =IF(AND(NOT(ISBLANK(C27)),NOT(ISBLANK(D27)),ISERROR(SEARCH("流拍待定",D27))),"球员已拍定",IF(ISNUMBER(SEARCH("流拍待定",D27)),"流拍待定",IF(AND(OR(ISBLANK(C27),ISBLANK(D27)),NOT(ISBLANK(C26)),NOT(ISBLANK(D26))),"正在竞拍",""))) -> 球员已拍定
A28: KillerQuin | B28: qifenzu | C28: =_xlfn.MAXIFS(交易历史!B:B,交易历史!A:A,A28) -> 20 | D28: =INDEX(交易历史!C:C,MATCH(A28,交易历史!A:A,0)) -> 【Miniworld】迷你世界 | E28: =IF(AND(NOT(ISBLANK(C28)),NOT(ISBLANK(D28)),ISERROR(SEARCH("流拍待定",D28))),"球员已拍定",IF(ISNUMBER(SEARCH("流拍待定",D28)),"流拍待定",IF(AND(OR(ISBLANK(C28),ISBLANK(D28)),NOT(ISBLANK(C27)),NOT(ISBLANK(D27))),"正在竞拍",""))) -> 球员已拍定
A29: 罗加 | B29: ZhouBaiYa | C29: =_xlfn.MAXIFS(交易历史!B:B,交易历史!A:A,A29) -> 0 | D29: =INDEX(交易历史!C:C,MATCH(A29,交易历史!A:A,0)) -> 【CbHz】吃饱喝足就是玩 | E29: =IF(AND(NOT(ISBLANK(C29)),NOT(ISBLANK(D29)),ISERROR(SEARCH("流拍待定",D29))),"球员已拍定",IF(ISNUMBER(SEARCH("流拍待定",D29)),"流拍待定",IF(AND(OR(ISBLANK(C29),ISBLANK(D29)),NOT(ISBLANK(C28)),NOT(ISBLANK(D28))),"正在竞拍",""))) -> 球员已拍定
A30: Luvv | B30: 05 | C30: =_xlfn.MAXIFS(交易历史!B:B,交易历史!A:A,A30) -> 200 | D30: =INDEX(交易历史!C:C,MATCH(A30,交易历史!A:A,0)) -> 【SSR】Superior Super Rare | E30: =IF(AND(NOT(ISBLANK(C30)),NOT(ISBLANK(D30)),ISERROR(SEARCH("流拍待定",D30))),"球员已拍定",IF(ISNUMBER(SEARCH("流拍待定",D30)),"流拍待定",IF(AND(OR(ISBLANK(C30),ISBLANK(D30)),NOT(ISBLANK(C29)),NOT(ISBLANK(D29))),"正在竞拍",""))) -> 球员已拍定
A31: 老鱼 | B31: 566 | C31: =_xlfn.MAXIFS(交易历史!B:B,交易历史!A:A,A31) -> 40 | D31: =INDEX(交易历史!C:C,MATCH(A31,交易历史!A:A,0)) -> 【Miniworld】迷你世界 | E31: =IF(AND(NOT(ISBLANK(C31)),NOT(ISBLANK(D31)),ISERROR(SEARCH("流拍待定",D31))),"球员已拍定",IF(ISNUMBER(SEARCH("流拍待定",D31)),"流拍待定",IF(AND(OR(ISBLANK(C31),ISBLANK(D31)),NOT(ISBLANK(C30)),NOT(ISBLANK(D30))),"正在竞拍",""))) -> 球员已拍定
... A66: Able | B66: Workwork | C66: =_xlfn.MAXIFS(交易历史!B:B,交易历史!A:A,A66) -> 410 | D66: =INDEX(交易历史!C:C,MATCH(A66,交易历史!A:A,0)) -> 【SSR】Superior Super Rare | E66: =IF(AND(NOT(ISBLANK(C66)),NOT(ISBLANK(D66)),ISERROR(SEARCH("流拍待定",D66))),"球员已拍定",IF(ISNUMBER(SEARCH("流拍待定",D66)),"流拍待定",IF(AND(OR(ISBLANK(C66),ISBLANK(D66)),NOT(ISBLANK(C65)),NOT(ISBLANK(D65))),"正在竞拍",""))) -> 球员已拍定
A67: 末影 | B67: lxclxc | C67: =_xlfn.MAXIFS(交易历史!B:B,交易历史!A:A,A67) -> 190 | D67: =INDEX(交易历史!C:C,MATCH(A67,交易历史!A:A,0)) -> 【G2】G2‭ | E67: =IF(AND(NOT(ISBLANK(C67)),NOT(ISBLANK(D67)),ISERROR(SEARCH("流拍待定",D67))),"球员已拍定",IF(ISNUMBER(SEARCH("流拍待定",D67)),"流拍待定",IF(AND(OR(ISBLANK(C67),ISBLANK(D67)),NOT(ISBLANK(#REF!)),NOT(ISBLANK(#REF!))),"正在竞拍",""))) -> 球员已拍定
A68: 城府 | B68: Jinzhaojianzhidieyunchu | C68: =_xlfn.MAXIFS(交易历史!B:B,交易历史!A:A,A68) -> 190 | D68: =INDEX(交易历史!C:C,MATCH(A68,交易历史!A:A,0)) -> 【AWO】逃出生天 | E68: =IF(AND(NOT(ISBLANK(C68)),NOT(ISBLANK(D68)),ISERROR(SEARCH("流拍待定",D68))),"球员已拍定",IF(ISNUMBER(SEARCH("流拍待定",D68)),"流拍待定",IF(AND(OR(ISBLANK(C68),ISBLANK(D68)),NOT(ISBLANK(C67)),NOT(ISBLANK(D67))),"正在竞拍",""))) -> 球员已拍定
A69: 苏雨晴 | B69: Elucoco | C69: =_xlfn.MAXIFS(交易历史!B:B,交易历史!A:A,A69) -> 350 | D69: =INDEX(交易历史!C:C,MATCH(A69,交易历史!A:A,0)) -> 【Miniworld】迷你世界 | E69: =IF(AND(NOT(ISBLANK(C69)),NOT(ISBLANK(D69)),ISERROR(SEARCH("流拍待定",D69))),"球员已拍定",IF(ISNUMBER(SEARCH("流拍待定",D69)),"流拍待定",IF(AND(OR(ISBLANK(C69),ISBLANK(D69)),NOT(ISBLANK(C68)),NOT(ISBLANK(D68))),"正在竞拍",""))) -> 球员已拍定
A70: Lezalit | B70: Yuukasama | C70: =_xlfn.MAXIFS(交易历史!B:B,交易历史!A:A,A70) -> 1000 | D70: =INDEX(交易历史!C:C,MATCH(A70,交易历史!A:A,0)) -> 【TV】Team Vitality | E70: =IF(AND(NOT(ISBLANK(C70)),NOT(ISBLANK(D70)),ISERROR(SEARCH("流拍待定",D70))),"球员已拍定",IF(ISNUMBER(SEARCH("流拍待定",D70)),"流拍待定",IF(AND(OR(ISBLANK(C70),ISBLANK(D70)),NOT(ISBLANK(C69)),NOT(ISBLANK(D69))),"正在竞拍",""))) -> 球员已拍定
A71: knightzz | B71: knightzz | C71: =_xlfn.MAXIFS(交易历史!B:B,交易历史!A:A,A71) -> 850 | D71: =INDEX(交易历史!C:C,MATCH(A71,交易历史!A:A,0)) -> 【AWO】逃出生天 | E71: =IF(AND(NOT(ISBLANK(C71)),NOT(ISBLANK(D71)),ISERROR(SEARCH("流拍待定",D71))),"球员已拍定",IF(ISNUMBER(SEARCH("流拍待定",D71)),"流拍待定",IF(AND(OR(ISBLANK(C71),ISBLANK(D71)),NOT(ISBLANK(C70)),NOT(ISBLANK(D70))),"正在竞拍",""))) -> 球员已拍定
A72: 天帝哥哥 | B72: TianDi | C72: =_xlfn.MAXIFS(交易历史!B:B,交易历史!A:A,A72) -> 10 | D72: =INDEX(交易历史!C:C,MATCH(A72,交易历史!A:A,0)) -> 【TV】Team Vitality | E72: =IF(AND(NOT(ISBLANK(C72)),NOT(ISBLANK(D72)),ISERROR(SEARCH("流拍待定",D72))),"球员已拍定",IF(ISNUMBER(SEARCH("流拍待定",D72)),"流拍待定",IF(AND(OR(ISBLANK(C72),ISBLANK(D72)),NOT(ISBLANK(C71)),NOT(ISBLANK(D71))),"正在竞拍",""))) -> 球员已拍定
A73: 冷夜 | B73: LengYe | C73: =_xlfn.MAXIFS(交易历史!B:B,交易历史!A:A,A73) -> 20 | D73: =INDEX(交易历史!C:C,MATCH(A73,交易历史!A:A,0)) -> 【TV】Team Vitality | E73: =IF(AND(NOT(ISBLANK(C73)),NOT(ISBLANK(D73)),ISERROR(SEARCH("流拍待定",D73))),"球员已拍定",IF(ISNUMBER(SEARCH("流拍待定",D73)),"流拍待定",IF(AND(OR(ISBLANK(C73),ISBLANK(D73)),NOT(ISBLANK(C72)),NOT(ISBLANK(D72))),"正在竞拍",""))) -> 球员已拍定
A74: 大聪明、呆呆 | B74: DaCongMing | C74: =_xlfn.MAXIFS(交易历史!B:B,交易历史!A:A,A74) -> 400 | D74: =INDEX(交易历史!C:C,MATCH(A74,交易历史!A:A,0)) -> 【G2】G2‭ | E74: =IF(AND(NOT(ISBLANK(C74)),NOT(ISBLANK(D74)),ISERROR(SEARCH("流拍待定",D74))),"球员已拍定",IF(ISNUMBER(SEARCH("流拍待定",D74)),"流拍待定",IF(AND(OR(ISBLANK(C74),ISBLANK(D74)),NOT(ISBLANK(C73)),NOT(ISBLANK(D73))),"正在竞拍",""))) -> 球员已拍定
...

Sheet 交易历史
A1: 2024年第二届梦幻联赛转会市场
A2: 队伍名称 | B2: 队伍资金 | C2: 剩余资金（单位：W） | D2: 账户状态 | E2: 队长名
A3: 【CbHz】吃饱喝足就是玩 | B3: ='队伍收入状况 '!D2 -> 2250 | C3: =B3-SUMIFS($B$11:$B$209,$C$11:$C$209,A3,$E$11:$E$209,"首轮交易")+SUMIFS($B$11:$B$209,$D$11:$D$209,A3,$E$11:$E$209,"首轮交易")-SUMIFS($B$11:$B$209,$C$11:$C$209,A3,$E$11:$E$209,"二轮交易")+SUMIFS($B$11:$B$209,$D$11:$D$209,A3,$E$11:$E$209,"二轮交易")-SUMIFS($B$11:$B$209,$C$11:$C$209,A3,$E$11:$E$209,"三轮交易")+SUMIFS($B$11:$B$209,$D$11:$D$209,A3,$E$11:$E$209,"三轮交易")-SUMIFS($B$11:$B$209,$C$11:$C$209,A3,$E$11:$E$209,"四轮交易")+SUMIFS($B$11:$B$209,$D$11:$D$209,A3,$E$11:$E$209,"四轮交易") -> 20 | D3: =IF(C3<=0,"超支",IF(C3<=500,"即将超支，剩余"&TEXT(C3,"0")&"W第纳尔","资金状况良好")) -> 即将超支，剩余20W第纳尔 | E3: 冲锋
A4: 【SSR】Superior Super Rare | B4: ='队伍收入状况 '!D3 -> 2550 | C4: =B4-SUMIFS(交易历史!$B$11:$B$209,交易历史!$C$11:$C$209,A4,交易历史!$E$11:$E$209,"首轮交易")+SUMIFS(交易历史!$B$11:$B$209,交易历史!$D$11:$D$209,A4,交易历史!$E$11:$E$209,"首轮交易")-SUMIFS(交易历史!$B$11:$B$209,交易历史!$C$11:$C$209,A4,交易历史!$E$11:$E$209,"二轮交易")+SUMIFS(交易历史!$B$11:$B$209,交易历史!$D$11:$D$209,A4,交易历史!$E$11:$E$209,"二轮交易")-SUMIFS(交易历史!$B$11:$B$209,交易历史!$C$11:$C$209,A4,交易历史!$E$11:$E$209,"三轮交易")+SUMIFS(交易历史!$B$11:$B$209,交易历史!$D$11:$D$209,A4,交易历史!$E$11:$E$209,"三轮交易")-SUMIFS(交易历史!$B$11:$B$209,交易历史!$C$11:$C$209,A4,交易历史!$E$11:$E$209,"四轮交易")+SUMIFS(交易历史!$B$11:$B$209,交易历史!$D$11:$D$209,A4,交易历史!$E$11:$E$209,"四轮交易") -> 0 | D4: =IF(C4<=0,"超支",IF(C4<=500,"即将超支，剩余"&TEXT(C4,"0")&"W第纳尔","资金状况良好")) -> 超支 | E4: 图派克
A5: 【OldH】老H犟嘴 | B5: ='队伍收入状况 '!D4 -> 2100 | C5: =B5-SUMIFS(交易历史!$B$11:$B$209,交易历史!$C$11:$C$209,A5,交易历史!$E$11:$E$209,"首轮交易")+SUMIFS(交易历史!$B$11:$B$209,交易历史!$D$11:$D$209,A5,交易历史!$E$11:$E$209,"首轮交易")-SUMIFS(交易历史!$B$11:$B$209,交易历史!$C$11:$C$209,A5,交易历史!$E$11:$E$209,"二轮交易")+SUMIFS(交易历史!$B$11:$B$209,交易历史!$D$11:$D$209,A5,交易历史!$E$11:$E$209,"二轮交易")-SUMIFS(交易历史!$B$11:$B$209,交易历史!$C$11:$C$209,A5,交易历史!$E$11:$E$209,"三轮交易")+SUMIFS(交易历史!$B$11:$B$209,交易历史!$D$11:$D$209,A5,交易历史!$E$11:$E$209,"三轮交易")-SUMIFS(交易历史!$B$11:$B$209,交易历史!$C$11:$C$209,A5,交易历史!$E$11:$E$209,"四轮交易")+SUMIFS(交易历史!$B$11:$B$209,交易历史!$D$11:$D$209,A5,交易历史!$E$11:$E$209,"四轮交易") -> 30 | D5: =IF(C5<=0,"超支",IF(C5<=500,"即将超支，剩余"&TEXT(C5,"0")&"W第纳尔","资金状况良好")) -> 即将超支，剩余30W第纳尔 | E5: 凯撒
A6: 【AWO】逃出生天 | B6: ='队伍收入状况 '!D5 -> 2200 | C6: =B6-SUMIFS(交易历史!$B$11:$B$209,交易历史!$C$11:$C$209,A6,交易历史!$E$11:$E$209,"首轮交易")+SUMIFS(交易历史!$B$11:$B$209,交易历史!$D$11:$D$209,A6,交易历史!$E$11:$E$209,"首轮交易")-SUMIFS(交易历史!$B$11:$B$209,交易历史!$C$11:$C$209,A6,交易历史!$E$11:$E$209,"二轮交易")+SUMIFS(交易历史!$B$11:$B$209,交易历史!$D$11:$D$209,A6,交易历史!$E$11:$E$209,"二轮交易")-SUMIFS(交易历史!$B$11:$B$209,交易历史!$C$11:$C$209,A6,交易历史!$E$11:$E$209,"三轮交易")+SUMIFS(交易历史!$B$11:$B$209,交易历史!$D$11:$D$209,A6,交易历史!$E$11:$E$209,"三轮交易")-SUMIFS(交易历史!$B$11:$B$209,交易历史!$C$11:$C$209,A6,交易历史!$E$11:$E$209,"四轮交易")+SUMIFS(交易历史!$B$11:$B$209,交易历史!$D$11:$D$209,A6,交易历史!$E$11:$E$209,"四轮交易") -> 630 | D6: =IF(C6<=0,"超支",IF(C6<=500,"即将超支，剩余"&TEXT(C6,"0")&"W第纳尔","资金状况良好")) -> 资金状况良好 | E6: 小山楂
A7: 【G2】G2‭ | B7: ='队伍收入状况 '!D6 -> 2200 | C7: =B7-SUMIFS(交易历史!$B$11:$B$209,交易历史!$C$11:$C$209,A7,交易历史!$E$11:$E$209,"首轮交易")+SUMIFS(交易历史!$B$11:$B$209,交易历史!$D$11:$D$209,A7,交易历史!$E$11:$E$209,"首轮交易")-SUMIFS(交易历史!$B$11:$B$209,交易历史!$C$11:$C$209,A7,交易历史!$E$11:$E$209,"二轮交易")+SUMIFS(交易历史!$B$11:$B$209,交易历史!$D$11:$D$209,A7,交易历史!$E$11:$E$209,"二轮交易")-SUMIFS(交易历史!$B$11:$B$209,交易历史!$C$11:$C$209,A7,交易历史!$E$11:$E$209,"三轮交易")+SUMIFS(交易历史!$B$11:$B$209,交易历史!$D$11:$D$209,A7,交易历史!$E$11:$E$209,"三轮交易")-SUMIFS(交易历史!$B$11:$B$209,交易历史!$C$11:$C$209,A7,交易历史!$E$11:$E$209,"四轮交易")+SUMIFS(交易历史!$B$11:$B$209,交易历史!$D$11:$D$209,A7,交易历史!$E$11:$E$209,"四轮交易") -> 90 | D7: =IF(C7<=0,"超支",IF(C7<=500,"即将超支，剩余"&TEXT(C7,"0")&"W第纳尔","资金状况良好")) -> 即将超支，剩余90W第纳尔 | E7: 米子
A8: 【TV】Team Vitality | B8: ='队伍收入状况 '!D7 -> 2200 | C8: =B8-SUMIFS(交易历史!$B$11:$B$209,交易历史!$C$11:$C$209,A8,交易历史!$E$11:$E$209,"首轮交易")+SUMIFS(交易历史!$B$11:$B$209,交易历史!$D$11:$D$209,A8,交易历史!$E$11:$E$209,"首轮交易")-SUMIFS(交易历史!$B$11:$B$209,交易历史!$C$11:$C$209,A8,交易历史!$E$11:$E$209,"二轮交易")+SUMIFS(交易历史!$B$11:$B$209,交易历史!$D$11:$D$209,A8,交易历史!$E$11:$E$209,"二轮交易")-SUMIFS(交易历史!$B$11:$B$209,交易历史!$C$11:$C$209,A8,交易历史!$E$11:$E$209,"三轮交易")+SUMIFS(交易历史!$B$11:$B$209,交易历史!$D$11:$D$209,A8,交易历史!$E$11:$E$209,"三轮交易")-SUMIFS(交易历史!$B$11:$B$209,交易历史!$C$11:$C$209,A8,交易历史!$E$11:$E$209,"四轮交易")+SUMIFS(交易历史!$B$11:$B$209,交易历史!$D$11:$D$209,A8,交易历史!$E$11:$E$209,"四轮交易") -> 90 | D8: =IF(C8<=0,"超支",IF(C8<=500,"即将超支，剩余"&TEXT(C8,"0")&"W第纳尔","资金状况良好")) -> 即将超支，剩余90W第纳尔 | E8: 赵毅
A9: 【Miniworld】迷你世界 | B9: ='队伍收入状况 '!D8 -> 2750 | C9: =B9-SUMIFS(交易历史!$B$11:$B$209,交易历史!$C$11:$C$209,A9,交易历史!$E$11:$E$209,"首轮交易")+SUMIFS(交易历史!$B$11:$B$209,交易历史!$D$11:$D$209,A9,交易历史!$E$11:$E$209,"首轮交易")-SUMIFS(交易历史!$B$11:$B$209,交易历史!$C$11:$C$209,A9,交易历史!$E$11:$E$209,"二轮交易")+SUMIFS(交易历史!$B$11:$B$209,交易历史!$D$11:$D$209,A9,交易历史!$E$11:$E$209,"二轮交易")-SUMIFS(交易历史!$B$11:$B$209,交易历史!$C$11:$C$209,A9,交易历史!$E$11:$E$209,"三轮交易")+SUMIFS(交易历史!$B$11:$B$209,交易历史!$D$11:$D$209,A9,交易历史!$E$11:$E$209,"三轮交易")-SUMIFS(交易历史!$B$11:$B$209,交易历史!$C$11:$C$209,A9,交易历史!$E$11:$E$209,"四轮交易")+SUMIFS(交易历史!$B$11:$B$209,交易历史!$D$11:$D$209,A9,交易历史!$E$11:$E$209,"四轮交易") -> 650 | D9: =IF(C9<=0,"超支",IF(C9<=500,"即将超支，剩余"&TEXT(C9,"0")&"W第纳尔","资金状况良好")) -> 资金状况良好 | E9: nane
A10: 【NikoFC】NikoCN Fanclub | B10: ='队伍收入状况 '!D9 -> 2700 | C10: =B10-SUMIFS(交易历史!$B$11:$B$209,交易历史!$C$11:$C$209,A10,交易历史!$E$11:$E$209,"首轮交易")+SUMIFS(交易历史!$B$11:$B$209,交易历史!$D$11:$D$209,A10,交易历史!$E$11:$E$209,"首轮交易")-SUMIFS(交易历史!$B$11:$B$209,交易历史!$C$11:$C$209,A10,交易历史!$E$11:$E$209,"二轮交易")+SUMIFS(交易历史!$B$11:$B$209,交易历史!$D$11:$D$209,A10,交易历史!$E$11:$E$209,"二轮交易")-SUMIFS(交易历史!$B$11:$B$209,交易历史!$C$11:$C$209,A10,交易历史!$E$11:$E$209,"三轮交易")+SUMIFS(交易历史!$B$11:$B$209,交易历史!$D$11:$D$209,A10,交易历史!$E$11:$E$209,"三轮交易")-SUMIFS(交易历史!$B$11:$B$209,交易历史!$C$11:$C$209,A10,交易历史!$E$11:$E$209,"四轮交易")+SUMIFS(交易历史!$B$11:$B$209,交易历史!$D$11:$D$209,A10,交易历史!$E$11:$E$209,"四轮交易") -> 360 | D10: =IF(C10<=0,"超支",IF(C10<=500,"即将超支，剩余"&TEXT(C10,"0")&"W第纳尔","资金状况良好")) -> 即将超支，剩余360W第纳尔 | E10: 梅森
A11: 球员昵称 | B11: 交易价格 | C11: 买入队伍 | D11: 卖出队伍 | E11: 交易窗口 | F11: 最终归属队伍 | G11: 最高身价
A12: xiaoliyu | B12: 0 | C12: 【G2】G2‭ | E12: 首轮交易 | F12: {=IFERROR(INDEX(交易历史!C:C,MATCH(1,(交易历史!A:A=A12)*(交易历史!E:E="四轮交易"),0)),IFERROR(INDEX(交易历史!C:C,MATCH(1,(交易历史!A:A=A12)*(交易历史!E:E="三轮交易"),0)),IFERROR(INDEX(交易历史!C:C,MATCH(1,(交易历史!A:A=A12)*(交易历史!E:E="二轮交易"),0)),IFERROR(INDEX(交易历史!C:C,MATCH(1,(交易历史!A:A=A12)*(交易历史!E:E="首轮交易"),0)),""))))} -> 【G2】G2‭ | G12: =IF(A12<>"",_xlfn.MAXIFS($B$12:$B$210,$A$12:$A$210,A12),"") -> 0 | H12: =IF(A12<>"",IF(COUNTIF($A12:$A$210,A12)=1,1,""),"") -> 1
A13: 小鱼 | B13: 80 | C13: 【SSR】Superior Super Rare | E13: 首轮交易 | F13: {=IFERROR(INDEX(交易历史!C:C,MATCH(1,(交易历史!A:A=A13)*(交易历史!E:E="四轮交易"),0)),IFERROR(INDEX(交易历史!C:C,MATCH(1,(交易历史!A:A=A13)*(交易历史!E:E="三轮交易"),0)),IFERROR(INDEX(交易历史!C:C,MATCH(1,(交易历史!A:A=A13)*(交易历史!E:E="二轮交易"),0)),IFERROR(INDEX(交易历史!C:C,MATCH(1,(交易历史!A:A=A13)*(交易历史!E:E="首轮交易"),0)),""))))} -> 【SSR】Superior Super Rare | G13: =IF(A13<>"",_xlfn.MAXIFS($B$12:$B$210,$A$12:$A$210,A13),"") -> 80 | H13: =IF(A13<>"",IF(COUNTIF($A13:$A$210,A13)=1,1,""),"") -> 1
A14: Mengdong | B14: 0 | C14: 【AWO】逃出生天 | E14: 首轮交易 | F14: {=IFERROR(INDEX(交易历史!C:C,MATCH(1,(交易历史!A:A=A14)*(交易历史!E:E="四轮交易"),0)),IFERROR(INDEX(交易历史!C:C,MATCH(1,(交易历史!A:A=A14)*(交易历史!E:E="三轮交易"),0)),IFERROR(INDEX(交易历史!C:C,MATCH(1,(交易历史!A:A=A14)*(交易历史!E:E="二轮交易"),0)),IFERROR(INDEX(交易历史!C:C,MATCH(1,(交易历史!A:A=A14)*(交易历史!E:E="首轮交易"),0)),""))))} -> 【AWO】逃出生天 | G14: =IF(A14<>"",_xlfn.MAXIFS($B$12:$B$210,$A$12:$A$210,A14),"") -> 0 | H14: =IF(A14<>"",IF(COUNTIF($A14:$A$210,A14)=1,1,""),"") -> 1
A15: awe23 | B15: 320 | C15: 【NikoFC】NikoCN Fanclub | E15: 首轮交易 | F15: {=IFERROR(INDEX(交易历史!C:C,MATCH(1,(交易历史!A:A=A15)*(交易历史!E:E="四轮交易"),0)),IFERROR(INDEX(交易历史!C:C,MATCH(1,(交易历史!A:A=A15)*(交易历史!E:E="三轮交易"),0)),IFERROR(INDEX(交易历史!C:C,MATCH(1,(交易历史!A:A=A15)*(交易历史!E:E="二轮交易"),0)),IFERROR(INDEX(交易历史!C:C,MATCH(1,(交易历史!A:A=A15)*(交易历史!E:E="首轮交易"),0)),""))))} -> 【NikoFC】NikoCN Fanclub | G15: =IF(A15<>"",_xlfn.MAXIFS($B$12:$B$210,$A$12:$A$210,A15),"") -> 320 | H15: =IF(A15<>"",IF(COUNTIF($A15:$A$210,A15)=1,1,""),"") -> 1
A16: 史蒂夫 | B16: 400 | C16: 【SSR】Superior Super Rare | E16: 首轮交易 | F16: {=IFERROR(INDEX(交易历史!C:C,MATCH(1,(交易历史!A:A=A16)*(交易历史!E:E="四轮交易"),0)),IFERROR(INDEX(交易历史!C:C,MATCH(1,(交易历史!A:A=A16)*(交易历史!E:E="三轮交易"),0)),IFERROR(INDEX(交易历史!C:C,MATCH(1,(交易历史!A:A=A16)*(交易历史!E:E="二轮交易"),0)),IFERROR(INDEX(交易历史!C:C,MATCH(1,(交易历史!A:A=A16)*(交易历史!E:E="首轮交易"),0)),""))))} -> 【SSR】Superior Super Rare | G16: =IF(A16<>"",_xlfn.MAXIFS($B$12:$B$210,$A$12:$A$210,A16),"") -> 400 | H16: =IF(A16<>"",IF(COUNTIF($A16:$A$210,A16)=1,1,""),"") -> 1
A17: f4 | B17: 600 | C17: 【TV】Team Vitality | E17: 首轮交易 | F17: {=IFERROR(INDEX(交易历史!C:C,MATCH(1,(交易历史!A:A=A17)*(交易历史!E:E="四轮交易"),0)),IFERROR(INDEX(交易历史!C:C,MATCH(1,(交易历史!A:A=A17)*(交易历史!E:E="三轮交易"),0)),IFERROR(INDEX(交易历史!C:C,MATCH(1,(交易历史!A:A=A17)*(交易历史!E:E="二轮交易"),0)),IFERROR(INDEX(交易历史!C:C,MATCH(1,(交易历史!A:A=A17)*(交易历史!E:E="首轮交易"),0)),""))))} -> 【TV】Team Vitality | G17: =IF(A17<>"",_xlfn.MAXIFS($B$12:$B$210,$A$12:$A$210,A17),"") -> 600 | H17: =IF(A17<>"",IF(COUNTIF($A17:$A$210,A17)=1,1,""),"") -> 1
A18: Bonaoart | B18: 100 | C18: 【NikoFC】NikoCN Fanclub | E18: 首轮交易 | F18: {=IFERROR(INDEX(交易历史!C:C,MATCH(1,(交易历史!A:A=A18)*(交易历史!E:E="四轮交易"),0)),IFERROR(INDEX(交易历史!C:C,MATCH(1,(交易历史!A:A=A18)*(交易历史!E:E="三轮交易"),0)),IFERROR(INDEX(交易历史!C:C,MATCH(1,(交易历史!A:A=A18)*(交易历史!E:E="二轮交易"),0)),IFERROR(INDEX(交易历史!C:C,MATCH(1,(交易历史!A:A=A18)*(交易历史!E:E="首轮交易"),0)),""))))} -> 【NikoFC】NikoCN Fanclub | G18: =IF(A18<>"",_xlfn.MAXIFS($B$12:$B$210,$A$12:$A$210,A18),"") -> 100 | H18: =IF(A18<>"",IF(COUNTIF($A18:$A$210,A18)=1,1,""),"") -> 1
A19: 哭丧 | B19: 80 | C19: 【Miniworld】迷你世界 | E19: 首轮交易 | F19: {=IFERROR(INDEX(交易历史!C:C,MATCH(1,(交易历史!A:A=A19)*(交易历史!E:E="四轮交易"),0)),IFERROR(INDEX(交易历史!C:C,MATCH(1,(交易历史!A:A=A19)*(交易历史!E:E="三轮交易"),0)),IFERROR(INDEX(交易历史!C:C,MATCH(1,(交易历史!A:A=A19)*(交易历史!E:E="二轮交易"),0)),IFERROR(INDEX(交易历史!C:C,MATCH(1,(交易历史!A:A=A19)*(交易历史!E:E="首轮交易"),0)),""))))} -> 【Miniworld】迷你世界 | G19: =IF(A19<>"",_xlfn.MAXIFS($B$12:$B$210,$A$12:$A$210,A19),"") -> 80 | H19: =IF(A19<>"",IF(COUNTIF($A19:$A$210,A19)=1,1,""),"") -> 1
A20: abin | B20: 10 | C20: 【TV】Team Vitality | E20: 首轮交易 | F20: {=IFERROR(INDEX(交易历史!C:C,MATCH(1,(交易历史!A:A=A20)*(交易历史!E:E="四轮交易"),0)),IFERROR(INDEX(交易历史!C:C,MATCH(1,(交易历史!A:A=A20)*(交易历史!E:E="三轮交易"),0)),IFERROR(INDEX(交易历史!C:C,MATCH(1,(交易历史!A:A=A20)*(交易历史!E:E="二轮交易"),0)),IFERROR(INDEX(交易历史!C:C,MATCH(1,(交易历史!A:A=A20)*(交易历史!E:E="首轮交易"),0)),""))))} -> 【TV】Team Vitality | G20: =IF(A20<>"",_xlfn.MAXIFS($B$12:$B$210,$A$12:$A$210,A20),"") -> 10 | H20: =IF(A20<>"",IF(COUNTIF($A20:$A$210,A20)=1,1,""),"") -> 1
A21: GJY | B21: 0 | C21: 【CbHz】吃饱喝足就是玩 | E21: 首轮交易 | F21: {=IFERROR(INDEX(交易历史!C:C,MATCH(1,(交易历史!A:A=A21)*(交易历史!E:E="四轮交易"),0)),IFERROR(INDEX(交易历史!C:C,MATCH(1,(交易历史!A:A=A21)*(交易历史!E:E="三轮交易"),0)),IFERROR(INDEX(交易历史!C:C,MATCH(1,(交易历史!A:A=A21)*(交易历史!E:E="二轮交易"),0)),IFERROR(INDEX(交易历史!C:C,MATCH(1,(交易历史!A:A=A21)*(交易历史!E:E="首轮交易"),0)),""))))} -> 【CbHz】吃饱喝足就是玩 | G21: =IF(A21<>"",_xlfn.MAXIFS($B$12:$B$210,$A$12:$A$210,A21),"") -> 0 | H21: =IF(A21<>"",IF(COUNTIF($A21:$A$210,A21)=1,1,""),"") -> 1
A22: AP-20 | B22: 20 | C22: 【TV】Team Vitality | E22: 首轮交易 | F22: {=IFERROR(INDEX(交易历史!C:C,MATCH(1,(交易历史!A:A=A22)*(交易历史!E:E="四轮交易"),0)),IFERROR(INDEX(交易历史!C:C,MATCH(1,(交易历史!A:A=A22)*(交易历史!E:E="三轮交易"),0)),IFERROR(INDEX(交易历史!C:C,MATCH(1,(交易历史!A:A=A22)*(交易历史!E:E="二轮交易"),0)),IFERROR(INDEX(交易历史!C:C,MATCH(1,(交易历史!A:A=A22)*(交易历史!E:E="首轮交易"),0)),""))))} -> 【TV】Team Vitality | G22: =IF(A22<>"",_xlfn.MAXIFS($B$12:$B$210,$A$12:$A$210,A22),"") -> 20 | H22: =IF(A22<>"",IF(COUNTIF($A22:$A$210,A22)=1,1,""),"") -> 1
A23: 王水灵 | B23: 10 | C23: 【SSR】Superior Super Rare | E23: 首轮交易 | F23: {=IFERROR(INDEX(交易历史!C:C,MATCH(1,(交易历史!A:A=A23)*(交易历史!E:E="四轮交易"),0)),IFERROR(INDEX(交易历史!C:C,MATCH(1,(交易历史!A:A=A23)*(交易历史!E:E="三轮交易"),0)),IFERROR(INDEX(交易历史!C:C,MATCH(1,(交易历史!A:A=A23)*(交易历史!E:E="二轮交易"),0)),IFERROR(INDEX(交易历史!C:C,MATCH(1,(交易历史!A:A=A23)*(交易历史!E:E="首轮交易"),0)),""))))} -> 【SSR】Superior Super Rare | G23: =IF(A23<>"",_xlfn.MAXIFS($B$12:$B$210,$A$12:$A$210,A23),"") -> 10 | H23: =IF(A23<>"",IF(COUNTIF($A23:$A$210,A23)=1,1,""),"") -> 1
... A93: 大西瓜 | B93: 100 | C93: 【OldH】老H犟嘴 | E93: 首轮交易 | F93: {=IFERROR(INDEX(交易历史!C:C,MATCH(1,(交易历史!A:A=A93)*(交易历史!E:E="四轮交易"),0)),IFERROR(INDEX(交易历史!C:C,MATCH(1,(交易历史!A:A=A93)*(交易历史!E:E="三轮交易"),0)),IFERROR(INDEX(交易历史!C:C,MATCH(1,(交易历史!A:A=A93)*(交易历史!E:E="二轮交易"),0)),IFERROR(INDEX(交易历史!C:C,MATCH(1,(交易历史!A:A=A93)*(交易历史!E:E="首轮交易"),0)),""))))} -> 【OldH】老H犟嘴 | G93: =IF(A93<>"",_xlfn.MAXIFS($B$12:$B$210,$A$12:$A$210,A93),"") -> 100 | H93: =IF(A93<>"",IF(COUNTIF($A93:$A$210,A93)=1,1,""),"") -> 1
A94: 白露 | E94: 首轮交易 | F94: {=IFERROR(INDEX(交易历史!C:C,MATCH(1,(交易历史!A:A=A94)*(交易历史!E:E="四轮交易"),0)),IFERROR(INDEX(交易历史!C:C,MATCH(1,(交易历史!A:A=A94)*(交易历史!E:E="三轮交易"),0)),IFERROR(INDEX(交易历史!C:C,MATCH(1,(交易历史!A:A=A94)*(交易历史!E:E="二轮交易"),0)),IFERROR(INDEX(交易历史!C:C,MATCH(1,(交易历史!A:A=A94)*(交易历史!E:E="首轮交易"),0)),""))))} -> 0 | G94: =IF(A94<>"",_xlfn.MAXIFS($B$12:$B$210,$A$12:$A$210,A94),"") -> 0 | H94: =IF(A94<>"",IF(COUNTIF($A94:$A$210,A94)=1,1,""),"") -> 1
A95: wind | E95: 首轮交易 | F95: {=IFERROR(INDEX(交易历史!C:C,MATCH(1,(交易历史!A:A=A95)*(交易历史!E:E="四轮交易"),0)),IFERROR(INDEX(交易历史!C:C,MATCH(1,(交易历史!A:A=A95)*(交易历史!E:E="三轮交易"),0)),IFERROR(INDEX(交易历史!C:C,MATCH(1,(交易历史!A:A=A95)*(交易历史!E:E="二轮交易"),0)),IFERROR(INDEX(交易历史!C:C,MATCH(1,(交易历史!A:A=A95)*(交易历史!E:E="首轮交易"),0)),""))))} -> 0 | G95: =IF(A95<>"",_xlfn.MAXIFS($B$12:$B$210,$A$12:$A$210,A95),"") -> 0 | H95: =IF(A95<>"",IF(COUNTIF($A95:$A$210,A95)=1,1,""),"") -> 1
A96: 波澜 | E96: 首轮交易 | F96: {=IFERROR(INDEX(交易历史!C:C,MATCH(1,(交易历史!A:A=A96)*(交易历史!E:E="四轮交易"),0)),IFERROR(INDEX(交易历史!C:C,MATCH(1,(交易历史!A:A=A96)*(交易历史!E:E="三轮交易"),0)),IFERROR(INDEX(交易历史!C:C,MATCH(1,(交易历史!A:A=A96)*(交易历史!E:E="二轮交易"),0)),IFERROR(INDEX(交易历史!C:C,MATCH(1,(交易历史!A:A=A96)*(交易历史!E:E="首轮交易"),0)),""))))} -> 0 | G96: =IF(A96<>"",_xlfn.MAXIFS($B$12:$B$210,$A$12:$A$210,A96),"") -> 0 | H96: =IF(A96<>"",IF(COUNTIF($A96:$A$210,A96)=1,1,""),"") -> 1
A97: YQS-Laozhongzhu | E97: 首轮交易 | F97: {=IFERROR(INDEX(交易历史!C:C,MATCH(1,(交易历史!A:A=A97)*(交易历史!E:E="四轮交易"),0)),IFERROR(INDEX(交易历史!C:C,MATCH(1,(交易历史!A:A=A97)*(交易历史!E:E="三轮交易"),0)),IFERROR(INDEX(交易历史!C:C,MATCH(1,(交易历史!A:A=A97)*(交易历史!E:E="二轮交易"),0)),IFERROR(INDEX(交易历史!C:C,MATCH(1,(交易历史!A:A=A97)*(交易历史!E:E="首轮交易"),0)),""))))} -> 0 | G97: =IF(A97<>"",_xlfn.MAXIFS($B$12:$B$210,$A$12:$A$210,A97),"") -> 0 | H97: =IF(A97<>"",IF(COUNTIF($A97:$A$210,A97)=1,1,""),"") -> 1
A98: TNT | E98: 首轮交易 | F98: {=IFERROR(INDEX(交易历史!C:C,MATCH(1,(交易历史!A:A=A98)*(交易历史!E:E="四轮交易"),0)),IFERROR(INDEX(交易历史!C:C,MATCH(1,(交易历史!A:A=A98)*(交易历史!E:E="三轮交易"),0)),IFERROR(INDEX(交易历史!C:C,MATCH(1,(交易历史!A:A=A98)*(交易历史!E:E="二轮交易"),0)),IFERROR(INDEX(交易历史!C:C,MATCH(1,(交易历史!A:A=A98)*(交易历史!E:E="首轮交易"),0)),""))))} -> 0 | G98: =IF(A98<>"",_xlfn.MAXIFS($B$12:$B$210,$A$12:$A$210,A98),"") -> 0 | H98: =IF(A98<>"",IF(COUNTIF($A98:$A$210,A98)=1,1,""),"") -> 1
A99: 天将 | E99: 首轮交易 | F99: {=IFERROR(INDEX(交易历史!C:C,MATCH(1,(交易历史!A:A=A99)*(交易历史!E:E="四轮交易"),0)),IFERROR(INDEX(交易历史!C:C,MATCH(1,(交易历史!A:A=A99)*(交易历史!E:E="三轮交易"),0)),IFERROR(INDEX(交易历史!C:C,MATCH(1,(交易历史!A:A=A99)*(交易历史!E:E="二轮交易"),0)),IFERROR(INDEX(交易历史!C:C,MATCH(1,(交易历史!A:A=A99)*(交易历史!E:E="首轮交易"),0)),""))))} -> 0 | G99: =IF(A99<>"",_xlfn.MAXIFS($B$12:$B$210,$A$12:$A$210,A99),"") -> 0 | H99: =IF(A99<>"",IF(COUNTIF($A99:$A$210,A99)=1,1,""),"") -> 1
A100: Rapier | E100: 首轮交易 | F100: {=IFERROR(INDEX(交易历史!C:C,MATCH(1,(交易历史!A:A=A100)*(交易历史!E:E="四轮交易"),0)),IFERROR(INDEX(交易历史!C:C,MATCH(1,(交易历史!A:A=A100)*(交易历史!E:E="三轮交易"),0)),IFERROR(INDEX(交易历史!C:C,MATCH(1,(交易历史!A:A=A100)*(交易历史!E:E="二轮交易"),0)),IFERROR(INDEX(交易历史!C:C,MATCH(1,(交易历史!A:A=A100)*(交易历史!E:E="首轮交易"),0)),""))))} -> 0 | G100: =IF(A100<>"",_xlfn.MAXIFS($B$12:$B$210,$A$12:$A$210,A100),"") -> 0 | H100: =IF(A100<>"",IF(COUNTIF($A100:$A$210,A100)=1,1,""),"") -> 1
A101: 鸡头 | E101: 首轮交易 | F101: {=IFERROR(INDEX(交易历史!C:C,MATCH(1,(交易历史!A:A=A101)*(交易历史!E:E="四轮交易"),0)),IFERROR(INDEX(交易历史!C:C,MATCH(1,(交易历史!A:A=A101)*(交易历史!E:E="三轮交易"),0)),IFERROR(INDEX(交易历史!C:C,MATCH(1,(交易历史!A:A=A101)*(交易历史!E:E="二轮交易"),0)),IFERROR(INDEX(交易历史!C:C,MATCH(1,(交易历史!A:A=A101)*(交易历史!E:E="首轮交易"),0)),""))))} -> 0 | G101: =IF(A101<>"",_xlfn.MAXIFS($B$12:$B$210,$A$12:$A$210,A101),"") -> 0 | H101: =IF(A101<>"",IF(COUNTIF($A101:$A$210,A101)=1,1,""),"") -> 1
A102: 888 | E102: 首轮交易 | F102: {=IFERROR(INDEX(交易历史!C:C,MATCH(1,(交易历史!A:A=A102)*(交易历史!E:E="四轮交易"),0)),IFERROR(INDEX(交易历史!C:C,MATCH(1,(交易历史!A:A=A102)*(交易历史!E:E="三轮交易"),0)),IFERROR(INDEX(交易历史!C:C,MATCH(1,(交易历史!A:A=A102)*(交易历史!E:E="二轮交易"),0)),IFERROR(INDEX(交易历史!C:C,MATCH(1,(交易历史!A:A=A102)*(交易历史!E:E="首轮交易"),0)),""))))} -> 0 | G102: =IF(A102<>"",_xlfn.MAXIFS($B$12:$B$210,$A$12:$A$210,A102),"") -> 0 | H102: =IF(A102<>"",IF(COUNTIF($A102:$A$210,A102)=1,1,""),"") -> 1
A103: 午马 | E103: 首轮交易 | F103: {=IFERROR(INDEX(交易历史!C:C,MATCH(1,(交易历史!A:A=A103)*(交易历史!E:E="四轮交易"),0)),IFERROR(INDEX(交易历史!C:C,MATCH(1,(交易历史!A:A=A103)*(交易历史!E:E="三轮交易"),0)),IFERROR(INDEX(交易历史!C:C,MATCH(1,(交易历史!A:A=A103)*(交易历史!E:E="二轮交易"),0)),IFERROR(INDEX(交易历史!C:C,MATCH(1,(交易历史!A:A=A103)*(交易历史!E:E="首轮交易"),0)),""))))} -> 0 | G103: =IF(A103<>"",_xlfn.MAXIFS($B$12:$B$210,$A$12:$A$210,A103),"") -> 0 | H103: =IF(A103<>"",IF(COUNTIF($A103:$A$210,A103)=1,1,""),"") -> 1
A104: xp | E104: 首轮交易 | F104: {=IFERROR(INDEX(交易历史!C:C,MATCH(1,(交易历史!A:A=A104)*(交易历史!E:E="四轮交易"),0)),IFERROR(INDEX(交易历史!C:C,MATCH(1,(交易历史!A:A=A104)*(交易历史!E:E="三轮交易"),0)),IFERROR(INDEX(交易历史!C:C,MATCH(1,(交易历史!A:A=A104)*(交易历史!E:E="二轮交易"),0)),IFERROR(INDEX(交易历史!C:C,MATCH(1,(交易历史!A:A=A104)*(交易历史!E:E="首轮交易"),0)),""))))} -> 0 | G104: =IF(A104<>"",_xlfn.MAXIFS($B$12:$B$210,$A$12:$A$210,A104),"") -> 0 | H104: =IF(A104<>"",IF(COUNTIF($A104:$A$210,A104)=1,1,""),"") -> 1
A105: 帅比大 | E105: 首轮交易 | F105: {=IFERROR(INDEX(交易历史!C:C,MATCH(1,(交易历史!A:A=A105)*(交易历史!E:E="四轮交易"),0)),IFERROR(INDEX(交易历史!C:C,MATCH(1,(交易历史!A:A=A105)*(交易历史!E:E="三轮交易"),0)),IFERROR(INDEX(交易历史!C:C,MATCH(1,(交易历史!A:A=A105)*(交易历史!E:E="二轮交易"),0)),IFERROR(INDEX(交易历史!C:C,MATCH(1,(交易历史!A:A=A105)*(交易历史!E:E="首轮交易"),0)),""))))} -> 0 | G105: =IF(A105<>"",_xlfn.MAXIFS($B$12:$B$210,$A$12:$A$210,A105),"") -> 0 | H105: =IF(A105<>"",IF(COUNTIF($A105:$A$210,A105)=1,1,""),"") -> 1
... A125: 牢云 | E125: 首轮交易 | F125: {=IFERROR(INDEX(交易历史!C:C,MATCH(1,(交易历史!A:A=A125)*(交易历史!E:E="四轮交易"),0)),IFERROR(INDEX(交易历史!C:C,MATCH(1,(交易历史!A:A=A125)*(交易历史!E:E="三轮交易"),0)),IFERROR(INDEX(交易历史!C:C,MATCH(1,(交易历史!A:A=A125)*(交易历史!E:E="二轮交易"),0)),IFERROR(INDEX(交易历史!C:C,MATCH(1,(交易历史!A:A=A125)*(交易历史!E:E="首轮交易"),0)),""))))} -> 0 | G125: =IF(A125<>"",_xlfn.MAXIFS($B$12:$B$210,$A$12:$A$210,A125),"") -> 0 | H125: =IF(A125<>"",IF(COUNTIF($A125:$A$210,A125)=1,1,""),"") -> 1
F126: {=IFERROR(INDEX(交易历史!C:C,MATCH(1,(交易历史!A:A=A126)*(交易历史!E:E="四轮交易"),0)),IFERROR(INDEX(交易历史!C:C,MATCH(1,(交易历史!A:A=A126)*(交易历史!E:E="三轮交易"),0)),IFERROR(INDEX(交易历史!C:C,MATCH(1,(交易历史!A:A=A126)*(交易历史!E:E="二轮交易"),0)),IFERROR(INDEX(交易历史!C:C,MATCH(1,(交易历史!A:A=A126)*(交易历史!E:E="首轮交易"),0)),""))))} | G126: =IF(A126<>"",_xlfn.MAXIFS($B$12:$B$210,$A$12:$A$210,A126),"") | H126: =IF(A126<>"",IF(COUNTIF($A126:$A$210,A126)=1,1,""),"")
F127: {=IFERROR(INDEX(交易历史!C:C,MATCH(1,(交易历史!A:A=A127)*(交易历史!E:E="四轮交易"),0)),IFERROR(INDEX(交易历史!C:C,MATCH(1,(交易历史!A:A=A127)*(交易历史!E:E="三轮交易"),0)),IFERROR(INDEX(交易历史!C:C,MATCH(1,(交易历史!A:A=A127)*(交易历史!E:E="二轮交易"),0)),IFERROR(INDEX(交易历史!C:C,MATCH(1,(交易历史!A:A=A127)*(交易历史!E:E="首轮交易"),0)),""))))} | G127: =IF(A127<>"",_xlfn.MAXIFS($B$12:$B$210,$A$12:$A$210,A127),"") | H127: =IF(A127<>"",IF(COUNTIF($A127:$A$210,A127)=1,1,""),"")
F128: {=IFERROR(INDEX(交易历史!C:C,MATCH(1,(交易历史!A:A=A128)*(交易历史!E:E="四轮交易"),0)),IFERROR(INDEX(交易历史!C:C,MATCH(1,(交易历史!A:A=A128)*(交易历史!E:E="三轮交易"),0)),IFERROR(INDEX(交易历史!C:C,MATCH(1,(交易历史!A:A=A128)*(交易历史!E:E="二轮交易"),0)),IFERROR(INDEX(交易历史!C:C,MATCH(1,(交易历史!A:A=A128)*(交易历史!E:E="首轮交易"),0)),""))))} | G128: =IF(A128<>"",_xlfn.MAXIFS($B$12:$B$210,$A$12:$A$210,A128),"") | H128: =IF(A128<>"",IF(COUNTIF($A128:$A$210,A128)=1,1,""),"")
...

Sheet 队伍总览 
B2: 【Cbhz】吃饱喝足就是玩 <1944993273> | F2: 【SSR】Superior Super Rare <2764659592> | J2: 【OldH】老H犟嘴 <3320553061> | N2: 【AWO】逃出生天 <740221391>
B3: 常用昵称 | C3: 身价（单位:w） | D3: 梦幻联赛ID | F3: 常用昵称 | G3: 身价（单位:w） | H3: 梦幻联赛ID | J3: 常用昵称 | K3: 身价（单位:w） | L3: 梦幻联赛ID | N3: 常用昵称 | O3: 身价（单位:w） | P3: 梦幻联赛ID
B4: 冲锋 | C4: 750 | F4: 图派克 | G4: 450 | J4: 凯撒 | K4: 900 | N4: Cooper | O4: 800
B5: {=IFERROR(_xlfn._xlws.FILTER(交易历史!$A$12:$A$210,(交易历史!$F$12:$F$210="【CbHz】吃饱喝足就是玩")*(交易历史!$H$12:$H$210=1)),"")} -> GJY | C5: {=IFERROR(_xlfn._xlws.FILTER(交易历史!$G$12:$G$210,(交易历史!$C$12:$C$210="【CbHz】吃饱喝足就是玩")*(交易历史!$H$12:$H$210=1)),"")} -> 0 | F5: {=IFERROR(_xlfn._xlws.FILTER(交易历史!$A$12:$A$210,(交易历史!$F$12:$F$210="【SSR】Superior Super Rare")*(交易历史!$H$12:$H$210=1)),"")} -> 小鱼 | G5: {=IFERROR(_xlfn._xlws.FILTER(交易历史!$G$12:$G$210,(交易历史!$C$12:$C$210="【SSR】Superior Super Rare")*(交易历史!$H$12:$H$210=1)),"")} -> 80 | J5: {=IFERROR(_xlfn._xlws.FILTER(交易历史!$A$12:$A$210,(交易历史!$F$12:$F$210="【OldH】老H犟嘴")*(交易历史!$H$12:$H$210=1)),"")} -> 宝爹 | K5: {=IFERROR(_xlfn._xlws.FILTER(交易历史!$G$12:$G$210,(交易历史!$C$12:$C$210="【OldH】老H犟嘴")*(交易历史!$H$12:$H$210=1)),"")} -> 360 | N5: {=IFERROR(_xlfn._xlws.FILTER(交易历史!$A$12:$A$210,(交易历史!$F$12:$F$210="【AWO】逃出生天")*(交易历史!$H$12:$H$210=1)),"")} -> Mengdong | O5: {=IFERROR(_xlfn._xlws.FILTER(交易历史!$G$12:$G$210,(交易历史!$C$12:$C$210="【AWO】逃出生天")*(交易历史!$H$12:$H$210=1)),"")} -> 0
B6: 豆子 | C6: 660 | F6: 史蒂夫 | G6: 400 | J6: 苏西斯 | K6: 100 | N6: HorN_kukuko | O6: 20
B7: 罗加 | C7: 0 | F7: 王水灵 | G7: 10 | J7: Ezio | K7: 30 | N7: DH | O7: 130
B8: twocat | C8: 0 | F8: Luvv | G8: 200 | J8: KR_YuXuan | K8: 500 | N8: parrot | O8: 80
B9: jmz | C9: 800 | F9: 艾拉AL | G9: 10 | J9: ai | K9: 100 | N9: 城府 | O9: 190
B10: baimayinqiang | C10: 10 | F10: 骑砍皇帝 | G10: 700 | J10: Motochika | K10: 160 | N10: knightzz | O10: 850
B11: IC | C11: 500 | F11: 小捷豹 | G11: 40 | J11: LSSL | K11: 90 | N11: 退休老人野望 | O11: 90
B12: xiaoye | C12: 0 | F12: 威廉 | G12: 700 | J12: shiran | K12: 380 | N12: 比伯 | O12: 210
B13: MANGOL | C13: 250 | F13: Able | G13: 410 | J13: havoc | K13: 150 | N13: XiaoRen | O13: 0
B14: 芬克 | C14: 0 | J14: 1911/Dogmeat | K14: 100
B15: 阿氰 | C15: 10 | J15: 大西瓜 | K15: 100
B20: =IFERROR(_xlfn._xlws.FILTER(转会市场!$A$12:$A$144,转会市场!$F$12:$F$144="【AWO】逃出'生天"),"") | C20: =IFERROR(_xlfn._xlws.FILTER(转会市场!$C$12:$C$144,转会市场!$F$12:$F$144="【AWO】逃出'生天"),"")
B21: =IFERROR(_xlfn._xlws.FILTER(转会市场!$A$12:$A$144,转会市场!$F$12:$F$144="【AWO】逃出'生天"),"") | C21: =IFERROR(_xlfn._xlws.FILTER(转会市场!$C$12:$C$144,转会市场!$F$12:$F$144="【AWO】逃出'生天"),"")
B22: =IFERROR(_xlfn._xlws.FILTER(转会市场!$A$12:$A$144,转会市场!$F$12:$F$144="【AWO】逃出'生天"),"") | C22: =IFERROR(_xlfn._xlws.FILTER(转会市场!$C$12:$C$144,转会市场!$F$12:$F$144="【AWO】逃出'生天"),"")
B23: 总身价 | F23: 总身价 | J23: 总身价 | N23: 总身价
B24: =SUM(C4:C23) -> 2980 | F24: =SUM(G4:G23) -> 3000 | J24: =SUM(K4:K23) -> 2970 | N24: =SUM(O4:O23) -> 2370
B25: =IFERROR(_xlfn._xlws.FILTER(转会市场!$A$12:$A$144,转会市场!$F$12:$F$144="【AWO】逃出'生天"),"") | C25: =IFERROR(_xlfn._xlws.FILTER(转会市场!$C$12:$C$144,转会市场!$F$12:$F$144="【AWO】逃出'生天"),"")
B26: =IFERROR(_xlfn._xlws.FILTER(转会市场!$A$12:$A$144,转会市场!$F$12:$F$144="【AWO】逃出'生天"),"") | C26: =IFERROR(_xlfn._xlws.FILTER(转会市场!$C$12:$C$144,转会市场!$F$12:$F$144="【AWO】逃出'生天"),"")
B27: =IFERROR(_xlfn._xlws.FILTER(转会市场!$A$12:$A$144,转会市场!$F$12:$F$144="【AWO】逃出'生天"),"") | C27: =IFERROR(_xlfn._xlws.FILTER(转会市场!$C$12:$C$144,转会市场!$F$12:$F$144="【AWO】逃出'生天"),"")
B28: =IFERROR(_xlfn._xlws.FILTER(转会市场!$A$12:$A$144,转会市场!$F$12:$F$144="【AWO】逃出'生天"),"") | C28: =IFERROR(_xlfn._xlws.FILTER(转会市场!$C$12:$C$144,转会市场!$F$12:$F$144="【AWO】逃出'生天"),"")
B29: =IFERROR(_xlfn._xlws.FILTER(转会市场!$A$12:$A$144,转会市场!$F$12:$F$144="【AWO】逃出'生天"),"") | C29: =IFERROR(_xlfn._xlws.FILTER(转会市场!$C$12:$C$144,转会市场!$F$12:$F$144="【AWO】逃出'生天"),"")
B30: =IFERROR(_xlfn._xlws.FILTER(转会市场!$A$12:$A$144,转会市场!$F$12:$F$144="【AWO】逃出'生天"),"") | C30: =IFERROR(_xlfn._xlws.FILTER(转会市场!$C$12:$C$144,转会市场!$F$12:$F$144="【AWO】逃出'生天"),"")
B31: =IFERROR(_xlfn._xlws.FILTER(转会市场!$A$12:$A$144,转会市场!$F$12:$F$144="【AWO】逃出'生天"),"") | C31: =IFERROR(_xlfn._xlws.FILTER(转会市场!$C$12:$C$144,转会市场!$F$12:$F$144="【AWO】逃出'生天"),"")
B32: =IFERROR(_xlfn._xlws.FILTER(转会市场!$A$12:$A$144,转会市场!$F$12:$F$144="【AWO】逃出'生天"),"") | C32: =IFERROR(_xlfn._xlws.FILTER(转会市场!$C$12:$C$144,转会市场!$F$12:$F$144="【AWO】逃出'生天"),"")
B33: =IFERROR(_xlfn._xlws.FILTER(转会市场!$A$12:$A$144,转会市场!$F$12:$F$144="【AWO】逃出'生天"),"") | C33: =IFERROR(_xlfn._xlws.FILTER(转会市场!$C$12:$C$144,转会市场!$F$12:$F$144="【AWO】逃出'生天"),"")
B34: 【G2】G2 <2682175052> | F34: 【TV】Team Vitality <1574911366> | J34: 【Miniworld】迷你世界 <2668013893> | N34: 【NikoFC】NikoCN Fanclub <1847932439>
B35: 常用昵称 | C35: 身价（单位:w） | D35: 梦幻联赛ID | F35: 常用昵称 | G35: 身价（单位:w） | H35: 梦幻联赛ID | J35: 常用昵称 | K35: 身价（单位:w） | L35: 梦幻联赛ID | N35: 常用昵称 | O35: 身价（单位:w） | P35: 梦幻联赛ID
B36: Zekken | C36: 800 | F36: zy | G36: 800 | J36: nane | K36: 250 | N36: 骑砍真神 | O36: 300
B37: {=IFERROR(_xlfn._xlws.FILTER(交易历史!$A$12:$A$210,(交易历史!$F$12:$F$210="【G2】G2")*(交易历史!$H$12:$H$210=1)),"")} -> xiaoliyu | C37: {=IFERROR(_xlfn._xlws.FILTER(交易历史!$G$12:$G$210,(交易历史!$C$12:$C$210="【G2】G2")*(交易历史!$H$12:$H$210=1)),"")} -> 0 | F37: {=IFERROR(_xlfn._xlws.FILTER(交易历史!$A$12:$A$210,(交易历史!$F$12:$F$210="【TV】Team Vitality")*(交易历史!$H$12:$H$210=1)),"")} -> f4 | G37: {=IFERROR(_xlfn._xlws.FILTER(交易历史!$G$12:$G$210,(交易历史!$C$12:$C$210="【TV】Team Vitality")*(交易历史!$H$12:$H$210=1)),"")} -> 600 | J37: {=IFERROR(_xlfn._xlws.FILTER(交易历史!$A$12:$A$210,(交易历史!$F$12:$F$210="【Miniworld】迷你世界")*(交易历史!$H$12:$H$210=1)),"")} -> 哭丧 | K37: {=IFERROR(_xlfn._xlws.FILTER(交易历史!$G$12:$G$210,(交易历史!$C$12:$C$210="【Miniworld】迷你世界")*(交易历史!$H$12:$H$210=1)),"")} -> 80 | N37: {=IFERROR(_xlfn._xlws.FILTER(交易历史!$A$12:$A$210,(交易历史!$F$12:$F$210="【NikoFC】NikoCN Fanclub")*(交易历史!$H$12:$H$210=1)),"")} -> awe23 | O37: {=IFERROR(_xlfn._xlws.FILTER(交易历史!$G$12:$G$210,(交易历史!$C$12:$C$210="【NikoFC】NikoCN Fanclub")*(交易历史!$H$12:$H$210=1)),"")} -> 320
B38: 233laoye | C38: 1000 | F38: abin | G38: 10 | J38: Tatum | K38: 350 | N38: Bonaoart | O38: 100
B39: 500 | C39: 0 | F39: AP-20 | G39: 20 | J39: KillerQuin | K39: 20 | N39: 果猫 | O39: 540
B40: Yoshino | C40: 350 | F40: 孟起 | G40: 20 | J40: 老鱼 | K40: 40 | N40: Mliya | O40: 50
B41: 末影 | C41: 190 | F41: Charlotte | G41: 60 | J41: AQI | K41: 20 | N41: YQS_dou_dou | O41: 30
B42: 大聪明、呆呆 | C42: 400 | F42: Lezalit | G42: 1000 | J42: Add | K42: 60 | N42: 淫荡 | O42: 510
B43: Maverick | C43: 140 | F43: 天帝哥哥 | G43: 10 | J43: Goganpa | K43: 30 | N43: comet | O43: 760
B44: 回火的头盖骨 | C44: 0 | F44: 冷夜 | G44: 20 | J44: diyuluguan | K44: 300 | N44: Gad_ALiang | O44: 10
B45: chengcheng | C45: 10 | F45: sy72sdf | G45: 120 | J45: 卡皇 | K45: 850 | N45: KT_riva | O45: 10
...

Sheet 队伍收入状况 
A1: 队伍名称 | B1: 队长ID | C1: 身价 | D1: 资金池 | E1: 剩余资金 | F1: 第一周奖金 | G1: 第二周奖金 | H1: 第三周奖金 | I1: 罚款 | J1: 道具使用
A2: 【CbHz】吃饱喝足就是玩 | B2: 冲锋 | C2: 750 | D2: =3000-C2+F2+G2+H2-I2-J2 -> 2250 | E2: =D2-SUMIFS(交易历史!B:B,交易历史!C:C,A2,交易历史!E:E,"首轮交易")+SUMIFS(交易历史!B:B,交易历史!D:D,A2,交易历史!E:E,"首轮交易")-SUMIFS(交易历史!B:B,交易历史!C:C,A2,交易历史!E:E,"二轮交易")+SUMIFS(交易历史!B:B,交易历史!D:D,A2,交易历史!E:E,"二轮交易")-SUMIFS(交易历史!B:B,交易历史!C:C,A2,交易历史!E:E,"三轮交易")+SUMIFS(交易历史!B:B,交易历史!D:D,A2,交易历史!E:E,"三轮交易")-SUMIFS(交易历史!B:B,交易历史!C:C,A2,交易历史!E:E,"四轮交易")+SUMIFS(交易历史!B:B,交易历史!D:D,A2,交易历史!E:E,"四轮交易") -> 20 | F2: =第一轮比赛!E14 -> 0 | G2: 0 | H2: 0 | I2: 0 | J2: 0
A3: 【SSR】Superior Super Rare | B3: 图派克 | C3: 450 | D3: =3000-C3+F3+G3+H3-I3-J3 -> 2550 | E3: =D3-SUMIFS(交易历史!B:B,交易历史!C:C,A3,交易历史!E:E,"首轮交易")+SUMIFS(交易历史!B:B,交易历史!D:D,A3,交易历史!E:E,"首轮交易")-SUMIFS(交易历史!B:B,交易历史!C:C,A3,交易历史!E:E,"二轮交易")+SUMIFS(交易历史!B:B,交易历史!D:D,A3,交易历史!E:E,"二轮交易")-SUMIFS(交易历史!B:B,交易历史!C:C,A3,交易历史!E:E,"三轮交易")+SUMIFS(交易历史!B:B,交易历史!D:D,A3,交易历史!E:E,"三轮交易")-SUMIFS(交易历史!B:B,交易历史!C:C,A3,交易历史!E:E,"四轮交易")+SUMIFS(交易历史!B:B,交易历史!D:D,A3,交易历史!E:E,"四轮交易") -> 0 | F3: =第一轮比赛!E15 -> 0 | G3: 0 | H3: 0 | I3: 0 | J3: 0
A4: 【OldH】老H犟嘴 | B4: 凯撒 | C4: 900 | D4: =3000-C4+F4+G4+H4-I4-J4 -> 2100 | E4: =D4-SUMIFS(交易历史!B:B,交易历史!C:C,A4,交易历史!E:E,"首轮交易")+SUMIFS(交易历史!B:B,交易历史!D:D,A4,交易历史!E:E,"首轮交易")-SUMIFS(交易历史!B:B,交易历史!C:C,A4,交易历史!E:E,"二轮交易")+SUMIFS(交易历史!B:B,交易历史!D:D,A4,交易历史!E:E,"二轮交易")-SUMIFS(交易历史!B:B,交易历史!C:C,A4,交易历史!E:E,"三轮交易")+SUMIFS(交易历史!B:B,交易历史!D:D,A4,交易历史!E:E,"三轮交易")-SUMIFS(交易历史!B:B,交易历史!C:C,A4,交易历史!E:E,"四轮交易")+SUMIFS(交易历史!B:B,交易历史!D:D,A4,交易历史!E:E,"四轮交易") -> 30 | F4: =第一轮比赛!E16 -> 0 | G4: 0 | H4: 0 | I4: 0 | J4: 0
A5: 【AWO】逃出生天 | B5: 小山楂 | C5: 800 | D5: =3000-C5+F5+G5+H5-I5-J5 -> 2200 | E5: =D5-SUMIFS(交易历史!B:B,交易历史!C:C,A5,交易历史!E:E,"首轮交易")+SUMIFS(交易历史!B:B,交易历史!D:D,A5,交易历史!E:E,"首轮交易")-SUMIFS(交易历史!B:B,交易历史!C:C,A5,交易历史!E:E,"二轮交易")+SUMIFS(交易历史!B:B,交易历史!D:D,A5,交易历史!E:E,"二轮交易")-SUMIFS(交易历史!B:B,交易历史!C:C,A5,交易历史!E:E,"三轮交易")+SUMIFS(交易历史!B:B,交易历史!D:D,A5,交易历史!E:E,"三轮交易")-SUMIFS(交易历史!B:B,交易历史!C:C,A5,交易历史!E:E,"四轮交易")+SUMIFS(交易历史!B:B,交易历史!D:D,A5,交易历史!E:E,"四轮交易") -> 630 | F5: =第一轮比赛!E17 -> 0 | G5: 0 | H5: 0 | I5: 0 | J5: 0
A6: 【G2】G2‭ | B6: 米子 | C6: 800 | D6: =3000-C6+F6+G6+H6-I6-J6 -> 2200 | E6: =D6-SUMIFS(交易历史!B:B,交易历史!C:C,A6,交易历史!E:E,"首轮交易")+SUMIFS(交易历史!B:B,交易历史!D:D,A6,交易历史!E:E,"首轮交易")-SUMIFS(交易历史!B:B,交易历史!C:C,A6,交易历史!E:E,"二轮交易")+SUMIFS(交易历史!B:B,交易历史!D:D,A6,交易历史!E:E,"二轮交易")-SUMIFS(交易历史!B:B,交易历史!C:C,A6,交易历史!E:E,"三轮交易")+SUMIFS(交易历史!B:B,交易历史!D:D,A6,交易历史!E:E,"三轮交易")-SUMIFS(交易历史!B:B,交易历史!C:C,A6,交易历史!E:E,"四轮交易")+SUMIFS(交易历史!B:B,交易历史!D:D,A6,交易历史!E:E,"四轮交易") -> 90 | F6: =第一轮比赛!E18 -> 0 | G6: 0 | H6: 0 | I6: 0 | J6: 0
A7: 【TV】Team Vitality | B7: 赵毅 | C7: 800 | D7: =3000-C7+F7+G7+H7-I7-J7 -> 2200 | E7: =D7-SUMIFS(交易历史!B:B,交易历史!C:C,A7,交易历史!E:E,"首轮交易")+SUMIFS(交易历史!B:B,交易历史!D:D,A7,交易历史!E:E,"首轮交易")-SUMIFS(交易历史!B:B,交易历史!C:C,A7,交易历史!E:E,"二轮交易")+SUMIFS(交易历史!B:B,交易历史!D:D,A7,交易历史!E:E,"二轮交易")-SUMIFS(交易历史!B:B,交易历史!C:C,A7,交易历史!E:E,"三轮交易")+SUMIFS(交易历史!B:B,交易历史!D:D,A7,交易历史!E:E,"三轮交易")-SUMIFS(交易历史!B:B,交易历史!C:C,A7,交易历史!E:E,"四轮交易")+SUMIFS(交易历史!B:B,交易历史!D:D,A7,交易历史!E:E,"四轮交易") -> 90 | F7: =第一轮比赛!E19 -> 0 | G7: 0 | H7: 0 | I7: 0 | J7: 0
A8: 【Miniworld】迷你世界 | B8: nane | C8: 250 | D8: =3000-C8+F8+G8+H8-I8-J8 -> 2750 | E8: =D8-SUMIFS(交易历史!B:B,交易历史!C:C,A8,交易历史!E:E,"首轮交易")+SUMIFS(交易历史!B:B,交易历史!D:D,A8,交易历史!E:E,"首轮交易")-SUMIFS(交易历史!B:B,交易历史!C:C,A8,交易历史!E:E,"二轮交易")+SUMIFS(交易历史!B:B,交易历史!D:D,A8,交易历史!E:E,"二轮交易")-SUMIFS(交易历史!B:B,交易历史!C:C,A8,交易历史!E:E,"三轮交易")+SUMIFS(交易历史!B:B,交易历史!D:D,A8,交易历史!E:E,"三轮交易")-SUMIFS(交易历史!B:B,交易历史!C:C,A8,交易历史!E:E,"四轮交易")+SUMIFS(交易历史!B:B,交易历史!D:D,A8,交易历史!E:E,"四轮交易") -> 650 | F8: =第一轮比赛!E20 -> 0 | G8: 0 | H8: 0 | I8: 0 | J8: 0
A9: 【NikoFC】NikoCN Fanclub | B9: 梅森 | C9: 300 | D9: =3000-C9+F9+G9+H9-I9-J9 -> 2700 | E9: =D9-SUMIFS(交易历史!B:B,交易历史!C:C,A9,交易历史!E:E,"首轮交易")+SUMIFS(交易历史!B:B,交易历史!D:D,A9,交易历史!E:E,"首轮交易")-SUMIFS(交易历史!B:B,交易历史!C:C,A9,交易历史!E:E,"二轮交易")+SUMIFS(交易历史!B:B,交易历史!D:D,A9,交易历史!E:E,"二轮交易")-SUMIFS(交易历史!B:B,交易历史!C:C,A9,交易历史!E:E,"三轮交易")+SUMIFS(交易历史!B:B,交易历史!D:D,A9,交易历史!E:E,"三轮交易")-SUMIFS(交易历史!B:B,交易历史!C:C,A9,交易历史!E:E,"四轮交易")+SUMIFS(交易历史!B:B,交易历史!D:D,A9,交易历史!E:E,"四轮交易") -> 360 | F9: =第一轮比赛!E21 -> 0 | G9: 0 | H9: 0 | I9: 0 | J9: 0

Sheet 第一轮比赛
A1: 积分表
A2: 队伍名称 | B2: 积分 | C2: 净胜分 | D2: 得分 | E2: 失分 | F2: 胜图数
A3: 【Cbhz】 | B3: =SUM(IF(($E$25=A3)*(($F$25+$F$26)<>0),IF($F$25>$F$26,3,IF($F$25<$F$26,0,1)),0),IF(($E$27=A3)*(($F$27+$F$28)<>0),IF($F$27>$F$28,3,IF($F$27<$F$28,0,1)),0),IF(($E$29=A3)*(($F$29+$F$30)<>0),IF($F$29>$F$30,3,IF($F$29<$F$30,0,1)),0),IF(($E$31=A3)*(($F$31+$F$32)<>0),IF($F$31>$F$32,3,IF($F$31<$F$32,0,1)),0),IF(($E$33=A3)*(($F$33+$F$34)<>0),IF($F$33>$F$34,3,IF($F$33<$F$34,0,1)),0),IF(($E$35=A3)*(($F$35+$F$36)<>0),IF($F$35>$F$36,3,IF($F$35<$F$36,0,1)),0),IF(($E$37=A3)*(($F$37+$F$38)<>0),IF($F$37>$F$38,3,IF($F$37<$F$38,0,1)),0),IF(($E$39=A3)*(($F$39+$F$40)<>0),IF($F$39>$F$40,3,IF($F$39<$F$40,0,1)),0),IF(($E$26=A3)*(($F$25+$F$26)<>0),IF($F$26>$F$25,3,IF($F$26<$F$25,0,1)),0),IF(($E$28=A3)*(($F$27+$F$28)<>0),IF($F$28>$F$27,3,IF($F$28<$F$27,0,1)),0),IF(($E$30=A3)*(($F$29+$F$30)<>0),IF($F$30>$F$29,3,IF($F$30<$F$29,0,1)),0),IF(($E$32=A3)*(($F$31+$F$32)<>0),IF($F$32>$F$31,3,IF($F$32<$F$31,0,1)),0),IF(($E$34=A3)*(($F$33+$F$34)<>0),IF($F$34>$F$33,3,IF($F$34<$F$33,0,1)),0),IF(($E$36=A3)*(($F$35+$F$36)<>0),IF($F$36>$F$35,3,IF($F$36<$F$35,0,1)),0),IF(($E$38=A3)*(($F$37+$F$38)<>0),IF($F$38>$F$37,3,IF($F$38<$F$37,0,1)),0),IF(($E$40=A3)*(($F$39+$F$40)<>0),IF($F$40>$F$39,3,IF($F$40<$F$39,0,1)),0)) -> 0 | C3: =D3-E3 -> 0 | D3: {=SUMPRODUCT(IF($E$25:$E$40=A3,$F$25:$F$40,0))} -> 0 | E3: {=SUMPRODUCT(IF(($E$25:$E$40=A3)*(MOD(ROW($E$25:$E$40)-ROW($E$25),2)=0),OFFSET($F$25:$F$40,1,0),0))+SUMPRODUCT(IF(($E$25:$E$40=A3)*(MOD(ROW($E$25:$E$40)-ROW($E$25),2)=1),OFFSET($F$25:$F$40,-1,0),0))} -> 0 | F3: {=SUMPRODUCT(IF($E$25:$E$40=A3,$G$25:$G$40,0))} -> 0
A4: 【SSR】 | B4: =SUM(IF(($E$25=A4)*(($F$25+$F$26)<>0),IF($F$25>$F$26,3,IF($F$25<$F$26,0,1)),0),IF(($E$27=A4)*(($F$27+$F$28)<>0),IF($F$27>$F$28,3,IF($F$27<$F$28,0,1)),0),IF(($E$29=A4)*(($F$29+$F$30)<>0),IF($F$29>$F$30,3,IF($F$29<$F$30,0,1)),0),IF(($E$31=A4)*(($F$31+$F$32)<>0),IF($F$31>$F$32,3,IF($F$31<$F$32,0,1)),0),IF(($E$33=A4)*(($F$33+$F$34)<>0),IF($F$33>$F$34,3,IF($F$33<$F$34,0,1)),0),IF(($E$35=A4)*(($F$35+$F$36)<>0),IF($F$35>$F$36,3,IF($F$35<$F$36,0,1)),0),IF(($E$37=A4)*(($F$37+$F$38)<>0),IF($F$37>$F$38,3,IF($F$37<$F$38,0,1)),0),IF(($E$39=A4)*(($F$39+$F$40)<>0),IF($F$39>$F$40,3,IF($F$39<$F$40,0,1)),0),IF(($E$26=A4)*(($F$25+$F$26)<>0),IF($F$26>$F$25,3,IF($F$26<$F$25,0,1)),0),IF(($E$28=A4)*(($F$27+$F$28)<>0),IF($F$28>$F$27,3,IF($F$28<$F$27,0,1)),0),IF(($E$30=A4)*(($F$29+$F$30)<>0),IF($F$30>$F$29,3,IF($F$30<$F$29,0,1)),0),IF(($E$32=A4)*(($F$31+$F$32)<>0),IF($F$32>$F$31,3,IF($F$32<$F$31,0,1)),0),IF(($E$34=A4)*(($F$33+$F$34)<>0),IF($F$34>$F$33,3,IF($F$34<$F$33,0,1)),0),IF(($E$36=A4)*(($F$35+$F$36)<>0),IF($F$36>$F$35,3,IF($F$36<$F$35,0,1)),0),IF(($E$38=A4)*(($F$37+$F$38)<>0),IF($F$38>$F$37,3,IF($F$38<$F$37,0,1)),0),IF(($E$40=A4)*(($F$39+$F$40)<>0),IF($F$40>$F$39,3,IF($F$40<$F$39,0,1)),0)) -> 0 | C4: {=SUMPRODUCT(IF(($E$25:$E$40=A4)*(MOD(ROW($F$25:$F$40)-ROW($F$25),2)=0),$F$25:$F$40-OFFSET($F$25:$F$40,1,0),0))+SUMPRODUCT(IF(($E$25:$E$40=A4)*(MOD(ROW($F$25:$F$40)-ROW($F$25),2)=1),OFFSET($F$25:$F$40,-1,0)-$F$25:$F$40,0))} -> 0 | D4: =SUMPRODUCT((($E$25:$E$40="【SSR】")*($F$25:$F$40))) -> 0 | E4: {=SUMPRODUCT(IF(($E$25:$E$40=A4)*(MOD(ROW($E$25:$E$40)-ROW($E$25),2)=0),OFFSET($F$25:$F$40,1,0),0))+SUMPRODUCT(IF(($E$25:$E$40=A4)*(MOD(ROW($E$25:$E$40)-ROW($E$25),2)=1),OFFSET($F$25:$F$40,-1,0),0))} -> 0 | F4: {=SUMPRODUCT(IF($E$25:$E$40=A4,$G$25:$G$40,0))} -> 0
A5: 【OldH】 | B5: =SUM(IF(($E$25=A5)*(($F$25+$F$26)<>0),IF($F$25>$F$26,3,IF($F$25<$F$26,0,1)),0),IF(($E$27=A5)*(($F$27+$F$28)<>0),IF($F$27>$F$28,3,IF($F$27<$F$28,0,1)),0),IF(($E$29=A5)*(($F$29+$F$30)<>0),IF($F$29>$F$30,3,IF($F$29<$F$30,0,1)),0),IF(($E$31=A5)*(($F$31+$F$32)<>0),IF($F$31>$F$32,3,IF($F$31<$F$32,0,1)),0),IF(($E$33=A5)*(($F$33+$F$34)<>0),IF($F$33>$F$34,3,IF($F$33<$F$34,0,1)),0),IF(($E$35=A5)*(($F$35+$F$36)<>0),IF($F$35>$F$36,3,IF($F$35<$F$36,0,1)),0),IF(($E$37=A5)*(($F$37+$F$38)<>0),IF($F$37>$F$38,3,IF($F$37<$F$38,0,1)),0),IF(($E$39=A5)*(($F$39+$F$40)<>0),IF($F$39>$F$40,3,IF($F$39<$F$40,0,1)),0),IF(($E$26=A5)*(($F$25+$F$26)<>0),IF($F$26>$F$25,3,IF($F$26<$F$25,0,1)),0),IF(($E$28=A5)*(($F$27+$F$28)<>0),IF($F$28>$F$27,3,IF($F$28<$F$27,0,1)),0),IF(($E$30=A5)*(($F$29+$F$30)<>0),IF($F$30>$F$29,3,IF($F$30<$F$29,0,1)),0),IF(($E$32=A5)*(($F$31+$F$32)<>0),IF($F$32>$F$31,3,IF($F$32<$F$31,0,1)),0),IF(($E$34=A5)*(($F$33+$F$34)<>0),IF($F$34>$F$33,3,IF($F$34<$F$33,0,1)),0),IF(($E$36=A5)*(($F$35+$F$36)<>0),IF($F$36>$F$35,3,IF($F$36<$F$35,0,1)),0),IF(($E$38=A5)*(($F$37+$F$38)<>0),IF($F$38>$F$37,3,IF($F$38<$F$37,0,1)),0),IF(($E$40=A5)*(($F$39+$F$40)<>0),IF($F$40>$F$39,3,IF($F$40<$F$39,0,1)),0)) -> 0 | C5: {=SUMPRODUCT(IF(($E$25:$E$40=A5)*(MOD(ROW($F$25:$F$40)-ROW($F$25),2)=0),$F$25:$F$40-OFFSET($F$25:$F$40,1,0),0))+SUMPRODUCT(IF(($E$25:$E$40=A5)*(MOD(ROW($F$25:$F$40)-ROW($F$25),2)=1),OFFSET($F$25:$F$40,-1,0)-$F$25:$F$40,0))} -> 0 | D5: =SUMPRODUCT((($E$25:$E$40="【OldH】")*($F$25:$F$40))) -> 0 | E5: {=SUMPRODUCT(IF(($E$25:$E$40=A5)*(MOD(ROW($E$25:$E$40)-ROW($E$25),2)=0),OFFSET($F$25:$F$40,1,0),0))+SUMPRODUCT(IF(($E$25:$E$40=A5)*(MOD(ROW($E$25:$E$40)-ROW($E$25),2)=1),OFFSET($F$25:$F$40,-1,0),0))} -> 0 | F5: {=SUMPRODUCT(IF($E$25:$E$40=A5,$G$25:$G$40,0))} -> 0
A6: 【AWO】 | B6: =SUM(IF(($E$25=A6)*(($F$25+$F$26)<>0),IF($F$25>$F$26,3,IF($F$25<$F$26,0,1)),0),IF(($E$27=A6)*(($F$27+$F$28)<>0),IF($F$27>$F$28,3,IF($F$27<$F$28,0,1)),0),IF(($E$29=A6)*(($F$29+$F$30)<>0),IF($F$29>$F$30,3,IF($F$29<$F$30,0,1)),0),IF(($E$31=A6)*(($F$31+$F$32)<>0),IF($F$31>$F$32,3,IF($F$31<$F$32,0,1)),0),IF(($E$33=A6)*(($F$33+$F$34)<>0),IF($F$33>$F$34,3,IF($F$33<$F$34,0,1)),0),IF(($E$35=A6)*(($F$35+$F$36)<>0),IF($F$35>$F$36,3,IF($F$35<$F$36,0,1)),0),IF(($E$37=A6)*(($F$37+$F$38)<>0),IF($F$37>$F$38,3,IF($F$37<$F$38,0,1)),0),IF(($E$39=A6)*(($F$39+$F$40)<>0),IF($F$39>$F$40,3,IF($F$39<$F$40,0,1)),0),IF(($E$26=A6)*(($F$25+$F$26)<>0),IF($F$26>$F$25,3,IF($F$26<$F$25,0,1)),0),IF(($E$28=A6)*(($F$27+$F$28)<>0),IF($F$28>$F$27,3,IF($F$28<$F$27,0,1)),0),IF(($E$30=A6)*(($F$29+$F$30)<>0),IF($F$30>$F$29,3,IF($F$30<$F$29,0,1)),0),IF(($E$32=A6)*(($F$31+$F$32)<>0),IF($F$32>$F$31,3,IF($F$32<$F$31,0,1)),0),IF(($E$34=A6)*(($F$33+$F$34)<>0),IF($F$34>$F$33,3,IF($F$34<$F$33,0,1)),0),IF(($E$36=A6)*(($F$35+$F$36)<>0),IF($F$36>$F$35,3,IF($F$36<$F$35,0,1)),0),IF(($E$38=A6)*(($F$37+$F$38)<>0),IF($F$38>$F$37,3,IF($F$38<$F$37,0,1)),0),IF(($E$40=A6)*(($F$39+$F$40)<>0),IF($F$40>$F$39,3,IF($F$40<$F$39,0,1)),0)) -> 0 | C6: {=SUMPRODUCT(IF(($E$25:$E$40=A6)*(MOD(ROW($F$25:$F$40)-ROW($F$25),2)=0),$F$25:$F$40-OFFSET($F$25:$F$40,1,0),0))+SUMPRODUCT(IF(($E$25:$E$40=A6)*(MOD(ROW($F$25:$F$40)-ROW($F$25),2)=1),OFFSET($F$25:$F$40,-1,0)-$F$25:$F$40,0))} -> 0 | D6: =SUMPRODUCT((($E$25:$E$40="【AWO】")*($F$25:$F$40))) -> 0 | E6: {=SUMPRODUCT(IF(($E$25:$E$40=A6)*(MOD(ROW($E$25:$E$40)-ROW($E$25),2)=0),OFFSET($F$25:$F$40,1,0),0))+SUMPRODUCT(IF(($E$25:$E$40=A6)*(MOD(ROW($E$25:$E$40)-ROW($E$25),2)=1),OFFSET($F$25:$F$40,-1,0),0))} -> 0 | F6: {=SUMPRODUCT(IF($E$25:$E$40=A6,$G$25:$G$40,0))} -> 0
A7: 【G2】 | B7: =SUM(IF(($E$25=A7)*(($F$25+$F$26)<>0),IF($F$25>$F$26,3,IF($F$25<$F$26,0,1)),0),IF(($E$27=A7)*(($F$27+$F$28)<>0),IF($F$27>$F$28,3,IF($F$27<$F$28,0,1)),0),IF(($E$29=A7)*(($F$29+$F$30)<>0),IF($F$29>$F$30,3,IF($F$29<$F$30,0,1)),0),IF(($E$31=A7)*(($F$31+$F$32)<>0),IF($F$31>$F$32,3,IF($F$31<$F$32,0,1)),0),IF(($E$33=A7)*(($F$33+$F$34)<>0),IF($F$33>$F$34,3,IF($F$33<$F$34,0,1)),0),IF(($E$35=A7)*(($F$35+$F$36)<>0),IF($F$35>$F$36,3,IF($F$35<$F$36,0,1)),0),IF(($E$37=A7)*(($F$37+$F$38)<>0),IF($F$37>$F$38,3,IF($F$37<$F$38,0,1)),0),IF(($E$39=A7)*(($F$39+$F$40)<>0),IF($F$39>$F$40,3,IF($F$39<$F$40,0,1)),0),IF(($E$26=A7)*(($F$25+$F$26)<>0),IF($F$26>$F$25,3,IF($F$26<$F$25,0,1)),0),IF(($E$28=A7)*(($F$27+$F$28)<>0),IF($F$28>$F$27,3,IF($F$28<$F$27,0,1)),0),IF(($E$30=A7)*(($F$29+$F$30)<>0),IF($F$30>$F$29,3,IF($F$30<$F$29,0,1)),0),IF(($E$32=A7)*(($F$31+$F$32)<>0),IF($F$32>$F$31,3,IF($F$32<$F$31,0,1)),0),IF(($E$34=A7)*(($F$33+$F$34)<>0),IF($F$34>$F$33,3,IF($F$34<$F$33,0,1)),0),IF(($E$36=A7)*(($F$35+$F$36)<>0),IF($F$36>$F$35,3,IF($F$36<$F$35,0,1)),0),IF(($E$38=A7)*(($F$37+$F$38)<>0),IF($F$38>$F$37,3,IF($F$38<$F$37,0,1)),0),IF(($E$40=A7)*(($F$39+$F$40)<>0),IF($F$40>$F$39,3,IF($F$40<$F$39,0,1)),0)) -> 0 | C7: {=SUMPRODUCT(IF(($E$25:$E$40=A7)*(MOD(ROW($F$25:$F$40)-ROW($F$25),2)=0),$F$25:$F$40-OFFSET($F$25:$F$40,1,0),0))+SUMPRODUCT(IF(($E$25:$E$40=A7)*(MOD(ROW($F$25:$F$40)-ROW($F$25),2)=1),OFFSET($F$25:$F$40,-1,0)-$F$25:$F$40,0))} -> 0 | D7: =SUMPRODUCT((($E$25:$E$40="【G2】")*($F$25:$F$40))) -> 0 | E7: {=SUMPRODUCT(IF(($E$25:$E$40=A7)*(MOD(ROW($E$25:$E$40)-ROW($E$25),2)=0),OFFSET($F$25:$F$40,1,0),0))+SUMPRODUCT(IF(($E$25:$E$40=A7)*(MOD(ROW($E$25:$E$40)-ROW($E$25),2)=1),OFFSET($F$25:$F$40,-1,0),0))} -> 0 | F7: {=SUMPRODUCT(IF($E$25:$E$40=A7,$G$25:$G$40,0))} -> 0
A8: 【TV】 | B8: =SUM(IF(($E$25=A8)*(($F$25+$F$26)<>0),IF($F$25>$F$26,3,IF($F$25<$F$26,0,1)),0),IF(($E$27=A8)*(($F$27+$F$28)<>0),IF($F$27>$F$28,3,IF($F$27<$F$28,0,1)),0),IF(($E$29=A8)*(($F$29+$F$30)<>0),IF($F$29>$F$30,3,IF($F$29<$F$30,0,1)),0),IF(($E$31=A8)*(($F$31+$F$32)<>0),IF($F$31>$F$32,3,IF($F$31<$F$32,0,1)),0),IF(($E$33=A8)*(($F$33+$F$34)<>0),IF($F$33>$F$34,3,IF($F$33<$F$34,0,1)),0),IF(($E$35=A8)*(($F$35+$F$36)<>0),IF($F$35>$F$36,3,IF($F$35<$F$36,0,1)),0),IF(($E$37=A8)*(($F$37+$F$38)<>0),IF($F$37>$F$38,3,IF($F$37<$F$38,0,1)),0),IF(($E$39=A8)*(($F$39+$F$40)<>0),IF($F$39>$F$40,3,IF($F$39<$F$40,0,1)),0),IF(($E$26=A8)*(($F$25+$F$26)<>0),IF($F$26>$F$25,3,IF($F$26<$F$25,0,1)),0),IF(($E$28=A8)*(($F$27+$F$28)<>0),IF($F$28>$F$27,3,IF($F$28<$F$27,0,1)),0),IF(($E$30=A8)*(($F$29+$F$30)<>0),IF($F$30>$F$29,3,IF($F$30<$F$29,0,1)),0),IF(($E$32=A8)*(($F$31+$F$32)<>0),IF($F$32>$F$31,3,IF($F$32<$F$31,0,1)),0),IF(($E$34=A8)*(($F$33+$F$34)<>0),IF($F$34>$F$33,3,IF($F$34<$F$33,0,1)),0),IF(($E$36=A8)*(($F$35+$F$36)<>0),IF($F$36>$F$35,3,IF($F$36<$F$35,0,1)),0),IF(($E$38=A8)*(($F$37+$F$38)<>0),IF($F$38>$F$37,3,IF($F$38<$F$37,0,1)),0),IF(($E$40=A8)*(($F$39+$F$40)<>0),IF($F$40>$F$39,3,IF($F$40<$F$39,0,1)),0)) -> 0 | C8: {=SUMPRODUCT(IF(($E$25:$E$40=A8)*(MOD(ROW($F$25:$F$40)-ROW($F$25),2)=0),$F$25:$F$40-OFFSET($F$25:$F$40,1,0),0))+SUMPRODUCT(IF(($E$25:$E$40=A8)*(MOD(ROW($F$25:$F$40)-ROW($F$25),2)=1),OFFSET($F$25:$F$40,-1,0)-$F$25:$F$40,0))} -> 0 | D8: =SUMPRODUCT((($E$25:$E$40="【TV】")*($F$25:$F$40))) -> 0 | E8: {=SUMPRODUCT(IF(($E$25:$E$40=A8)*(MOD(ROW($E$25:$E$40)-ROW($E$25),2)=0),OFFSET($F$25:$F$40,1,0),0))+SUMPRODUCT(IF(($E$25:$E$40=A8)*(MOD(ROW($E$25:$E$40)-ROW($E$25),2)=1),OFFSET($F$25:$F$40,-1,0),0))} -> 0 | F8: {=SUMPRODUCT(IF($E$25:$E$40=A8,$G$25:$G$40,0))} -> 0
A9: 【Miniworld】 | B9: =SUM(IF(($E$25=A9)*(($F$25+$F$26)<>0),IF($F$25>$F$26,3,IF($F$25<$F$26,0,1)),0),IF(($E$27=A9)*(($F$27+$F$28)<>0),IF($F$27>$F$28,3,IF($F$27<$F$28,0,1)),0),IF(($E$29=A9)*(($F$29+$F$30)<>0),IF($F$29>$F$30,3,IF($F$29<$F$30,0,1)),0),IF(($E$31=A9)*(($F$31+$F$32)<>0),IF($F$31>$F$32,3,IF($F$31<$F$32,0,1)),0),IF(($E$33=A9)*(($F$33+$F$34)<>0),IF($F$33>$F$34,3,IF($F$33<$F$34,0,1)),0),IF(($E$35=A9)*(($F$35+$F$36)<>0),IF($F$35>$F$36,3,IF($F$35<$F$36,0,1)),0),IF(($E$37=A9)*(($F$37+$F$38)<>0),IF($F$37>$F$38,3,IF($F$37<$F$38,0,1)),0),IF(($E$39=A9)*(($F$39+$F$40)<>0),IF($F$39>$F$40,3,IF($F$39<$F$40,0,1)),0),IF(($E$26=A9)*(($F$25+$F$26)<>0),IF($F$26>$F$25,3,IF($F$26<$F$25,0,1)),0),IF(($E$28=A9)*(($F$27+$F$28)<>0),IF($F$28>$F$27,3,IF($F$28<$F$27,0,1)),0),IF(($E$30=A9)*(($F$29+$F$30)<>0),IF($F$30>$F$29,3,IF($F$30<$F$29,0,1)),0),IF(($E$32=A9)*(($F$31+$F$32)<>0),IF($F$32>$F$31,3,IF($F$32<$F$31,0,1)),0),IF(($E$34=A9)*(($F$33+$F$34)<>0),IF($F$34>$F$33,3,IF($F$34<$F$33,0,1)),0),IF(($E$36=A9)*(($F$35+$F$36)<>0),IF($F$36>$F$35,3,IF($F$36<$F$35,0,1)),0),IF(($E$38=A9)*(($F$37+$F$38)<>0),IF($F$38>$F$37,3,IF($F$38<$F$37,0,1)),0),IF(($E$40=A9)*(($F$39+$F$40)<>0),IF($F$40>$F$39,3,IF($F$40<$F$39,0,1)),0)) -> 0 | C9: {=SUMPRODUCT(IF(($E$25:$E$40=A9)*(MOD(ROW($F$25:$F$40)-ROW($F$25),2)=0),$F$25:$F$40-OFFSET($F$25:$F$40,1,0),0))+SUMPRODUCT(IF(($E$25:$E$40=A9)*(MOD(ROW($F$25:$F$40)-ROW($F$25),2)=1),OFFSET($F$25:$F$40,-1,0)-$F$25:$F$40,0))} -> 0 | D9: =SUMPRODUCT((($E$25:$E$40="【Miniworld】")*($F$25:$F$40))) -> 0 | E9: {=SUMPRODUCT(IF(($E$25:$E$40=A9)*(MOD(ROW($E$25:$E$40)-ROW($E$25),2)=0),OFFSET($F$25:$F$40,1,0),0))+SUMPRODUCT(IF(($E$25:$E$40=A9)*(MOD(ROW($E$25:$E$40)-ROW($E$25),2)=1),OFFSET($F$25:$F$40,-1,0),0))} -> 0 | F9: {=SUMPRODUCT(IF($E$25:$E$40=A9,$G$25:$G$40,0))} -> 0
A10: 【NikoFC】 | B10: =SUM(IF(($E$25=A10)*(($F$25+$F$26)<>0),IF($F$25>$F$26,3,IF($F$25<$F$26,0,1)),0),IF(($E$27=A10)*(($F$27+$F$28)<>0),IF($F$27>$F$28,3,IF($F$27<$F$28,0,1)),0),IF(($E$29=A10)*(($F$29+$F$30)<>0),IF($F$29>$F$30,3,IF($F$29<$F$30,0,1)),0),IF(($E$31=A10)*(($F$31+$F$32)<>0),IF($F$31>$F$32,3,IF($F$31<$F$32,0,1)),0),IF(($E$33=A10)*(($F$33+$F$34)<>0),IF($F$33>$F$34,3,IF($F$33<$F$34,0,1)),0),IF(($E$35=A10)*(($F$35+$F$36)<>0),IF($F$35>$F$36,3,IF($F$35<$F$36,0,1)),0),IF(($E$37=A10)*(($F$37+$F$38)<>0),IF($F$37>$F$38,3,IF($F$37<$F$38,0,1)),0),IF(($E$39=A10)*(($F$39+$F$40)<>0),IF($F$39>$F$40,3,IF($F$39<$F$40,0,1)),0),IF(($E$26=A10)*(($F$25+$F$26)<>0),IF($F$26>$F$25,3,IF($F$26<$F$25,0,1)),0),IF(($E$28=A10)*(($F$27+$F$28)<>0),IF($F$28>$F$27,3,IF($F$28<$F$27,0,1)),0),IF(($E$30=A10)*(($F$29+$F$30)<>0),IF($F$30>$F$29,3,IF($F$30<$F$29,0,1)),0),IF(($E$32=A10)*(($F$31+$F$32)<>0),IF($F$32>$F$31,3,IF($F$32<$F$31,0,1)),0),IF(($E$34=A10)*(($F$33+$F$34)<>0),IF($F$34>$F$33,3,IF($F$34<$F$33,0,1)),0),IF(($E$36=A10)*(($F$35+$F$36)<>0),IF($F$36>$F$35,3,IF($F$36<$F$35,0,1)),0),IF(($E$38=A10)*(($F$37+$F$38)<>0),IF($F$38>$F$37,3,IF($F$38<$F$37,0,1)),0),IF(($E$40=A10)*(($F$39+$F$40)<>0),IF($F$40>$F$39,3,IF($F$40<$F$39,0,1)),0)) -> 0 | C10: {=SUMPRODUCT(IF(($E$25:$E$40=A10)*(MOD(ROW($F$25:$F$40)-ROW($F$25),2)=0),$F$25:$F$40-OFFSET($F$25:$F$40,1,0),0))+SUMPRODUCT(IF(($E$25:$E$40=A10)*(MOD(ROW($F$25:$F$40)-ROW($F$25),2)=1),OFFSET($F$25:$F$40,-1,0)-$F$25:$F$40,0))} -> 0 | D10: =SUMPRODUCT((($E$25:$E$40="【NikoFC】")*($F$25:$F$40))) -> 0 | E10: {=SUMPRODUCT(IF(($E$25:$E$40=A10)*(MOD(ROW($E$25:$E$40)-ROW($E$25),2)=0),OFFSET($F$25:$F$40,1,0),0))+SUMPRODUCT(IF(($E$25:$E$40=A10)*(MOD(ROW($E$25:$E$40)-ROW($E$25),2)=1),OFFSET($F$25:$F$40,-1,0),0))} -> 0 | F10: {=SUMPRODUCT(IF($E$25:$E$40=A10,$G$25:$G$40,0))} -> 0
A12: 比赛奖励金
A13: 队伍名称 | B13: 小分奖励 | C13: 胜图奖励 | D13: 劣势奖励 | E13: 总奖励
