Workbook
Name WebWps_Form: 报名表!$A$1:$M$118

Sheet 拍卖列表
A1: 2024年第二届梦幻联赛转会市场
A2: 队伍名称 | B2: 队伍资金 | C2: 剩余资金（单位：W） | D2: 账户状态 | E2: 队长名
A3: 【CbHz】吃饱喝足就是玩 | B3: =队伍收入状况!D2 -> 2250 | C3: =B3-SUMIFS(交易历史!B:B,交易历史!C:C,A3,交易历史!E:E,"首次交易")+SUMIFS(交易历史!B:B,交易历史!D:D,A3,交易历史!E:E,"首次交易")-SUMIFS(交易历史!B:B,交易历史!C:C,A3,交易历史!E:E,"二次交易")+SUMIFS(交易历史!B:B,交易历史!D:D,A3,交易历史!E:E,"二次交易")-SUMIFS(交易历史!B:B,交易历史!C:C,A3,交易历史!E:E,"三次交易")+SUMIFS(交易历史!B:B,交易历史!D:D,A3,交易历史!E:E,"三次交易")-SUMIFS(交易历史!B:B,交易历史!C:C,A3,交易历史!E:E,"四次交易")+SUMIFS(交易历史!B:B,交易历史!D:D,A3,交易历史!E:E,"四次交易") -> 20 | D3: =IF(C3<=0,"超支",IF(C3<=500,"即将超支，剩余"&TEXT(C3,"0")&"W第纳尔","资金状况良好")) -> 即将超支，剩余20W第纳尔 | E3: 冲锋
A4: 【SSR】Superior Super Rare | B4: =队伍收入状况!D3 -> 2550 | C4: =B4-SUMIFS(交易历史!B:B,交易历史!C:C,A4,交易历史!E:E,"首次交易")+SUMIFS(交易历史!B:B,交易历史!D:D,A4,交易历史!E:E,"首次交易")-SUMIFS(交易历史!B:B,交易历史!C:C,A4,交易历史!E:E,"二次交易")+SUMIFS(交易历史!B:B,交易历史!D:D,A4,交易历史!E:E,"二次交易")-SUMIFS(交易历史!B:B,交易历史!C:C,A4,交易历史!E:E,"三次交易")+SUMIFS(交易历史!B:B,交易历史!D:D,A4,交易历史!E:E,"三次交易")-SUMIFS(交易历史!B:B,交易历史!C:C,A4,交易历史!E:E,"四次交易")+SUMIFS(交易历史!B:B,交易历史!D:D,A4,交易历史!E:E,"四次交易") -> 0 | D4: =IF(C4<=0,"超支",IF(C4<=500,"即将超支，剩余"&TEXT(C4,"0")&"W第纳尔","资金状况良好")) -> 超支 | E4: 图派克
A5: 【OldH】老H犟嘴 | B5: =队伍收入状况!D4 -> 2100 | C5: =B5-SUMIFS(交易历史!B:B,交易历史!C:C,A5,交易历史!E:E,"首次交易")+SUMIFS(交易历史!B:B,交易历史!D:D,A5,交易历史!E:E,"首次交易")-SUMIFS(交易历史!B:B,交易历史!C:C,A5,交易历史!E:E,"二次交易")+SUMIFS(交易历史!B:B,交易历史!D:D,A5,交易历史!E:E,"二次交易")-SUMIFS(交易历史!B:B,交易历史!C:C,A5,交易历史!E:E,"三次交易")+SUMIFS(交易历史!B:B,交易历史!D:D,A5,交易历史!E:E,"三次交易")-SUMIFS(交易历史!B:B,交易历史!C:C,A5,交易历史!E:E,"四次交易")+SUMIFS(交易历史!B:B,交易历史!D:D,A5,交易历史!E:E,"四次交易") -> 30 | D5: =IF(C5<=0,"超支",IF(C5<=500,"即将超支，剩余"&TEXT(C5,"0")&"W第纳尔","资金状况良好")) -> 即将超支，剩余30W第纳尔 | E5: 凯撒
A6: 【AWO】逃出生天 | B6: =队伍收入状况!D5 -> 2200 | C6: =B6-SUMIFS(交易历史!B:B,交易历史!C:C,A6,交易历史!E:E,"首次交易")+SUMIFS(交易历史!B:B,交易历史!D:D,A6,交易历史!E:E,"首次交易")-SUMIFS(交易历史!B:B,交易历史!C:C,A6,交易历史!E:E,"二次交易")+SUMIFS(交易历史!B:B,交易历史!D:D,A6,交易历史!E:E,"二次交易")-SUMIFS(交易历史!B:B,交易历史!C:C,A6,交易历史!E:E,"三次交易")+SUMIFS(交易历史!B:B,交易历史!D:D,A6,交易历史!E:E,"三次交易")-SUMIFS(交易历史!B:B,交易历史!C:C,A6,交易历史!E:E,"四次交易")+SUMIFS(交易历史!B:B,交易历史!D:D,A6,交易历史!E:E,"四次交易") -> 630 | D6: =IF(C6<=0,"超支",IF(C6<=500,"即将超支，剩余"&TEXT(C6,"0")&"W第纳尔","资金状况良好")) -> 资金状况良好 | E6: 小山楂
A7: 【G2】G2‭ | B7: =队伍收入状况!D6 -> 2200 | C7: =B7-SUMIFS(交易历史!B:B,交易历史!C:C,A7,交易历史!E:E,"首次交易")+SUMIFS(交易历史!B:B,交易历史!D:D,A7,交易历史!E:E,"首次交易")-SUMIFS(交易历史!B:B,交易历史!C:C,A7,交易历史!E:E,"二次交易")+SUMIFS(交易历史!B:B,交易历史!D:D,A7,交易历史!E:E,"二次交易")-SUMIFS(交易历史!B:B,交易历史!C:C,A7,交易历史!E:E,"三次交易")+SUMIFS(交易历史!B:B,交易历史!D:D,A7,交易历史!E:E,"三次交易")-SUMIFS(交易历史!B:B,交易历史!C:C,A7,交易历史!E:E,"四次交易")+SUMIFS(交易历史!B:B,交易历史!D:D,A7,交易历史!E:E,"四次交易") -> 90 | D7: =IF(C7<=0,"超支",IF(C7<=500,"即将超支，剩余"&TEXT(C7,"0")&"W第纳尔","资金状况良好")) -> 即将超支，剩余90W第纳尔 | E7: 米子
A8: 【TV】Team Vitality | B8: =队伍收入状况!D7 -> 2200 | C8: =B8-SUMIFS(交易历史!B:B,交易历史!C:C,A8,交易历史!E:E,"首次交易")+SUMIFS(交易历史!B:B,交易历史!D:D,A8,交易历史!E:E,"首次交易")-SUMIFS(交易历史!B:B,交易历史!C:C,A8,交易历史!E:E,"二次交易")+SUMIFS(交易历史!B:B,交易历史!D:D,A8,交易历史!E:E,"二次交易")-SUMIFS(交易历史!B:B,交易历史!C:C,A8,交易历史!E:E,"三次交易")+SUMIFS(交易历史!B:B,交易历史!D:D,A8,交易历史!E:E,"三次交易")-SUMIFS(交易历史!B:B,交易历史!C:C,A8,交易历史!E:E,"四次交易")+SUMIFS(交易历史!B:B,交易历史!D:D,A8,交易历史!E:E,"四次交易") -> 90 | D8: =IF(C8<=0,"超支",IF(C8<=500,"即将超支，剩余"&TEXT(C8,"0")&"W第纳尔","资金状况良好")) -> 即将超支，剩余90W第纳尔 | E8: 赵毅
A9: 【Miniworld】迷你世界 | B9: =队伍收入状况!D8 -> 2750 | C9: =B9-SUMIFS(交易历史!B:B,交易历史!C:C,A9,交易历史!E:E,"首次交易")+SUMIFS(交易历史!B:B,交易历史!D:D,A9,交易历史!E:E,"首次交易")-SUMIFS(交易历史!B:B,交易历史!C:C,A9,交易历史!E:E,"二次交易")+SUMIFS(交易历史!B:B,交易历史!D:D,A9,交易历史!E:E,"二次交易")-SUMIFS(交易历史!B:B,交易历史!C:C,A9,交易历史!E:E,"三次交易")+SUMIFS(交易历史!B:B,交易历史!D:D,A9,交易历史!E:E,"三次交易")-SUMIFS(交易历史!B:B,交易历史!C:C,A9,交易历史!E:E,"四次交易")+SUMIFS(交易历史!B:B,交易历史!D:D,A9,交易历史!E:E,"四次交易") -> 650 | D9: =IF(C9<=0,"超支",IF(C9<=500,"即将超支，剩余"&TEXT(C9,"0")&"W第纳尔","资金状况良好")) -> 资金状况良好 | E9: nane
A10: 【NikoFC】NikoCN Fanclub | B10: =队伍收入状况!D9 -> 2700 | C10: =B10-SUMIFS(交易历史!B:B,交易历史!C:C,A10,交易历史!E:E,"首次交易")+SUMIFS(交易历史!B:B,交易历史!D:D,A10,交易历史!E:E,"首次交易")-SUMIFS(交易历史!B:B,交易历史!C:C,A10,交易历史!E:E,"二次交易")+SUMIFS(交易历史!B:B,交易历史!D:D,A10,交易历史!E:E,"二次交易")-SUMIFS(交易历史!B:B,交易历史!C:C,A10,交易历史!E:E,"三次交易")+SUMIFS(交易历史!B:B,交易历史!D:D,A10,交易历史!E:E,"三次交易")-SUMIFS(交易历史!B:B,交易历史!C:C,A10,交易历史!E:E,"四次交易")+SUMIFS(交易历史!B:B,交易历史!D:D,A10,交易历史!E:E,"四次交易") -> 360 | D10: =IF(C10<=0,"超支",IF(C10<=500,"即将超支，剩余"&TEXT(C10,"0")&"W第纳尔","资金状况良好")) -> 即将超支，剩余360W第纳尔 | E10: 梅森
A11: 常用昵称 | B11: 报名ID | C11: 最高身价（单位：W） | D11: 当前队伍（出价最高队） | E11: 球员目前状态
A12: xiaoliyu | B12: JackeyLove | C12: =_xlfn.MAXIFS(交易历史!B:B,交易历史!A:A,A12) -> 0 | D12: =INDEX(交易历史!C:C,MATCH(A12,交易历史!A:A,0)) -> 【G2】G2‭ | E12: =IF(AND(NOT(ISBLANK(C12)),NOT(ISBLANK(D12)),ISERROR(SEARCH("流拍待定",D12))),"球员已拍定",IF(ISNUMBER(SEARCH("流拍待定",D12)),"流拍待定",IF(AND(OR(ISBLANK(C12),ISBLANK(D12)),NOT(ISBLANK(C11)),NOT(ISBLANK(D11))),"正在竞拍",""))) -> 球员已拍定
A13: 小鱼 | B13: 18SadYu | C13: =_xlfn.MAXIFS(交易历史!B:B,交易历史!A:A,A13) -> 80 | D13: =INDEX(交易历史!C:C,MATCH(A13,交易历史!A:A,0)) -> 【SSR】Superior Super Rare | E13: =IF(AND(NOT(ISBLANK(C13)),NOT(ISBLANK(D13)),ISERROR(SEARCH("流拍待定",D13))),"球员已拍定",IF(ISNUMBER(SEARCH("流拍待定",D13)),"流拍待定",IF(AND(OR(ISBLANK(C13),ISBLANK(D13)),NOT(ISBLANK(C12)),NOT(ISBLANK(D12))),"正在竞拍",""))) -> 球员已拍定
A14: Mengdong | B14: Mengdong | C14: =_xlfn.MAXIFS(交易历史!B:B,交易历史!A:A,A14) -> 0 | D14: =INDEX(交易历史!C:C,MATCH(A14,交易历史!A:A,0)) -> 【AWO】逃出生天 | E14: =IF(AND(NOT(ISBLANK(C14)),NOT(ISBLANK(D14)),ISERROR(SEARCH("流拍待定",D14))),"球员已拍定",IF(ISNUMBER(SEARCH("流拍待定",D14)),"流拍待定",IF(AND(OR(ISBLANK(C14),ISBLANK(D14)),NOT(ISBLANK(C13)),NOT(ISBLANK(D13))),"正在竞拍",""))) -> 球员已拍定
A15: awe23 | B15: Lezafans | C15: =_xlfn.MAXIFS(交易历史!B:B,交易历史!A:A,A15) -> 320 | D15: =INDEX(交易历史!C:C,MATCH(A15,交易历史!A:A,0)) -> 【NikoFC】NikoCN Fanclub | E15: =IF(AND(NOT(ISBLANK(C15)),NOT(ISBLANK(D15)),ISERROR(SEARCH("流拍待定",D15))),"球员已拍定",IF(ISNUMBER(SEARCH("流拍待定",D15)),"流拍待定",IF(AND(OR(ISBLANK(C15),ISBLANK(D15)),NOT(ISBLANK(C14)),NOT(ISBLANK(D14))),"正在竞拍",""))) -> 球员已拍定
A16: 史蒂夫 | B16: [Vinland]Steve | C16: =_xlfn.MAXIFS(交易历史!B:B,交易历史!A:A,A16) -> 400 | D16: =INDEX(交易历史!C:C,MATCH(A16,交易历史!A:A,0)) -> 【SSR】Superior Super Rare | E16: =IF(AND(NOT(ISBLANK(C16)),NOT(ISBLANK(D16)),ISERROR(SEARCH("流拍待定",D16))),"球员已拍定",IF(ISNUMBER(SEARCH("流拍待定",D16)),"流拍待定",IF(AND(OR(ISBLANK(C16),ISBLANK(D16)),NOT(ISBLANK(C15)),NOT(ISBLANK(D15))),"正在竞拍",""))) -> 球员已拍定
A17: f4 | B17: quandouwushILing | C17: =_xlfn.MAXIFS(交易历史!B:B,交易历史!A:A,A17) -> 600 | D17: =INDEX(交易历史!C:C,MATCH(A17,交易历史!A:A,0)) -> 【TV】Team Vitality | E17: =IF(AND(NOT(ISBLANK(C17)),NOT(ISBLANK(D17)),ISERROR(SEARCH("流拍待定",D17))),"球员已拍定",IF(ISNUMBER(SEARCH("流拍待定",D17)),"流拍待定",IF(AND(OR(ISBLANK(C17),ISBLANK(D17)),NOT(ISBLANK(C16)),NOT(ISBLANK(D16))),"正在竞拍",""))) -> 球员已拍定
A18: Bonaoart | B18: Bonapart | C18: =_xlfn.MAXIFS(交易历史!B:B,交易历史!A:A,A18) -> 100 | D18: =INDEX(交易历史!C:C,MATCH(A18,交易历史!A:A,0)) -> 【NikoFC】NikoCN Fanclub | E18: =IF(AND(NOT(ISBLANK(C18)),NOT(ISBLANK(D18)),ISERROR(SEARCH("流拍待定",D18))),"球员已拍定",IF(ISNUMBER(SEARCH("流拍待定",D18)),"流拍待定",IF(AND(OR(ISBLANK(C18),ISBLANK(D18)),NOT(ISBLANK(C17)),NOT(ISBLANK(D17))),"正在竞拍",""))) -> 球员已拍定
A19: 哭丧 | B19: KUSANAGE | C19: =_xlfn.MAXIFS(交易历史!B:B,交易历史!A:A,A19) -> 80 | D19: =INDEX(交易历史!C:C,MATCH(A19,交易历史!A:A,0)) -> 【Miniworld】迷你世界 | E19: =IF(AND(NOT(ISBLANK(C19)),NOT(ISBLANK(D19)),ISERROR(SEARCH("流拍待定",D19))),"球员已拍定",IF(ISNUMBER(SEARCH("流拍待定",D19)),"流拍待定",IF(AND(OR(ISBLANK(C19),ISBLANK(D19)),NOT(ISBLANK(#REF!)),NOT(ISBLANK(#REF!))),"正在竞拍",""))) -> 球员已拍定
A20: abin | B20: abin | C20: =_xlfn.MAXIFS(交易历史!B:B,交易历史!A:A,A20) -> 10 | D20: =INDEX(交易历史!C:C,MATCH(A20,交易历史!A:A,0)) -> 【TV】Team Vitality | E20: =IF(AND(NOT(ISBLANK(C20)),NOT(ISBLANK(D20)),ISERROR(SEARCH("流拍待定",D20))),"球员已拍定",IF(ISNUMBER(SEARCH("流拍待定",D20)),"流拍待定",IF(AND(OR(ISBLANK(C20),ISBLANK(D20)),NOT(ISBLANK(C19)),NOT(ISBLANK(D19))),"正在竞拍",""))) -> 球员已拍定
A21: GJY | B21: Ak King | C21: =_xlfn.MAXIFS(交易历史!B:B,交易历史!A:A,A21) -> 0 | D21: =INDEX(交易历史!C:C,MATCH(A21,交易历史!A:A,0)) -> 【CbHz】吃饱喝足就是玩 | E21: =IF(AND(NOT(ISBLANK(C21)),NOT(ISBLANK(D21)),ISERROR(SEARCH("流拍待定",D21))),"球员已拍定",IF(ISNUMBER(SEARCH("流拍待定",D21)),"流拍待定",IF(AND(OR(ISBLANK(C21),ISBLANK(D21)),NOT(ISBLANK(C20)),NOT(ISBLANK(D20))),"正在竞拍",""))) -> 球员已拍定
A22: AP-20 | B22: AP-20 | C22: =_xlfn.MAXIFS(交易历史!B:B,交易历史!A:A,A22) -> 20 | D22: =INDEX(交易历史!C:C,MATCH(A22,交易历史!A:A,0)) -> 【TV】Team Vitality | E22: =IF(AND(NOT(ISBLANK(C22)),NOT(ISBLANK(D22)),ISERROR(SEARCH("流拍待定",D22))),"球员已拍定",IF(ISNUMBER(SEARCH("流拍待定",D22)),"流拍待定",IF(AND(OR(ISBLANK(C22),ISBLANK(D22)),NOT(ISBLANK(C21)),NOT(ISBLANK(D21))),"正在竞拍",""))) -> 球员已拍定
A23: 王水灵 | B23: wsl | C23: =_xlfn.MAXIFS(交易历史!B:B,交易历史!A:A,A23) -> 10 | D23: =INDEX(交易历史!C:C,MATCH(A23,交易历史!A:A,0)) -> 【SSR】Superior Super Rare | E23: =IF(AND(NOT(ISBLANK(C23)),NOT(ISBLANK(D23)),ISERROR(SEARCH("流拍待定",D23))),"球员已拍定",IF(ISNUMBER(SEARCH("流拍待定",D23)),"流拍待定",IF(AND(OR(ISBLANK(C23),ISBLANK(D23)),NOT(ISBLANK(C22)),NOT(ISBLANK(D22))),"正在竞拍",""))) -> 球员已拍定
A24: 豆子 | B24: HeiAnZhiWang | C24: =_xlfn.MAXIFS(交易历史!B:B,交易历史!A:A,A24) -> 660 | D24: =INDEX(交易历史!C:C,MATCH(A24,交易历史!A:A,0)) -> 【CbHz】吃饱喝足就是玩 | E24: =IF(AND(NOT(ISBLANK(C24)),NOT(ISBLANK(D24)),ISERROR(SEARCH("流拍待定",D24))),"球员已拍定",IF(ISNUMBER(SEARCH("流拍待定",D24)),"流拍待定",IF(AND(OR(ISBLANK(C24),ISBLANK(D24)),NOT(ISBLANK(C23)),NOT(ISBLANK(D23))),"正在竞拍",""))) -> 球员已拍定
A25: 果猫 | B25: sichuanmei | C25: =_xlfn.MAXIFS(交易历史!B:B,交易历史!A:A,A25) -> 540 | D25: =INDEX(交易历史!C:C,MATCH(A25,交易历史!A:A,0)) -> 【NikoFC】NikoCN Fanclub | E25: =IF(AND(NOT(ISBLANK(C25)),NOT(ISBLANK(D25)),ISERROR(SEARCH("流拍待定",D25))),"球员已拍定",IF(ISNUMBER(SEARCH("流拍待定",D25)),"流拍待定",IF(AND(OR(ISBLANK(C25),ISBLANK(D25)),NOT(ISBLANK(C24)),NOT(ISBLANK(D24))),"正在竞拍",""))) -> 球员已拍定
A26: 233laoye | B26: Super_Seal | C26: =_xlfn.MAXIFS(交易历史!B:B,交易历史!A:A,A26) -> 1000 | D26: =INDEX(交易历史!C:C,MATCH(A26,交易历史!A:A,0)) -> 【G2】G2‭ | E26: =IF(AND(NOT(ISBLANK(C26)),NOT(ISBLANK(D26)),ISERROR(SEARCH("流拍待定",D26))),"球员已拍定",IF(ISNUMBER(SEARCH("流拍待定",D26)),"流拍待定",IF(AND(OR(ISBLANK(C26),ISBLANK(D26)),NOT(ISBLANK(C25)),NOT(ISBLANK(D25))),"正在竞拍",""))) -> 球员已拍定
A27: Tatum | B27: Tatum | C27: =_xlfn.MAXIFS(交易历史!B:B,交易历史!A:A,A27) -> 350 | D27: =INDEX(交易历史!C:C,MATCH(A27,交易历史!A:A,0)) -> 【Miniworld】迷你世界 | E27: =IF(AND(NOT(ISBLANK(C27)),NOT(ISBLANK(D27)),ISERROR(SEARCH("流拍待定",D27))),"球员已拍定",IF(ISNUMBER(SEARCH("流拍待定",D27)),"流拍待定",IF(AND(OR(ISBLANK(C27),ISBLANK(D27)),NOT(ISBLANK(C26)),NOT(ISBLANK(D26))),"正在竞拍",""))) -> 球员已拍定
A28: KillerQuin | B28: qifenzu | C28: =_xlfn.MAXIFS(交易历史!B:B,交易历史!A:A,A28) -> 20 | D28: =INDEX(交易历史!C:C,MATCH(A28,交易历史!A:A,0)) -> 【Miniworld】迷你世界 | E28: =IF(AND(NOT(ISBLANK(C28)),NOT(ISBLANK(D28)),ISERROR(SEARCH("流拍待定",D28))),"球员已拍定",IF(ISNUMBER(SEARCH("流拍待定",D28)),"流拍待定",IF(AND(OR(ISBLANK(C28),ISBLANK(D28)),NOT(ISBLANK(C27)),NOT(ISBLANK(D27))),"正在竞拍",""))) -> 球员已拍定
A29: 罗加 | B29: ZhouBaiYa | C29: =_xlfn.MAXIFS(交易历史!B:B,交易历史!A:A,A29) -> 0 | D29: =INDEX(交易历史!C:C,MATCH(A29,交易历史!A:A,0)) -> 【CbHz】吃饱喝足就是玩 | E29: =IF(AND(NOT(ISBLANK(C29)),NOT(ISBLANK(D29)),ISERROR(SEARCH("流拍待定",D29))),"球员已拍定",IF(ISNUMBER(SEARCH("流拍待定",D29)),"流拍待定",IF(AND(OR(ISBLANK(C29),ISBLANK(D29)),NOT(ISBLANK(C28)),NOT(ISBLANK(D28))),"正在竞拍",""))) -> 球员已拍定
A30: Luvv | B30: 05 | C30: =_xlfn.MAXIFS(交易历史!B:B,交易历史!A:A,A30) -> 200 | D30: =INDEX(交易历史!C:C,MATCH(A30,交易历史!A:A,0)) -> 【SSR】Superior Super Rare | E30: =IF(AND(NOT(ISBLANK(C30)),NOT(ISBLANK(D30)),ISERROR(SEARCH("流拍待定",D30))),"球员已拍定",IF(ISNUMBER(SEARCH("流拍待定",D30)),"流拍待定",IF(AND(OR(ISBLANK(C30),ISBLANK(D30)),NOT(ISBLANK(C29)),NOT(ISBLANK(D29))),"正在竞拍",""))) -> 球员已拍定
A31: 老鱼 | B31: 566 | C31: =_xlfn.MAXIFS(交易历史!B:B,交易历史!A:A,A31) -> 40 | D31: =INDEX(交易历史!C:C,MATCH(A31,交易历史!A:A,0)) -> 【Miniworld】迷你世界 | E31: =IF(AND(NOT(ISBLANK(C31)),NOT(ISBLANK(D31)),ISERROR(SEARCH("流拍待定",D31))),"球员已拍定",IF(ISNUMBER(SEARCH("流拍待定",D31)),"流拍待定",IF(AND(OR(ISBLANK(C31),ISBLANK(D31)),NOT(ISBLANK(C30)),NOT(ISBLANK(D30))),"正在竞拍",""))) -> 球员已拍定
... A66: Able | B66: Workwork | C66: =_xlfn.MAXIFS(交易历史!B:B,交易历史!A:A,A66) -> 410 | D66: =INDEX(交易历史!C:C,MATCH(A66,交易历史!A:A,0)) -> 【SSR】Superior Super Rare | E66: =IF(AND(NOT(ISBLANK(C66)),NOT(ISBLANK(D66)),ISERROR(SEARCH("流拍待定",D66))),"球员已拍定",IF(ISNUMBER(SEARCH("流拍待定",D66)),"流拍待定",IF(AND(OR(ISBLANK(C66),ISBLANK(D66)),NOT(ISBLANK(C65)),NOT(ISBLANK(D65))),"正在竞拍",""))) -> 球员已拍定
A67: 末影 | B67: lxclxc | C67: =_xlfn.MAXIFS(交易历史!B:B,交易历史!A:A,A67) -> 190 | D67: =INDEX(交易历史!C:C,MATCH(A67,交易历史!A:A,0)) -> 【G2】G2‭ | E67: =IF(AND(NOT(ISBLANK(C67)),NOT(ISBLANK(D67)),ISERROR(SEARCH("流拍待定",D67))),"球员已拍定",IF(ISNUMBER(SEARCH("流拍待定",D67)),"流拍待定",IF(AND(OR(ISBLANK(C67),ISBLANK(D67)),NOT(ISBLANK(#REF!)),NOT(ISBLANK(#REF!))),"正在竞拍",""))) -> 球员已拍定
A68: 城府 | B68: Jinzhaojianzhidieyunchu | C68: =_xlfn.MAXIFS(交易历史!B:B,交易历史!A:A,A68) -> 190 | D68: =INDEX(交易历史!C:C,MATCH(A68,交易历史!A:A,0)) -> 【AWO】逃出生天 | E68: =IF(AND(NOT(ISBLANK(C68)),NOT(ISBLANK(D68)),ISERROR(SEARCH("流拍待定",D68))),"球员已拍定",IF(ISNUMBER(SEARCH("流拍待定",D68)),"流拍待定",IF(AND(OR(ISBLANK(C68),ISBLANK(D68)),NOT(ISBLANK(C67)),NOT(ISBLANK(D67))),"正在竞拍",""))) -> 球员已拍定
A69: 苏雨晴 | B69: Elucoco | C69: =_xlfn.MAXIFS(交易历史!B:B,交易历史!A:A,A69) -> 350 | D69: =INDEX(交易历史!C:C,MATCH(A69,交易历史!A:A,0)) -> 【Miniworld】迷你世界 | E69: =IF(AND(NOT(ISBLANK(C69)),NOT(ISBLANK(D69)),ISERROR(SEARCH("流拍待定",D69))),"球员已拍定",IF(ISNUMBER(SEARCH("流拍待定",D69)),"流拍待定",IF(AND(OR(ISBLANK(C69),ISBLANK(D69)),NOT(ISBLANK(C68)),NOT(ISBLANK(D68))),"正在竞拍",""))) -> 球员已拍定
A70: Lezalit | B70: Yuukasama | C70: =_xlfn.MAXIFS(交易历史!B:B,交易历史!A:A,A70) -> 1000 | D70: =INDEX(交易历史!C:C,MATCH(A70,交易历史!A:A,0)) -> 【TV】Team Vitality | E70: =IF(AND(NOT(ISBLANK(C70)),NOT(ISBLANK(D70)),ISERROR(SEARCH("流拍待定",D70))),"球员已拍定",IF(ISNUMBER(SEARCH("流拍待定",D70)),"流拍待定",IF(AND(OR(ISBLANK(C70),ISBLANK(D70)),NOT(ISBLANK(C69)),NOT(ISBLANK(D69))),"正在竞拍",""))) -> 球员已拍定
A71: knightzz | B71: knightzz | C71: =_xlfn.MAXIFS(交易历史!B:B,交易历史!A:A,A71) -> 850 | D71: =INDEX(交易历史!C:C,MATCH(A71,交易历史!A:A,0)) -> 【AWO】逃出生天 | E71: =IF(AND(NOT(ISBLANK(C71)),NOT(ISBLANK(D71)),ISERROR(SEARCH("流拍待定",D71))),"球员已拍定",IF(ISNUMBER(SEARCH("流拍待定",D71)),"流拍待定",IF(AND(OR(ISBLANK(C71),ISBLANK(D71)),NOT(ISBLANK(C70)),NOT(ISBLANK(D70))),"正在竞拍",""))) -> 球员已拍定
A72: 天帝哥哥 | B72: TianDi | C72: =_xlfn.MAXIFS(交易历史!B:B,交易历史!A:A,A72) -> 10 | D72: =INDEX(交易历史!C:C,MATCH(A72,交易历史!A:A,0)) -> 【TV】Team Vitality | E72: =IF(AND(NOT(ISBLANK(C72)),NOT(ISBLANK(D72)),ISERROR(SEARCH("流拍待定",D72))),"球员已拍定",IF(ISNUMBER(SEARCH("流拍待定",D72)),"流拍待定",IF(AND(OR(ISBLANK(C72),ISBLANK(D72)),NOT(ISBLANK(C71)),NOT(ISBLANK(D71))),"正在竞拍",""))) -> 球员已拍定
A73: 冷夜 | B73: LengYe | C73: =_xlfn.MAXIFS(交易历史!B:B,交易历史!A:A,A73) -> 20 | D73: =INDEX(交易历史!C:C,MATCH(A73,交易历史!A:A,0)) -> 【TV】Team Vitality | E73: =IF(AND(NOT(ISBLANK(C73)),NOT(ISBLANK(D73)),ISERROR(SEARCH("流拍待定",D73))),"球员已拍定",IF(ISNUMBER(SEARCH("流拍待定",D73)),"流拍待定",IF(AND(OR(ISBLANK(C73),ISBLANK(D73)),NOT(ISBLANK(C72)),NOT(ISBLANK(D72))),"正在竞拍",""))) -> 球员已拍定
A74: 大聪明、呆呆 | B74: DaCongMing | C74: =_xlfn.MAXIFS(交易历史!B:B,交易历史!A:A,A74) -> 400 | D74: =INDEX(交易历史!C:C,MATCH(A74,交易历史!A:A,0)) -> 【G2】G2‭ | E74: =IF(AND(NOT(ISBLANK(C74)),NOT(ISBLANK(D74)),ISERROR(SEARCH("流拍待定",D74))),"球员已拍定",IF(ISNUMBER(SEARCH("流拍待定",D74)),"流拍待定",IF(AND(OR(ISBLANK(C74),ISBLANK(D74)),NOT(ISBLANK(C73)),NOT(ISBLANK(D73))),"正在竞拍",""))) -> 球员已拍定
...

Sheet 交易历史
A1: 球员昵称 | B1: 交易价格 | C1: 买入队伍 | D1: 卖出队伍 | E1: 交易窗口 | F1: 最终归属队伍 | G1: 最高身价
A2: xiaoliyu | B2: 0 | C2: 【G2】G2‭ | E2: 首次交易 | F2: {=IFERROR(INDEX(交易历史!C:C,MATCH(1,(交易历史!A:A=A2)*(交易历史!E:E="四次交易")+(交易历史!A:A=A2)*(交易历史!E:E="三次交易")+(交易历史!A:A=A2)*(交易历史!E:E="二次交易")+(交易历史!A:A=A2)*(交易历史!E:E="首次交易"),0)),"")} -> 【G2】G2‭ | G2: =IF(A2<>"",_xlfn.MAXIFS($B$2:$B$200,$A$2:$A$200,A2),"") -> 0
A3: 小鱼 | B3: 80 | C3: 【SSR】Superior Super Rare | E3: 首次交易 | F3: {=IFERROR(INDEX(交易历史!C:C,MATCH(1,(交易历史!A:A=A3)*(交易历史!E:E="四次交易")+(交易历史!A:A=A3)*(交易历史!E:E="三次交易")+(交易历史!A:A=A3)*(交易历史!E:E="二次交易")+(交易历史!A:A=A3)*(交易历史!E:E="首次交易"),0)),"")} -> 【SSR】Superior Super Rare | G3: =IF(A3<>"",_xlfn.MAXIFS($B$2:$B$200,$A$2:$A$200,A3),"") -> 80
A4: Mengdong | B4: 0 | C4: 【AWO】逃出生天 | E4: 首次交易 | F4: {=IFERROR(INDEX(交易历史!C:C,MATCH(1,(交易历史!A:A=A4)*(交易历史!E:E="四次交易")+(交易历史!A:A=A4)*(交易历史!E:E="三次交易")+(交易历史!A:A=A4)*(交易历史!E:E="二次交易")+(交易历史!A:A=A4)*(交易历史!E:E="首次交易"),0)),"")} -> 【AWO】逃出生天 | G4: =IF(A4<>"",_xlfn.MAXIFS($B$2:$B$200,$A$2:$A$200,A4),"") -> 0
A5: awe23 | B5: 320 | C5: 【NikoFC】NikoCN Fanclub | E5: 首次交易 | F5: {=IFERROR(INDEX(交易历史!C:C,MATCH(1,(交易历史!A:A=A5)*(交易历史!E:E="四次交易")+(交易历史!A:A=A5)*(交易历史!E:E="三次交易")+(交易历史!A:A=A5)*(交易历史!E:E="二次交易")+(交易历史!A:A=A5)*(交易历史!E:E="首次交易"),0)),"")} -> 【NikoFC】NikoCN Fanclub | G5: =IF(A5<>"",_xlfn.MAXIFS($B$2:$B$200,$A$2:$A$200,A5),"") -> 320
A6: 史蒂夫 | B6: 400 | C6: 【SSR】Superior Super Rare | E6: 首次交易 | F6: {=IFERROR(INDEX(交易历史!C:C,MATCH(1,(交易历史!A:A=A6)*(交易历史!E:E="四次交易")+(交易历史!A:A=A6)*(交易历史!E:E="三次交易")+(交易历史!A:A=A6)*(交易历史!E:E="二次交易")+(交易历史!A:A=A6)*(交易历史!E:E="首次交易"),0)),"")} -> 【SSR】Superior Super Rare | G6: =IF(A6<>"",_xlfn.MAXIFS($B$2:$B$200,$A$2:$A$200,A6),"") -> 400
A7: f4 | B7: 600 | C7: 【TV】Team Vitality | E7: 首次交易 | F7: {=IFERROR(INDEX(交易历史!C:C,MATCH(1,(交易历史!A:A=A7)*(交易历史!E:E="四次交易")+(交易历史!A:A=A7)*(交易历史!E:E="三次交易")+(交易历史!A:A=A7)*(交易历史!E:E="二次交易")+(交易历史!A:A=A7)*(交易历史!E:E="首次交易"),0)),"")} -> 【TV】Team Vitality | G7: =IF(A7<>"",_xlfn.MAXIFS($B$2:$B$200,$A$2:$A$200,A7),"") -> 600
A8: Bonaoart | B8: 100 | C8: 【NikoFC】NikoCN Fanclub | E8: 首次交易 | F8: {=IFERROR(INDEX(交易历史!C:C,MATCH(1,(交易历史!A:A=A8)*(交易历史!E:E="四次交易")+(交易历史!A:A=A8)*(交易历史!E:E="三次交易")+(交易历史!A:A=A8)*(交易历史!E:E="二次交易")+(交易历史!A:A=A8)*(交易历史!E:E="首次交易"),0)),"")} -> 【NikoFC】NikoCN Fanclub | G8: =IF(A8<>"",_xlfn.MAXIFS($B$2:$B$200,$A$2:$A$200,A8),"") -> 100
A9: 哭丧 | B9: 80 | C9: 【Miniworld】迷你世界 | E9: 首次交易 | F9: {=IFERROR(INDEX(交易历史!C:C,MATCH(1,(交易历史!A:A=A9)*(交易历史!E:E="四次交易")+(交易历史!A:A=A9)*(交易历史!E:E="三次交易")+(交易历史!A:A=A9)*(交易历史!E:E="二次交易")+(交易历史!A:A=A9)*(交易历史!E:E="首次交易"),0)),"")} -> 【Miniworld】迷你世界 | G9: =IF(A9<>"",_xlfn.MAXIFS($B$2:$B$200,$A$2:$A$200,A9),"") -> 80
A10: abin | B10: 10 | C10: 【TV】Team Vitality | E10: 首次交易 | F10: {=IFERROR(INDEX(交易历史!C:C,MATCH(1,(交易历史!A:A=A10)*(交易历史!E:E="四次交易")+(交易历史!A:A=A10)*(交易历史!E:E="三次交易")+(交易历史!A:A=A10)*(交易历史!E:E="二次交易")+(交易历史!A:A=A10)*(交易历史!E:E="首次交易"),0)),"")} -> 【TV】Team Vitality | G10: =IF(A10<>"",_xlfn.MAXIFS($B$2:$B$200,$A$2:$A$200,A10),"") -> 10
A11: GJY | B11: 0 | C11: 【CbHz】吃饱喝足就是玩 | E11: 首次交易 | F11: {=IFERROR(INDEX(交易历史!C:C,MATCH(1,(交易历史!A:A=A11)*(交易历史!E:E="四次交易")+(交易历史!A:A=A11)*(交易历史!E:E="三次交易")+(交易历史!A:A=A11)*(交易历史!E:E="二次交易")+(交易历史!A:A=A11)*(交易历史!E:E="首次交易"),0)),"")} -> 【CbHz】吃饱喝足就是玩 | G11: =IF(A11<>"",_xlfn.MAXIFS($B$2:$B$200,$A$2:$A$200,A11),"") -> 0
A12: AP-20 | B12: 20 | C12: 【TV】Team Vitality | E12: 首次交易 | F12: {=IFERROR(INDEX(交易历史!C:C,MATCH(1,(交易历史!A:A=A12)*(交易历史!E:E="四次交易")+(交易历史!A:A=A12)*(交易历史!E:E="三次交易")+(交易历史!A:A=A12)*(交易历史!E:E="二次交易")+(交易历史!A:A=A12)*(交易历史!E:E="首次交易"),0)),"")} -> 【TV】Team Vitality | G12: =IF(A12<>"",_xlfn.MAXIFS($B$2:$B$200,$A$2:$A$200,A12),"") -> 20
A13: 王水灵 | B13: 10 | C13: 【SSR】Superior Super Rare | E13: 首次交易 | F13: {=IFERROR(INDEX(交易历史!C:C,MATCH(1,(交易历史!A:A=A13)*(交易历史!E:E="四次交易")+(交易历史!A:A=A13)*(交易历史!E:E="三次交易")+(交易历史!A:A=A13)*(交易历史!E:E="二次交易")+(交易历史!A:A=A13)*(交易历史!E:E="首次交易"),0)),"")} -> 【SSR】Superior Super Rare | G13: =IF(A13<>"",_xlfn.MAXIFS($B$2:$B$200,$A$2:$A$200,A13),"") -> 10
... A83: 大西瓜 | B83: 100 | C83: 【OldH】老H犟嘴 | E83: 首次交易 | F83: {=IFERROR(INDEX(交易历史!C:C,MATCH(1,(交易历史!A:A=A83)*(交易历史!E:E="四次交易")+(交易历史!A:A=A83)*(交易历史!E:E="三次交易")+(交易历史!A:A=A83)*(交易历史!E:E="二次交易")+(交易历史!A:A=A83)*(交易历史!E:E="首次交易"),0)),"")} -> 【OldH】老H犟嘴 | G83: =IF(A83<>"",_xlfn.MAXIFS($B$2:$B$200,$A$2:$A$200,A83),"") -> 100
A84: 白露 | E84: 首次交易 | F84: {=IFERROR(INDEX(交易历史!C:C,MATCH(1,(交易历史!A:A=A84)*(交易历史!E:E="四次交易")+(交易历史!A:A=A84)*(交易历史!E:E="三次交易")+(交易历史!A:A=A84)*(交易历史!E:E="二次交易")+(交易历史!A:A=A84)*(交易历史!E:E="首次交易"),0)),"")} -> 0 | G84: =IF(A84<>"",_xlfn.MAXIFS($B$2:$B$200,$A$2:$A$200,A84),"") -> 0
A85: wind | E85: 首次交易 | F85: {=IFERROR(INDEX(交易历史!C:C,MATCH(1,(交易历史!A:A=A85)*(交易历史!E:E="四次交易")+(交易历史!A:A=A85)*(交易历史!E:E="三次交易")+(交易历史!A:A=A85)*(交易历史!E:E="二次交易")+(交易历史!A:A=A85)*(交易历史!E:E="首次交易"),0)),"")} -> 0 | G85: =IF(A85<>"",_xlfn.MAXIFS($B$2:$B$200,$A$2:$A$200,A85),"") -> 0
A86: 波澜 | E86: 首次交易 | F86: {=IFERROR(INDEX(交易历史!C:C,MATCH(1,(交易历史!A:A=A86)*(交易历史!E:E="四次交易")+(交易历史!A:A=A86)*(交易历史!E:E="三次交易")+(交易历史!A:A=A86)*(交易历史!E:E="二次交易")+(交易历史!A:A=A86)*(交易历史!E:E="首次交易"),0)),"")} -> 0 | G86: =IF(A86<>"",_xlfn.MAXIFS($B$2:$B$200,$A$2:$A$200,A86),"") -> 0
A87: YQS-Laozhongzhu | E87: 首次交易 | F87: {=IFERROR(INDEX(交易历史!C:C,MATCH(1,(交易历史!A:A=A87)*(交易历史!E:E="四次交易")+(交易历史!A:A=A87)*(交易历史!E:E="三次交易")+(交易历史!A:A=A87)*(交易历史!E:E="二次交易")+(交易历史!A:A=A87)*(交易历史!E:E="首次交易"),0)),"")} -> 0 | G87: =IF(A87<>"",_xlfn.MAXIFS($B$2:$B$200,$A$2:$A$200,A87),"") -> 0
A88: TNT | E88: 首次交易 | F88: {=IFERROR(INDEX(交易历史!C:C,MATCH(1,(交易历史!A:A=A88)*(交易历史!E:E="四次交易")+(交易历史!A:A=A88)*(交易历史!E:E="三次交易")+(交易历史!A:A=A88)*(交易历史!E:E="二次交易")+(交易历史!A:A=A88)*(交易历史!E:E="首次交易"),0)),"")} -> 0 | G88: =IF(A88<>"",_xlfn.MAXIFS($B$2:$B$200,$A$2:$A$200,A88),"") -> 0
A89: 天将 | E89: 首次交易 | F89: {=IFERROR(INDEX(交易历史!C:C,MATCH(1,(交易历史!A:A=A89)*(交易历史!E:E="四次交易")+(交易历史!A:A=A89)*(交易历史!E:E="三次交易")+(交易历史!A:A=A89)*(交易历史!E:E="二次交易")+(交易历史!A:A=A89)*(交易历史!E:E="首次交易"),0)),"")} -> 0 | G89: =IF(A89<>"",_xlfn.MAXIFS($B$2:$B$200,$A$2:$A$200,A89),"") -> 0
A90: Rapier | E90: 首次交易 | F90: {=IFERROR(INDEX(交易历史!C:C,MATCH(1,(交易历史!A:A=A90)*(交易历史!E:E="四次交易")+(交易历史!A:A=A90)*(交易历史!E:E="三次交易")+(交易历史!A:A=A90)*(交易历史!E:E="二次交易")+(交易历史!A:A=A90)*(交易历史!E:E="首次交易"),0)),"")} -> 0 | G90: =IF(A90<>"",_xlfn.MAXIFS($B$2:$B$200,$A$2:$A$200,A90),"") -> 0
A91: 鸡头 | E91: 首次交易 | F91: {=IFERROR(INDEX(交易历史!C:C,MATCH(1,(交易历史!A:A=A91)*(交易历史!E:E="四次交易")+(交易历史!A:A=A91)*(交易历史!E:E="三次交易")+(交易历史!A:A=A91)*(交易历史!E:E="二次交易")+(交易历史!A:A=A91)*(交易历史!E:E="首次交易"),0)),"")} -> 0 | G91: =IF(A91<>"",_xlfn.MAXIFS($B$2:$B$200,$A$2:$A$200,A91),"") -> 0
A92: 888 | E92: 首次交易 | F92: {=IFERROR(INDEX(交易历史!C:C,MATCH(1,(交易历史!A:A=A92)*(交易历史!E:E="四次交易")+(交易历史!A:A=A92)*(交易历史!E:E="三次交易")+(交易历史!A:A=A92)*(交易历史!E:E="二次交易")+(交易历史!A:A=A92)*(交易历史!E:E="首次交易"),0)),"")} -> 0 | G92: =IF(A92<>"",_xlfn.MAXIFS($B$2:$B$200,$A$2:$A$200,A92),"") -> 0
A93: 午马 | E93: 首次交易 | F93: {=IFERROR(INDEX(交易历史!C:C,MATCH(1,(交易历史!A:A=A93)*(交易历史!E:E="四次交易")+(交易历史!A:A=A93)*(交易历史!E:E="三次交易")+(交易历史!A:A=A93)*(交易历史!E:E="二次交易")+(交易历史!A:A=A93)*(交易历史!E:E="首次交易"),0)),"")} -> 0 | G93: =IF(A93<>"",_xlfn.MAXIFS($B$2:$B$200,$A$2:$A$200,A93),"") -> 0
A94: xp | E94: 首次交易 | F94: {=IFERROR(INDEX(交易历史!C:C,MATCH(1,(交易历史!A:A=A94)*(交易历史!E:E="四次交易")+(交易历史!A:A=A94)*(交易历史!E:E="三次交易")+(交易历史!A:A=A94)*(交易历史!E:E="二次交易")+(交易历史!A:A=A94)*(交易历史!E:E="首次交易"),0)),"")} -> 0 | G94: =IF(A94<>"",_xlfn.MAXIFS($B$2:$B$200,$A$2:$A$200,A94),"") -> 0
A95: 帅比大 | E95: 首次交易 | F95: {=IFERROR(INDEX(交易历史!C:C,MATCH(1,(交易历史!A:A=A95)*(交易历史!E:E="四次交易")+(交易历史!A:A=A95)*(交易历史!E:E="三次交易")+(交易历史!A:A=A95)*(交易历史!E:E="二次交易")+(交易历史!A:A=A95)*(交易历史!E:E="首次交易"),0)),"")} -> 0 | G95: =IF(A95<>"",_xlfn.MAXIFS($B$2:$B$200,$A$2:$A$200,A95),"") -> 0
... A115: 牢云 | E115: 首次交易 | F115: {=IFERROR(INDEX(交易历史!C:C,MATCH(1,(交易历史!A:A=A115)*(交易历史!E:E="四次交易")+(交易历史!A:A=A115)*(交易历史!E:E="三次交易")+(交易历史!A:A=A115)*(交易历史!E:E="二次交易")+(交易历史!A:A=A115)*(交易历史!E:E="首次交易"),0)),"")} -> 0 | G115: =IF(A115<>"",_xlfn.MAXIFS($B$2:$B$200,$A$2:$A$200,A115),"") -> 0
F116: {=IFERROR(INDEX(交易历史!C:C,MATCH(1,(交易历史!A:A=A116)*(交易历史!E:E="四次交易")+(交易历史!A:A=A116)*(交易历史!E:E="三次交易")+(交易历史!A:A=A116)*(交易历史!E:E="二次交易")+(交易历史!A:A=A116)*(交易历史!E:E="首次交易"),0)),"")} | G116: =IF(A116<>"",_xlfn.MAXIFS($B$2:$B$200,$A$2:$A$200,A116),"")
F117: {=IFERROR(INDEX(交易历史!C:C,MATCH(1,(交易历史!A:A=A117)*(交易历史!E:E="四次交易")+(交易历史!A:A=A117)*(交易历史!E:E="三次交易")+(交易历史!A:A=A117)*(交易历史!E:E="二次交易")+(交易历史!A:A=A117)*(交易历史!E:E="首次交易"),0)),"")} | G117: =IF(A117<>"",_xlfn.MAXIFS($B$2:$B$200,$A$2:$A$200,A117),"")
F118: {=IFERROR(INDEX(交易历史!C:C,MATCH(1,(交易历史!A:A=A118)*(交易历史!E:E="四次交易")+(交易历史!A:A=A118)*(交易历史!E:E="三次交易")+(交易历史!A:A=A118)*(交易历史!E:E="二次交易")+(交易历史!A:A=A118)*(交易历史!E:E="首次交易"),0)),"")} | G118: =IF(A118<>"",_xlfn.MAXIFS($B$2:$B$200,$A$2:$A$200,A118),"")
F119: {=IFERROR(INDEX(交易历史!C:C,MATCH(1,(交易历史!A:A=A119)*(交易历史!E:E="四次交易")+(交易历史!A:A=A119)*(交易历史!E:E="三次交易")+(交易历史!A:A=A119)*(交易历史!E:E="二次交易")+(交易历史!A:A=A119)*(交易历史!E:E="首次交易"),0)),"")} | G119: =IF(A119<>"",_xlfn.MAXIFS($B$2:$B$200,$A$2:$A$200,A119),"")
F120: {=IFERROR(INDEX(交易历史!C:C,MATCH(1,(交易历史!A:A=A120)*(交易历史!E:E="四次交易")+(交易历史!A:A=A120)*(交易历史!E:E="三次交易")+(交易历史!A:A=A120)*(交易历史!E:E="二次交易")+(交易历史!A:A=A120)*(交易历史!E:E="首次交易"),0)),"")} | G120: =IF(A120<>"",_xlfn.MAXIFS($B$2:$B$200,$A$2:$A$200,A120),"")
F121: {=IFERROR(INDEX(交易历史!C:C,MATCH(1,(交易历史!A:A=A121)*(交易历史!E:E="四次交易")+(交易历史!A:A=A121)*(交易历史!E:E="三次交易")+(交易历史!A:A=A121)*(交易历史!E:E="二次交易")+(交易历史!A:A=A121)*(交易历史!E:E="首次交易"),0)),"")} | G121: =IF(A121<>"",_xlfn.MAXIFS($B$2:$B$200,$A$2:$A$200,A121),"")
F122: {=IFERROR(INDEX(交易历史!C:C,MATCH(1,(交易历史!A:A=A122)*(交易历史!E:E="四次交易")+(交易历史!A:A=A122)*(交易历史!E:E="三次交易")+(交易历史!A:A=A122)*(交易历史!E:E="二次交易")+(交易历史!A:A=A122)*(交易历史!E:E="首次交易"),0)),"")} | G122: =IF(A122<>"",_xlfn.MAXIFS($B$2:$B$200,$A$2:$A$200,A122),"")
F123: {=IFERROR(INDEX(交易历史!C:C,MATCH(1,(交易历史!A:A=A123)*(交易历史!E:E="四次交易")+(交易历史!A:A=A123)*(交易历史!E:E="三次交易")+(交易历史!A:A=A123)*(交易历史!E:E="二次交易")+(交易历史!A:A=A123)*(交易历史!E:E="首次交易"),0)),"")} | G123: =IF(A123<>"",_xlfn.MAXIFS($B$2:$B$200,$A$2:$A$200,A123),"")
F124: {=IFERROR(INDEX(交易历史!C:C,MATCH(1,(交易历史!A:A=A124)*(交易历史!E:E="四次交易")+(交易历史!A:A=A124)*(交易历史!E:E="三次交易")+(交易历史!A:A=A124)*(交易历史!E:E="二次交易")+(交易历史!A:A=A124)*(交易历史!E:E="首次交易"),0)),"")} | G124: =IF(A124<>"",_xlfn.MAXIFS($B$2:$B$200,$A$2:$A$200,A124),"")
F125: {=IFERROR(INDEX(交易历史!C:C,MATCH(1,(交易历史!A:A=A125)*(交易历史!E:E="四次交易")+(交易历史!A:A=A125)*(交易历史!E:E="三次交易")+(交易历史!A:A=A125)*(交易历史!E:E="二次交易")+(交易历史!A:A=A125)*(交易历史!E:E="首次交易"),0)),"")} | G125: =IF(A125<>"",_xlfn.MAXIFS($B$2:$B$200,$A$2:$A$200,A125),"")
F126: {=IFERROR(INDEX(交易历史!C:C,MATCH(1,(交易历史!A:A=A126)*(交易历史!E:E="四次交易")+(交易历史!A:A=A126)*(交易历史!E:E="三次交易")+(交易历史!A:A=A126)*(交易历史!E:E="二次交易")+(交易历史!A:A=A126)*(交易历史!E:E="首次交易"),0)),"")} | G126: =IF(A126<>"",_xlfn.MAXIFS($B$2:$B$200,$A$2:$A$200,A126),"")
F127: {=IFERROR(INDEX(交易历史!C:C,MATCH(1,(交易历史!A:A=A127)*(交易历史!E:E="四次交易")+(交易历史!A:A=A127)*(交易历史!E:E="三次交易")+(交易历史!A:A=A127)*(交易历史!E:E="二次交易")+(交易历史!A:A=A127)*(交易历史!E:E="首次交易"),0)),"")} | G127: =IF(A127<>"",_xlfn.MAXIFS($B$2:$B$200,$A$2:$A$200,A127),"")
... F147: {=IFERROR(INDEX(交易历史!C:C,MATCH(1,(交易历史!A:A=A147)*(交易历史!E:E="四次交易")+(交易历史!A:A=A147)*(交易历史!E:E="三次交易")+(交易历史!A:A=A147)*(交易历史!E:E="二次交易")+(交易历史!A:A=A147)*(交易历史!E:E="首次交易"),0)),"")} | G147: =IF(A147<>"",_xlfn.MAXIFS($B$2:$B$200,$A$2:$A$200,A147),"")
...

Sheet 队伍总览
B2: 【Cbhz】吃饱喝足就是玩 <1944993273> | F2: 【SSR】Superior Super Rare <2764659592> | J2: 【OldH】老H犟嘴 <3320553061> | N2: 【AWO】逃出生天 <740221391>
B3: 常用昵称 | C3: 身价（单位:w） | D3: 总身价 | F3: 常用昵称 | G3: 身价（单位:w） | H3: 总身价 | J3: 常用昵称 | K3: 身价（单位:w） | L3: 总身价 | N3: 常用昵称 | O3: 身价（单位:w） | P3: 总身价
B4: 冲锋 | C4: 750 | D4: =SUM(C4:C19) -> 2980 | F4: 图派克 | G4: 450 | H4: =SUM(G4:G23) -> 3000 | J4: 凯撒 | K4: 900 | L4: =SUM(K4:K23) -> 2970 | N4: cooper | O4: 800 | P4: =SUM(O4:O23) -> 2370
B5: {=IFERROR(_xlfn._xlws.FILTER(交易历史!$A$2:$A$200,交易历史!$F$2:$F$200="【CbHz】吃饱喝足就是玩"),"")} -> GJY | C5: {=IFERROR(_xlfn._xlws.FILTER(交易历史!$G$2:$G$200,交易历史!$C$2:$C$200="【CbHz】吃饱喝足就是玩"),"")} -> 0 | F5: {=IFERROR(_xlfn._xlws.FILTER(交易历史!$A$2:$A$200,交易历史!$F$2:$F$200="【SSR】Superior Super Rare"),"")} -> 小鱼 | G5: {=IFERROR(_xlfn._xlws.FILTER(交易历史!$G$2:$G$200,交易历史!$F$2:$F$200="【SSR】Superior Super Rare"),"")} -> 80 | J5: {=IFERROR(_xlfn._xlws.FILTER(交易历史!$A$2:$A$200,交易历史!$F$2:$F$200="【OldH】老H犟嘴"),"")} -> 宝爹 | K5: {=IFERROR(_xlfn._xlws.FILTER(交易历史!$G$2:$G$200,交易历史!$F$2:$F$200="【OldH】老H犟嘴"),"")} -> 360 | N5: {=IFERROR(_xlfn._xlws.FILTER(交易历史!$A$2:$A$200,交易历史!$F$2:$F$200="【AWO】逃出生天"),"")} -> Mengdong | O5: {=IFERROR(_xlfn._xlws.FILTER(交易历史!$G$2:$G$200,交易历史!$F$2:$F$200="【AWO】逃出生天"),"")} -> 0
B6: 豆子 | C6: 660 | F6: 史蒂夫 | G6: 400 | J6: 苏西斯 | K6: 100 | N6: HorN_kukuko | O6: 20
B7: 罗加 | C7: 0 | F7: 王水灵 | G7: 10 | J7: Ezio | K7: 30 | N7: DH | O7: 130
B8: twocat | C8: 0 | F8: Luvv | G8: 200 | J8: KR_YuXuan | K8: 500 | N8: parrot | O8: 80
B9: jmz | C9: 800 | F9: 艾拉AL | G9: 10 | J9: ai | K9: 100 | N9: 城府 | O9: 190
B10: baimayinqiang | C10: 10 | F10: 骑砍皇帝 | G10: 700 | J10: Motochika | K10: 160 | N10: knightzz | O10: 850
B11: IC | C11: 500 | F11: 小捷豹 | G11: 40 | J11: LSSL | K11: 90 | N11: 退休老人野望 | O11: 90
B12: xiaoye | C12: 0 | F12: 威廉 | G12: 700 | J12: shiran | K12: 380 | N12: 比伯 | O12: 210
B13: MANGOL | C13: 250 | F13: Able | G13: 410 | J13: havoc | K13: 150 | N13: XiaoRen | O13: 0
B14: 芬克 | C14: 0 | J14: 1911/Dogmeat | K14: 100
B15: 阿氰 | C15: 10 | J15: 大西瓜 | K15: 100
B20: =IFERROR(_xlfn._xlws.FILTER(拍卖列表!$A$12:$A$144,拍卖列表!$F$12:$F$144="【AWO】逃出'生天"),"") | C20: =IFERROR(_xlfn._xlws.FILTER(拍卖列表!$C$12:$C$144,拍卖列表!$F$12:$F$144="【AWO】逃出'生天"),"")
B21: =IFERROR(_xlfn._xlws.FILTER(拍卖列表!$A$12:$A$144,拍卖列表!$F$12:$F$144="【AWO】逃出'生天"),"") | C21: =IFERROR(_xlfn._xlws.FILTER(拍卖列表!$C$12:$C$144,拍卖列表!$F$12:$F$144="【AWO】逃出'生天"),"")
B22: =IFERROR(_xlfn._xlws.FILTER(拍卖列表!$A$12:$A$144,拍卖列表!$F$12:$F$144="【AWO】逃出'生天"),"") | C22: =IFERROR(_xlfn._xlws.FILTER(拍卖列表!$C$12:$C$144,拍卖列表!$F$12:$F$144="【AWO】逃出'生天"),"")
B23: =IFERROR(_xlfn._xlws.FILTER(拍卖列表!$A$12:$A$144,拍卖列表!$F$12:$F$144="【AWO】逃出'生天"),"") | C23: =IFERROR(_xlfn._xlws.FILTER(拍卖列表!$C$12:$C$144,拍卖列表!$F$12:$F$144="【AWO】逃出'生天"),"")
B24: =IFERROR(_xlfn._xlws.FILTER(拍卖列表!$A$12:$A$144,拍卖列表!$F$12:$F$144="【AWO】逃出'生天"),"") | C24: =IFERROR(_xlfn._xlws.FILTER(拍卖列表!$C$12:$C$144,拍卖列表!$F$12:$F$144="【AWO】逃出'生天"),"")
B25: =IFERROR(_xlfn._xlws.FILTER(拍卖列表!$A$12:$A$144,拍卖列表!$F$12:$F$144="【AWO】逃出'生天"),"") | C25: =IFERROR(_xlfn._xlws.FILTER(拍卖列表!$C$12:$C$144,拍卖列表!$F$12:$F$144="【AWO】逃出'生天"),"")
B26: =IFERROR(_xlfn._xlws.FILTER(拍卖列表!$A$12:$A$144,拍卖列表!$F$12:$F$144="【AWO】逃出'生天"),"") | C26: =IFERROR(_xlfn._xlws.FILTER(拍卖列表!$C$12:$C$144,拍卖列表!$F$12:$F$144="【AWO】逃出'生天"),"")
B27: =IFERROR(_xlfn._xlws.FILTER(拍卖列表!$A$12:$A$144,拍卖列表!$F$12:$F$144="【AWO】逃出'生天"),"") | C27: =IFERROR(_xlfn._xlws.FILTER(拍卖列表!$C$12:$C$144,拍卖列表!$F$12:$F$144="【AWO】逃出'生天"),"")
B28: =IFERROR(_xlfn._xlws.FILTER(拍卖列表!$A$12:$A$144,拍卖列表!$F$12:$F$144="【AWO】逃出'生天"),"") | C28: =IFERROR(_xlfn._xlws.FILTER(拍卖列表!$C$12:$C$144,拍卖列表!$F$12:$F$144="【AWO】逃出'生天"),"")
B29: =IFERROR(_xlfn._xlws.FILTER(拍卖列表!$A$12:$A$144,拍卖列表!$F$12:$F$144="【AWO】逃出'生天"),"") | C29: =IFERROR(_xlfn._xlws.FILTER(拍卖列表!$C$12:$C$144,拍卖列表!$F$12:$F$144="【AWO】逃出'生天"),"")
B30: =IFERROR(_xlfn._xlws.FILTER(拍卖列表!$A$12:$A$144,拍卖列表!$F$12:$F$144="【AWO】逃出'生天"),"") | C30: =IFERROR(_xlfn._xlws.FILTER(拍卖列表!$C$12:$C$144,拍卖列表!$F$12:$F$144="【AWO】逃出'生天"),"")
B31: =IFERROR(_xlfn._xlws.FILTER(拍卖列表!$A$12:$A$144,拍卖列表!$F$12:$F$144="【AWO】逃出'生天"),"") | C31: =IFERROR(_xlfn._xlws.FILTER(拍卖列表!$C$12:$C$144,拍卖列表!$F$12:$F$144="【AWO】逃出'生天"),"")
... B33: =IFERROR(_xlfn._xlws.FILTER(拍卖列表!$A$12:$A$144,拍卖列表!$F$12:$F$144="【AWO】逃出'生天"),"") | C33: =IFERROR(_xlfn._xlws.FILTER(拍卖列表!$C$12:$C$144,拍卖列表!$F$12:$F$144="【AWO】逃出'生天"),"")
B34: 【G2】G2 <2682175052> | F34: 【TV】Team Vitality <1574911366> | J34: 【Miniworld】迷你世界 <2668013893> | N34: 【NikoFC】NikoCN Fanclub <1847932439>
B35: 常用昵称 | C35: 身价（单位:w） | D35: 总身价 | F35: 常用昵称 | G35: 身价（单位:w） | H35: 总身价 | J35: 常用昵称 | K35: 身价（单位:w） | L35: 总身价 | N35: 常用昵称 | O35: 身价（单位:w） | P35: 总身价
B36: Zekken | C36: 800 | D36: =SUM(C36:C55) -> 2910 | F36: zy | G36: 800 | H36: =SUM(G36:G55) -> 2910 | J36: nane | K36: 250 | L36: =SUM(K36:K54) -> 2350 | N36: 骑砍真神 | O36: 300 | P36: =SUM(O36:O54) -> 2640
B37: {=IFERROR(_xlfn._xlws.FILTER(交易历史!$A$2:$A$200,交易历史!$F$2:$F$200="【G2】G2"),"")} -> xiaoliyu | C37: {=IFERROR(_xlfn._xlws.FILTER(交易历史!$G$2:$G$200,交易历史!$F$2:$F$200="【G2】G2"),"")} -> 0 | F37: {=IFERROR(_xlfn._xlws.FILTER(交易历史!$A$2:$A$200,交易历史!$F$2:$F$200="【TV】Team Vitality"),"")} -> f4 | G37: {=IFERROR(_xlfn._xlws.FILTER(交易历史!$G$2:$G$200,交易历史!$F$2:$F$200="【TV】Team Vitality"),"")} -> 600 | J37: {=IFERROR(_xlfn._xlws.FILTER(交易历史!$A$2:$A$200,交易历史!$F$2:$F$200="【Miniworld】迷你世界"),"")} -> 哭丧 | K37: {=IFERROR(_xlfn._xlws.FILTER(交易历史!$G$2:$G$200,交易历史!$F$2:$F$200="【Miniworld】迷你世界"),"")} -> 80 | N37: {=IFERROR(_xlfn._xlws.FILTER(交易历史!$A$2:$A$200,交易历史!$F$2:$F$200="【NikoFC】NikoCN Fanclub"),"")} -> awe23 | O37: {=IFERROR(_xlfn._xlws.FILTER(交易历史!$G$2:$G$200,交易历史!$F$2:$F$200="【NikoFC】NikoCN Fanclub"),"")} -> 320
B38: 233laoye | C38: 1000 | F38: abin | G38: 10 | J38: Tatum | K38: 350 | N38: Bonaoart | O38: 100
B39: 500 | C39: 0 | F39: AP-20 | G39: 20 | J39: KillerQuin | K39: 20 | N39: 果猫 | O39: 540
B40: Yoshino | C40: 350 | F40: 孟起 | G40: 20 | J40: 老鱼 | K40: 40 | N40: Mliya | O40: 50
B41: 末影 | C41: 190 | F41: Charlotte | G41: 60 | J41: AQI | K41: 20 | N41: YQS_dou_dou | O41: 30
B42: 大聪明、呆呆 | C42: 400 | F42: Lezalit | G42: 1000 | J42: Add | K42: 60 | N42: 淫荡 | O42: 510
B43: Maverick | C43: 140 | F43: 天帝哥哥 | G43: 10 | J43: Goganpa | K43: 30 | N43: comet | O43: 760
B44: 回火的头盖骨 | C44: 0 | F44: 冷夜 | G44: 20 | J44: diyuluguan | K44: 300 | N44: Gad_ALiang | O44: 10
B45: chengcheng | C45: 10 | F45: sy72sdf | G45: 120 | J45: 卡皇 | K45: 850 | N45: KT_riva | O45: 10
B46: Smile | C46: 0 | F46: 凯德 | G46: 120 | J46: 苏雨晴 | K46: 350 | N46: lirene | O46: 10
...

Sheet 队伍收入状况
A1: 队伍名称 | B1: 队长ID | C1: 身价 | D1: 资金池 | E1: 第一周比赛奖励金 | F1: 第二周比赛奖励金 | G1: 第三周比赛奖励金
A2: 【CbHz】吃饱喝足就是玩 | B2: 冲锋 | C2: 750 | D2: =3000-C2+E2+F2+G2 -> 2250 | E2: =第一轮比赛!E14 -> 0 | F2: 0 | G2: 0
A3: 【SSR】Superior Super Rare | B3: 图派克 | C3: 450 | D3: =3000-C3+E3+F3+G3 -> 2550 | E3: =第一轮比赛!E15 -> 0 | F3: 0 | G3: 0
A4: 【OldH】老H犟嘴 | B4: 凯撒 | C4: 900 | D4: =3000-C4+E4+F4+G4 -> 2100 | E4: =第一轮比赛!E16 -> 0 | F4: 0 | G4: 0
A5: 【AWO】逃出生天 | B5: 小山楂 | C5: 800 | D5: =3000-C5+E5+F5+G5 -> 2200 | E5: =第一轮比赛!E17 -> 0 | F5: 0 | G5: 0
A6: 【G2】G2‭ | B6: 米子 | C6: 800 | D6: =3000-C6+E6+F6+G6 -> 2200 | E6: =第一轮比赛!E18 -> 0 | F6: 0 | G6: 0
A7: 【TV】Team Vitality | B7: 赵毅 | C7: 800 | D7: =3000-C7+E7+F7+G7 -> 2200 | E7: =第一轮比赛!E19 -> 0 | F7: 0 | G7: 0
A8: 【Miniworld】迷你世界 | B8: nane | C8: 250 | D8: =3000-C8+E8+F8+G8 -> 2750 | E8: =第一轮比赛!E20 -> 0 | F8: 0 | G8: 0
A9: 【NikoFC】NikoCN Fanclub | B9: 梅森 | C9: 300 | D9: =3000-C9+E9+F9+G9 -> 2700 | E9: =第一轮比赛!E21 -> 0

Sheet 比赛规则
A1: 2024年骑马与砍杀第二届梦幻联赛比赛介绍
A2: https://kdocs.cn/l/cd1pt4d5tPbS
A4: 拍卖流程
A5: 1. 竞拍开始前，各队队长按要求进入腾讯会议，进入后，主持人将更改ID为序号，序号大小不决定出价顺序。
A6: 2. 主持人介绍球员信息
A7: 3. 队长出价，每位球员起价10w，每次加价必须10w的倍数，出价最高者获得对应的球员，首轮竞拍，最高价1000W
A8: 4. 主持人喊三次当前最高价，若无更高价格，则成交；
A9: 5. 无论任何情况，中途退出，失去的机会不做补偿，队伍名额未满，则随机获得剩余球员
A10: 6. 资金不足问题
A11: ➡️队长可当场向主持人申请使用备用金，但同时，该名队长的匿名状态将取消。
A12: ➡️若队长本金及备用金均使用完毕,则随机获得流拍的球员。

Sheet 第一轮比赛
A1: 积分表
A2: 队伍名称 | B2: 积分 | C2: 净胜分 | D2: 得分 | E2: 失分 | F2: 胜图数
A3: 【Cbhz】 | B3: =SUM(IF(($E$25=A3)*(($F$25+$F$26)<>0),IF($F$25>$F$26,3,IF($F$25<$F$26,0,1)),0),IF(($E$27=A3)*(($F$27+$F$28)<>0),IF($F$27>$F$28,3,IF($F$27<$F$28,0,1)),0),IF(($E$29=A3)*(($F$29+$F$30)<>0),IF($F$29>$F$30,3,IF($F$29<$F$30,0,1)),0),IF(($E$31=A3)*(($F$31+$F$32)<>0),IF($F$31>$F$32,3,IF($F$31<$F$32,0,1)),0),IF(($E$33=A3)*(($F$33+$F$34)<>0),IF($F$33>$F$34,3,IF($F$33<$F$34,0,1)),0),IF(($E$35=A3)*(($F$35+$F$36)<>0),IF($F$35>$F$36,3,IF($F$35<$F$36,0,1)),0),IF(($E$37=A3)*(($F$37+$F$38)<>0),IF($F$37>$F$38,3,IF($F$37<$F$38,0,1)),0),IF(($E$39=A3)*(($F$39+$F$40)<>0),IF($F$39>$F$40,3,IF($F$39<$F$40,0,1)),0),IF(($E$26=A3)*(($F$25+$F$26)<>0),IF($F$26>$F$25,3,IF($F$26<$F$25,0,1)),0),IF(($E$28=A3)*(($F$27+$F$28)<>0),IF($F$28>$F$27,3,IF($F$28<$F$27,0,1)),0),IF(($E$30=A3)*(($F$29+$F$30)<>0),IF($F$30>$F$29,3,IF($F$30<$F$29,0,1)),0),IF(($E$32=A3)*(($F$31+$F$32)<>0),IF($F$32>$F$31,3,IF($F$32<$F$31,0,1)),0),IF(($E$34=A3)*(($F$33+$F$34)<>0),IF($F$34>$F$33,3,IF($F$34<$F$33,0,1)),0),IF(($E$36=A3)*(($F$35+$F$36)<>0),IF($F$36>$F$35,3,IF($F$36<$F$35,0,1)),0),IF(($E$38=A3)*(($F$37+$F$38)<>0),IF($F$38>$F$37,3,IF($F$38<$F$37,0,1)),0),IF(($E$40=A3)*(($F$39+$F$40)<>0),IF($F$40>$F$39,3,IF($F$40<$F$39,0,1)),0)) -> 0 | C3: =D3-E3 -> 0 | D3: {=SUMPRODUCT(IF($E$25:$E$40=A3,$F$25:$F$40,0))} -> 0 | E3: {=SUMPRODUCT(IF(($E$25:$E$40=A3)*(MOD(ROW($E$25:$E$40)-ROW($E$25),2)=0),OFFSET($F$25:$F$40,1,0),0))+SUMPRODUCT(IF(($E$25:$E$40=A3)*(MOD(ROW($E$25:$E$40)-ROW($E$25),2)=1),OFFSET($F$25:$F$40,-1,0),0))} -> 0 | F3: {=SUMPRODUCT(IF($E$25:$E$40=A3,$G$25:$G$40,0))} -> 0
A4: 【SSR】 | B4: =SUM(IF(($E$25=A4)*(($F$25+$F$26)<>0),IF($F$25>$F$26,3,IF($F$25<$F$26,0,1)),0),IF(($E$27=A4)*(($F$27+$F$28)<>0),IF($F$27>$F$28,3,IF($F$27<$F$28,0,1)),0),IF(($E$29=A4)*(($F$29+$F$30)<>0),IF($F$29>$F$30,3,IF($F$29<$F$30,0,1)),0),IF(($E$31=A4)*(($F$31+$F$32)<>0),IF($F$31>$F$32,3,IF($F$31<$F$32,0,1)),0),IF(($E$33=A4)*(($F$33+$F$34)<>0),IF($F$33>$F$34,3,IF($F$33<$F$34,0,1)),0),IF(($E$35=A4)*(($F$35+$F$36)<>0),IF($F$35>$F$36,3,IF($F$35<$F$36,0,1)),0),IF(($E$37=A4)*(($F$37+$F$38)<>0),IF($F$37>$F$38,3,IF($F$37<$F$38,0,1)),0),IF(($E$39=A4)*(($F$39+$F$40)<>0),IF($F$39>$F$40,3,IF($F$39<$F$40,0,1)),0),IF(($E$26=A4)*(($F$25+$F$26)<>0),IF($F$26>$F$25,3,IF($F$26<$F$25,0,1)),0),IF(($E$28=A4)*(($F$27+$F$28)<>0),IF($F$28>$F$27,3,IF($F$28<$F$27,0,1)),0),IF(($E$30=A4)*(($F$29+$F$30)<>0),IF($F$30>$F$29,3,IF($F$30<$F$29,0,1)),0),IF(($E$32=A4)*(($F$31+$F$32)<>0),IF($F$32>$F$31,3,IF($F$32<$F$31,0,1)),0),IF(($E$34=A4)*(($F$33+$F$34)<>0),IF($F$34>$F$33,3,IF($F$34<$F$33,0,1)),0),IF(($E$36=A4)*(($F$35+$F$36)<>0),IF($F$36>$F$35,3,IF($F$36<$F$35,0,1)),0),IF(($E$38=A4)*(($F$37+$F$38)<>0),IF($F$38>$F$37,3,IF($F$38<$F$37,0,1)),0),IF(($E$40=A4)*(($F$39+$F$40)<>0),IF($F$40>$F$39,3,IF($F$40<$F$39,0,1)),0)) -> 0 | C4: {=SUMPRODUCT(IF(($E$25:$E$40=A4)*(MOD(ROW($F$25:$F$40)-ROW($F$25),2)=0),$F$25:$F$40-OFFSET($F$25:$F$40,1,0),0))+SUMPRODUCT(IF(($E$25:$E$40=A4)*(MOD(ROW($F$25:$F$40)-ROW($F$25),2)=1),OFFSET($F$25:$F$40,-1,0)-$F$25:$F$40,0))} -> 0 | D4: =SUMPRODUCT((($E$25:$E$40="【SSR】")*($F$25:$F$40))) -> 0 | E4: {=SUMPRODUCT(IF(($E$25:$E$40=A4)*(MOD(ROW($E$25:$E$40)-ROW($E$25),2)=0),OFFSET($F$25:$F$40,1,0),0))+SUMPRODUCT(IF(($E$25:$E$40=A4)*(MOD(ROW($E$25:$E$40)-ROW($E$25),2)=1),OFFSET($F$25:$F$40,-1,0),0))} -> 0 | F4: {=SUMPRODUCT(IF($E$25:$E$40=A4,$G$25:$G$40,0))} -> 0
A5: 【OldH】 | B5: =SUM(IF(($E$25=A5)*(($F$25+$F$26)<>0),IF($F$25>$F$26,3,IF($F$25<$F$26,0,1)),0),IF(($E$27=A5)*(($F$27+$F$28)<>0),IF($F$27>$F$28,3,IF($F$27<$F$28,0,1)),0),IF(($E$29=A5)*(($F$29+$F$30)<>0),IF($F$29>$F$30,3,IF($F$29<$F$30,0,1)),0),IF(($E$31=A5)*(($F$31+$F$32)<>0),IF($F$31>$F$32,3,IF($F$31<$F$32,0,1)),0),IF(($E$33=A5)*(($F$33+$F$34)<>0),IF($F$33>$F$34,3,IF($F$33<$F$34,0,1)),0),IF(($E$35=A5)*(($F$35+$F$36)<>0),IF($F$35>$F$36,3,IF($F$35<$F$36,0,1)),0),IF(($E$37=A5)*(($F$37+$F$38)<>0),IF($F$37>$F$38,3,IF($F$37<$F$38,0,1)),0),IF(($E$39=A5)*(($F$39+$F$40)<>0),IF($F$39>$F$40,3,IF($F$39<$F$40,0,1)),0),IF(($E$26=A5)*(($F$25+$F$26)<>0),IF($F$26>$F$25,3,IF($F$26<$F$25,0,1)),0),IF(($E$28=A5)*(($F$27+$F$28)<>0),IF($F$28>$F$27,3,IF($F$28<$F$27,0,1)),0),IF(($E$30=A5)*(($F$29+$F$30)<>0),IF($F$30>$F$29,3,IF($F$30<$F$29,0,1)),0),IF(($E$32=A5)*(($F$31+$F$32)<>0),IF($F$32>$F$31,3,IF($F$32<$F$31,0,1)),0),IF(($E$34=A5)*(($F$33+$F$34)<>0),IF($F$34>$F$33,3,IF($F$34<$F$33,0,1)),0),IF(($E$36=A5)*(($F$35+$F$36)<>0),IF($F$36>$F$35,3,IF($F$36<$F$35,0,1)),0),IF(($E$38=A5)*(($F$37+$F$38)<>0),IF($F$38>$F$37,3,IF($F$38<$F$37,0,1)),0),IF(($E$40=A5)*(($F$39+$F$40)<>0),IF($F$40>$F$39,3,IF($F$40<$F$39,0,1)),0)) -> 0 | C5: {=SUMPRODUCT(IF(($E$25:$E$40=A5)*(MOD(ROW($F$25:$F$40)-ROW($F$25),2)=0),$F$25:$F$40-OFFSET($F$25:$F$40,1,0),0))+SUMPRODUCT(IF(($E$25:$E$40=A5)*(MOD(ROW($F$25:$F$40)-ROW($F$25),2)=1),OFFSET($F$25:$F$40,-1,0)-$F$25:$F$40,0))} -> 0 | D5: =SUMPRODUCT((($E$25:$E$40="【OldH】")*($F$25:$F$40))) -> 0 | E5: {=SUMPRODUCT(IF(($E$25:$E$40=A5)*(MOD(ROW($E$25:$E$40)-ROW($E$25),2)=0),OFFSET($F$25:$F$40,1,0),0))+SUMPRODUCT(IF(($E$25:$E$40=A5)*(MOD(ROW($E$25:$E$40)-ROW($E$25),2)=1),OFFSET($F$25:$F$40,-1,0),0))} -> 0 | F5: {=SUMPRODUCT(IF($E$25:$E$40=A5,$G$25:$G$40,0))} -> 0
A6: 【AWO】 | B6: =SUM(IF(($E$25=A6)*(($F$25+$F$26)<>0),IF($F$25>$F$26,3,IF($F$25<$F$26,0,1)),0),IF(($E$27=A6)*(($F$27+$F$28)<>0),IF($F$27>$F$28,3,IF($F$27<$F$28,0,1)),0),IF(($E$29=A6)*(($F$29+$F$30)<>0),IF($F$29>$F$30,3,IF($F$29<$F$30,0,1)),0),IF(($E$31=A6)*(($F$31+$F$32)<>0),IF($F$31>$F$32,3,IF($F$31<$F$32,0,1)),0),IF(($E$33=A6)*(($F$33+$F$34)<>0),IF($F$33>$F$34,3,IF($F$33<$F$34,0,1)),0),IF(($E$35=A6)*(($F$35+$F$36)<>0),IF($F$35>$F$36,3,IF($F$35<$F$36,0,1)),0),IF(($E$37=A6)*(($F$37+$F$38)<>0),IF($F$37>$F$38,3,IF($F$37<$F$38,0,1)),0),IF(($E$39=A6)*(($F$39+$F$40)<>0),IF($F$39>$F$40,3,IF($F$39<$F$40,0,1)),0),IF(($E$26=A6)*(($F$25+$F$26)<>0),IF($F$26>$F$25,3,IF($F$26<$F$25,0,1)),0),IF(($E$28=A6)*(($F$27+$F$28)<>0),IF($F$28>$F$27,3,IF($F$28<$F$27,0,1)),0),IF(($E$30=A6)*(($F$29+$F$30)<>0),IF($F$30>$F$29,3,IF($F$30<$F$29,0,1)),0),IF(($E$32=A6)*(($F$31+$F$32)<>0),IF($F$32>$F$31,3,IF($F$32<$F$31,0,1)),0),IF(($E$34=A6)*(($F$33+$F$34)<>0),IF($F$34>$F$33,3,IF($F$34<$F$33,0,1)),0),IF(($E$36=A6)*(($F$35+$F$36)<>0),IF($F$36>$F$35,3,IF($F$36<$F$35,0,1)),0),IF(($E$38=A6)*(($F$37+$F$38)<>0),IF($F$38>$F$37,3,IF($F$38<$F$37,0,1)),0),IF(($E$40=A6)*(($F$39+$F$40)<>0),IF($F$40>$F$39,3,IF($F$40<$F$39,0,1)),0)) -> 0 | C6: {=SUMPRODUCT(IF(($E$25:$E$40=A6)*(MOD(ROW($F$25:$F$40)-ROW($F$25),2)=0),$F$25:$F$40-OFFSET($F$25:$F$40,1,0),0))+SUMPRODUCT(IF(($E$25:$E$40=A6)*(MOD(ROW($F$25:$F$40)-ROW($F$25),2)=1),OFFSET($F$25:$F$40,-1,0)-$F$25:$F$40,0))} -> 0 | D6: =SUMPRODUCT((($E$25:$E$40="【AWO】")*($F$25:$F$40))) -> 0 | E6: {=SUMPRODUCT(IF(($E$25:$E$40=A6)*(MOD(ROW($E$25:$E$40)-ROW($E$25),2)=0),OFFSET($F$25:$F$40,1,0),0))+SUMPRODUCT(IF(($E$25:$E$40=A6)*(MOD(ROW($E$25:$E$40)-ROW($E$25),2)=1),OFFSET($F$25:$F$40,-1,0),0))} -> 0 | F6: {=SUMPRODUCT(IF($E$25:$E$40=A6,$G$25:$G$40,0))} -> 0
A7: 【G2】 | B7: =SUM(IF(($E$25=A7)*(($F$25+$F$26)<>0),IF($F$25>$F$26,3,IF($F$25<$F$26,0,1)),0),IF(($E$27=A7)*(($F$27+$F$28)<>0),IF($F$27>$F$28,3,IF($F$27<$F$28,0,1)),0),IF(($E$29=A7)*(($F$29+$F$30)<>0),IF($F$29>$F$30,3,IF($F$29<$F$30,0,1)),0),IF(($E$31=A7)*(($F$31+$F$32)<>0),IF($F$31>$F$32,3,IF($F$31<$F$32,0,1)),0),IF(($E$33=A7)*(($F$33+$F$34)<>0),IF($F$33>$F$34,3,IF($F$33<$F$34,0,1)),0),IF(($E$35=A7)*(($F$35+$F$36)<>0),IF($F$35>$F$36,3,IF($F$35<$F$36,0,1)),0),IF(($E$37=A7)*(($F$37+$F$38)<>0),IF($F$37>$F$38,3,IF($F$37<$F$38,0,1)),0),IF(($E$39=A7)*(($F$39+$F$40)<>0),IF($F$39>$F$40,3,IF($F$39<$F$40,0,1)),0),IF(($E$26=A7)*(($F$25+$F$26)<>0),IF($F$26>$F$25,3,IF($F$26<$F$25,0,1)),0),IF(($E$28=A7)*(($F$27+$F$28)<>0),IF($F$28>$F$27,3,IF($F$28<$F$27,0,1)),0),IF(($E$30=A7)*(($F$29+$F$30)<>0),IF($F$30>$F$29,3,IF($F$30<$F$29,0,1)),0),IF(($E$32=A7)*(($F$31+$F$32)<>0),IF($F$32>$F$31,3,IF($F$32<$F$31,0,1)),0),IF(($E$34=A7)*(($F$33+$F$34)<>0),IF($F$34>$F$33,3,IF($F$34<$F$33,0,1)),0),IF(($E$36=A7)*(($F$35+$F$36)<>0),IF($F$36>$F$35,3,IF($F$36<$F$35,0,1)),0),IF(($E$38=A7)*(($F$37+$F$38)<>0),IF($F$38>$F$37,3,IF($F$38<$F$37,0,1)),0),IF(($E$40=A7)*(($F$39+$F$40)<>0),IF($F$40>$F$39,3,IF($F$40<$F$39,0,1)),0)) -> 0 | C7: {=SUMPRODUCT(IF(($E$25:$E$40=A7)*(MOD(ROW($F$25:$F$40)-ROW($F$25),2)=0),$F$25:$F$40-OFFSET($F$25:$F$40,1,0),0))+SUMPRODUCT(IF(($E$25:$E$40=A7)*(MOD(ROW($F$25:$F$40)-ROW($F$25),2)=1),OFFSET($F$25:$F$40,-1,0)-$F$25:$F$40,0))} -> 0 | D7: =SUMPRODUCT((($E$25:$E$40="【G2】")*($F$25:$F$40))) -> 0 | E7: {=SUMPRODUCT(IF(($E$25:$E$40=A7)*(MOD(ROW($E$25:$E$40)-ROW($E$25),2)=0),OFFSET($F$25:$F$40,1,0),0))+SUMPRODUCT(IF(($E$25:$E$40=A7)*(MOD(ROW($E$25:$E$40)-ROW($E$25),2)=1),OFFSET($F$25:$F$40,-1,0),0))} -> 0 | F7: {=SUMPRODUCT(IF($E$25:$E$40=A7,$G$25:$G$40,0))} -> 0
A8: 【TV】 | B8: =SUM(IF(($E$25=A8)*(($F$25+$F$26)<>0),IF($F$25>$F$26,3,IF($F$25<$F$26,0,1)),0),IF(($E$27=A8)*(($F$27+$F$28)<>0),IF($F$27>$F$28,3,IF($F$27<$F$28,0,1)),0),IF(($E$29=A8)*(($F$29+$F$30)<>0),IF($F$29>$F$30,3,IF($F$29<$F$30,0,1)),0),IF(($E$31=A8)*(($F$31+$F$32)<>0),IF($F$31>$F$32,3,IF($F$31<$F$32,0,1)),0),IF(($E$33=A8)*(($F$33+$F$34)<>0),IF($F$33>$F$34,3,IF($F$33<$F$34,0,1)),0),IF(($E$35=A8)*(($F$35+$F$36)<>0),IF($F$35>$F$36,3,IF($F$35<$F$36,0,1)),0),IF(($E$37=A8)*(($F$37+$F$38)<>0),IF($F$37>$F$38,3,IF($F$37<$F$38,0,1)),0),IF(($E$39=A8)*(($F$39+$F$40)<>0),IF($F$39>$F$40,3,IF($F$39<$F$40,0,1)),0),IF(($E$26=A8)*(($F$25+$F$26)<>0),IF($F$26>$F$25,3,IF($F$26<$F$25,0,1)),0),IF(($E$28=A8)*(($F$27+$F$28)<>0),IF($F$28>$F$27,3,IF($F$28<$F$27,0,1)),0),IF(($E$30=A8)*(($F$29+$F$30)<>0),IF($F$30>$F$29,3,IF($F$30<$F$29,0,1)),0),IF(($E$32=A8)*(($F$31+$F$32)<>0),IF($F$32>$F$31,3,IF($F$32<$F$31,0,1)),0),IF(($E$34=A8)*(($F$33+$F$34)<>0),IF($F$34>$F$33,3,IF($F$34<$F$33,0,1)),0),IF(($E$36=A8)*(($F$35+$F$36)<>0),IF($F$36>$F$35,3,IF($F$36<$F$35,0,1)),0),IF(($E$38=A8)*(($F$37+$F$38)<>0),IF($F$38>$F$37,3,IF($F$38<$F$37,0,1)),0),IF(($E$40=A8)*(($F$39+$F$40)<>0),IF($F$40>$F$39,3,IF($F$40<$F$39,0,1)),0)) -> 0 | C8: {=SUMPRODUCT(IF(($E$25:$E$40=A8)*(MOD(ROW($F$25:$F$40)-ROW($F$25),2)=0),$F$25:$F$40-OFFSET($F$25:$F$40,1,0),0))+SUMPRODUCT(IF(($E$25:$E$40=A8)*(MOD(ROW($F$25:$F$40)-ROW($F$25),2)=1),OFFSET($F$25:$F$40,-1,0)-$F$25:$F$40,0))} -> 0 | D8: =SUMPRODUCT((($E$25:$E$40="【TV】")*($F$25:$F$40))) -> 0 | E8: {=SUMPRODUCT(IF(($E$25:$E$40=A8)*(MOD(ROW($E$25:$E$40)-ROW($E$25),2)=0),OFFSET($F$25:$F$40,1,0),0))+SUMPRODUCT(IF(($E$25:$E$40=A8)*(MOD(ROW($E$25:$E$40)-ROW($E$25),2)=1),OFFSET($F$25:$F$40,-1,0),0))} -> 0 | F8: {=SUMPRODUCT(IF($E$25:$E$40=A8,$G$25:$G$40,0))} -> 0
A9: 【Miniworld】 | B9: =SUM(IF(($E$25=A9)*(($F$25+$F$26)<>0),IF($F$25>$F$26,3,IF($F$25<$F$26,0,1)),0),IF(($E$27=A9)*(($F$27+$F$28)<>0),IF($F$27>$F$28,3,IF($F$27<$F$28,0,1)),0),IF(($E$29=A9)*(($F$29+$F$30)<>0),IF($F$29>$F$30,3,IF($F$29<$F$30,0,1)),0),IF(($E$31=A9)*(($F$31+$F$32)<>0),IF($F$31>$F$32,3,IF($F$31<$F$32,0,1)),0),IF(($E$33=A9)*(($F$33+$F$34)<>0),IF($F$33>$F$34,3,IF($F$33<$F$34,0,1)),0),IF(($E$35=A9)*(($F$35+$F$36)<>0),IF($F$35>$F$36,3,IF($F$35<$F$36,0,1)),0),IF(($E$37=A9)*(($F$37+$F$38)<>0),IF($F$37>$F$38,3,IF($F$37<$F$38,0,1)),0),IF(($E$39=A9)*(($F$39+$F$40)<>0),IF($F$39>$F$40,3,IF($F$39<$F$40,0,1)),0),IF(($E$26=A9)*(($F$25+$F$26)<>0),IF($F$26>$F$25,3,IF($F$26<$F$25,0,1)),0),IF(($E$28=A9)*(($F$27+$F$28)<>0),IF($F$28>$F$27,3,IF($F$28<$F$27,0,1)),0),IF(($E$30=A9)*(($F$29+$F$30)<>0),IF($F$30>$F$29,3,IF($F$30<$F$29,0,1)),0),IF(($E$32=A9)*(($F$31+$F$32)<>0),IF($F$32>$F$31,3,IF($F$32<$F$31,0,1)),0),IF(($E$34=A9)*(($F$33+$F$34)<>0),IF($F$34>$F$33,3,IF($F$34<$F$33,0,1)),0),IF(($E$36=A9)*(($F$35+$F$36)<>0),IF($F$36>$F$35,3,IF($F$36<$F$35,0,1)),0),IF(($E$38=A9)*(($F$37+$F$38)<>0),IF($F$38>$F$37,3,IF($F$38<$F$37,0,1)),0),IF(($E$40=A9)*(($F$39+$F$40)<>0),IF($F$40>$F$39,3,IF($F$40<$F$39,0,1)),0)) -> 0 | C9: {=SUMPRODUCT(IF(($E$25:$E$40=A9)*(MOD(ROW($F$25:$F$40)-ROW($F$25),2)=0),$F$25:$F$40-OFFSET($F$25:$F$40,1,0),0))+SUMPRODUCT(IF(($E$25:$E$40=A9)*(MOD(ROW($F$25:$F$40)-ROW($F$25),2)=1),OFFSET($F$25:$F$40,-1,0)-$F$25:$F$40,0))} -> 0 | D9: =SUMPRODUCT((($E$25:$E$40="【Miniworld】")*($F$25:$F$40))) -> 0 | E9: {=SUMPRODUCT(IF(($E$25:$E$40=A9)*(MOD(ROW($E$25:$E$40)-ROW($E$25),2)=0),OFFSET($F$25:$F$40,1,0),0))+SUMPRODUCT(IF(($E$25:$E$40=A9)*(MOD(ROW($E$25:$E$40)-ROW($E$25),2)=1),OFFSET($F$25:$F$40,-1,0),0))} -> 0 | F9: {=SUMPRODUCT(IF($E$25:$E$40=A9,$G$25:$G$40,0))} -> 0
A10: 【NikoFC】 | B10: =SUM(IF(($E$25=A10)*(($F$25+$F$26)<>0),IF($F$25>$F$26,3,IF($F$25<$F$26,0,1)),0),IF(($E$27=A10)*(($F$27+$F$28)<>0),IF($F$27>$F$28,3,IF($F$27<$F$28,0,1)),0),IF(($E$29=A10)*(($F$29+$F$30)<>0),IF($F$29>$F$30,3,IF($F$29<$F$30,0,1)),0),IF(($E$31=A10)*(($F$31+$F$32)<>0),IF($F$31>$F$32,3,IF($F$31<$F$32,0,1)),0),IF(($E$33=A10)*(($F$33+$F$34)<>0),IF($F$33>$F$34,3,IF($F$33<$F$34,0,1)),0),IF(($E$35=A10)*(($F$35+$F$36)<>0),IF($F$35>$F$36,3,IF($F$35<$F$36,0,1)),0),IF(($E$37=A10)*(($F$37+$F$38)<>0),IF($F$37>$F$38,3,IF($F$37<$F$38,0,1)),0),IF(($E$39=A10)*(($F$39+$F$40)<>0),IF($F$39>$F$40,3,IF($F$39<$F$40,0,1)),0),IF(($E$26=A10)*(($F$25+$F$26)<>0),IF($F$26>$F$25,3,IF($F$26<$F$25,0,1)),0),IF(($E$28=A10)*(($F$27+$F$28)<>0),IF($F$28>$F$27,3,IF($F$28<$F$27,0,1)),0),IF(($E$30=A10)*(($F$29+$F$30)<>0),IF($F$30>$F$29,3,IF($F$30<$F$29,0,1)),0),IF(($E$32=A10)*(($F$31+$F$32)<>0),IF($F$32>$F$31,3,IF($F$32<$F$31,0,1)),0),IF(($E$34=A10)*(($F$33+$F$34)<>0),IF($F$34>$F$33,3,IF($F$34<$F$33,0,1)),0),IF(($E$36=A10)*(($F$35+$F$36)<>0),IF($F$36>$F$35,3,IF($F$36<$F$35,0,1)),0),IF(($E$38=A10)*(($F$37+$F$38)<>0),IF($F$38>$F$37,3,IF($F$38<$F$37,0,1)),0),IF(($E$40=A10)*(($F$39+$F$40)<>0),IF($F$40>$F$39,3,IF($F$40<$F$39,0,1)),0)) -> 0 | C10: {=SUMPRODUCT(IF(($E$25:$E$40=A10)*(MOD(ROW($F$25:$F$40)-ROW($F$25),2)=0),$F$25:$F$40-OFFSET($F$25:$F$40,1,0),0))+SUMPRODUCT(IF(($E$25:$E$40=A10)*(MOD(ROW($F$25:$F$40)-ROW($F$25),2)=1),OFFSET($F$25:$F$40,-1,0)-$F$25:$F$40,0))} -> 0 | D10: =SUMPRODUCT((($E$25:$E$40="【NikoFC】")*($F$25:$F$40))) -> 0 | E10: {=SUMPRODUCT(IF(($E$25:$E$40=A10)*(MOD(ROW($E$25:$E$40)-ROW($E$25),2)=0),OFFSET($F$25:$F$40,1,0),0))+SUMPRODUCT(IF(($E$25:$E$40=A10)*(MOD(ROW($E$25:$E$40)-ROW($E$25),2)=1),OFFSET($F$25:$F$40,-1,0),0))} -> 0 | F10: {=SUMPRODUCT(IF($E$25:$E$40=A10,$G$25:$G$40,0))} -> 0
A12: 比赛奖励金表
A13: 队伍名称 | B13: 小分奖励 | C13: 胜图奖励 | D13: 劣势奖励 | E13: 总奖励
A14: 【Cbhz】 | B14: =INDEX(D$3:D$10,MATCH(A14,A$3:A$10,0))*10 -> 0 | C14: =INDEX(F$3:F$10,MATCH(A14,A$3:A$10,0))*50 -> 0 | D14: =SUM(IF(($E$25=$A14)*($I$25=$E$25),($F$25*10+$G$25*50),0),IF(($E$27=$A14)*($I$27=$E$27),($F$27*10+$G$27*50),0),IF(($E$29=$A14)*($I$29=$E$29),($F$29*10+$G$29*50),0),IF(($E$31=$A14)*($I$31=$E$31),($F$31*10+$G$31*50),0),IF(($E$33=$A14)*($I$33=$E$33),($F$33*10+$G$33*50),0),IF(($E$35=$A14)*($I$35=$E$35),($F$35*10+$G$35*50),0),IF(($E$37=$A14)*($I$37=$E$37),($F$37*10+$G$37*50),0),IF(($E$39=$A14)*($I$39=$E$39),($F$39*10+$G$39*50),0),IF(($E$26=$A14)*($I$25=$E$26),($F$26*10+$G$26*50),0),IF(($E$28=$A14)*($I$27=$E$28),($F$28*10+$G$28*50),0),IF(($E$30=$A14)*($I$29=$E$30),($F$30*10+$G$30*50),0),IF(($E$32=$A14)*($I$31=$E$32),($F$32*10+$G$32*50),0),IF(($E$34=$A14)*($I$33=$E$34),($F$34*10+$G$34*50),0),IF(($E$36=$A14)*($I$35=$E$36),($F$36*10+$G$36*50),0),IF(($E$38=$A14)*($I$37=$E$38),($F$38*10+$G$38*50),0),IF(($E$40=$A14)*($I$39=$E$40),($F$40*10+$G$40*50),0)) -> 0 | E14: =B14+C14+D14 -> 0
A15: 【SSR】 | B15: =INDEX(D$3:D$10,MATCH(A15,A$3:A$10,0))*10 -> 0 | C15: =INDEX(F$3:F$10,MATCH(A15,A$3:A$10,0))*50 -> 0 | D15: =SUM(IF(($E$25=$A15)*($I$25=$E$25),($F$25*10+$G$25*50),0),IF(($E$27=$A15)*($I$27=$E$27),($F$27*10+$G$27*50),0),IF(($E$29=$A15)*($I$29=$E$29),($F$29*10+$G$29*50),0),IF(($E$31=$A15)*($I$31=$E$31),($F$31*10+$G$31*50),0),IF(($E$33=$A15)*($I$33=$E$33),($F$33*10+$G$33*50),0),IF(($E$35=$A15)*($I$35=$E$35),($F$35*10+$G$35*50),0),IF(($E$37=$A15)*($I$37=$E$37),($F$37*10+$G$37*50),0),IF(($E$39=$A15)*($I$39=$E$39),($F$39*10+$G$39*50),0),IF(($E$26=$A15)*($I$25=$E$26),($F$26*10+$G$26*50),0),IF(($E$28=$A15)*($I$27=$E$28),($F$28*10+$G$28*50),0),IF(($E$30=$A15)*($I$29=$E$30),($F$30*10+$G$30*50),0),IF(($E$32=$A15)*($I$31=$E$32),($F$32*10+$G$32*50),0),IF(($E$34=$A15)*($I$33=$E$34),($F$34*10+$G$34*50),0),IF(($E$36=$A15)*($I$35=$E$36),($F$36*10+$G$36*50),0),IF(($E$38=$A15)*($I$37=$E$38),($F$38*10+$G$38*50),0),IF(($E$40=$A15)*($I$39=$E$40),($F$40*10+$G$40*50),0)) -> 0 | E15: =B15+C15+D15 -> 0
A16: 【OldH】 | B16: =INDEX(D$3:D$10,MATCH(A16,A$3:A$10,0))*10 -> 0 | C16: =INDEX(F$3:F$10,MATCH(A16,A$3:A$10,0))*50 -> 0 | D16: =SUM(IF(($E$25=$A16)*($I$25=$E$25),($F$25*10+$G$25*50),0),IF(($E$27=$A16)*($I$27=$E$27),($F$27*10+$G$27*50),0),IF(($E$29=$A16)*($I$29=$E$29),($F$29*10+$G$29*50),0),IF(($E$31=$A16)*($I$31=$E$31),($F$31*10+$G$31*50),0),IF(($E$33=$A16)*($I$33=$E$33),($F$33*10+$G$33*50),0),IF(($E$35=$A16)*($I$35=$E$35),($F$35*10+$G$35*50),0),IF(($E$37=$A16)*($I$37=$E$37),($F$37*10+$G$37*50),0),IF(($E$39=$A16)*($I$39=$E$39),($F$39*10+$G$39*50),0),IF(($E$26=$A16)*($I$25=$E$26),($F$26*10+$G$26*50),0),IF(($E$28=$A16)*($I$27=$E$28),($F$28*10+$G$28*50),0),IF(($E$30=$A16)*($I$29=$E$30),($F$30*10+$G$30*50),0),IF(($E$32=$A16)*($I$31=$E$32),($F$32*10+$G$32*50),0),IF(($E$34=$A16)*($I$33=$E$34),($F$34*10+$G$34*50),0),IF(($E$36=$A16)*($I$35=$E$36),($F$36*10+$G$36*50),0),IF(($E$38=$A16)*($I$37=$E$38),($F$38*10+$G$38*50),0),IF(($E$40=$A16)*($I$39=$E$40),($F$40*10+$G$40*50),0)) -> 0 | E16: =B16+C16+D16 -> 0
A17: 【AWO】 | B17: =INDEX(D$3:D$10,MATCH(A17,A$3:A$10,0))*10 -> 0 | C17: =INDEX(F$3:F$10,MATCH(A17,A$3:A$10,0))*50 -> 0 | D17: =SUM(IF(($E$25=$A17)*($I$25=$E$25),($F$25*10+$G$25*50),0),IF(($E$27=$A17)*($I$27=$E$27),($F$27*10+$G$27*50),0),IF(($E$29=$A17)*($I$29=$E$29),($F$29*10+$G$29*50),0),IF(($E$31=$A17)*($I$31=$E$31),($F$31*10+$G$31*50),0),IF(($E$33=$A17)*($I$33=$E$33),($F$33*10+$G$33*50),0),IF(($E$35=$A17)*($I$35=$E$35),($F$35*10+$G$35*50),0),IF(($E$37=$A17)*($I$37=$E$37),($F$37*10+$G$37*50),0),IF(($E$39=$A17)*($I$39=$E$39),($F$39*10+$G$39*50),0),IF(($E$26=$A17)*($I$25=$E$26),($F$26*10+$G$26*50),0),IF(($E$28=$A17)*($I$27=$E$28),($F$28*10+$G$28*50),0),IF(($E$30=$A17)*($I$29=$E$30),($F$30*10+$G$30*50),0),IF(($E$32=$A17)*($I$31=$E$32),($F$32*10+$G$32*50),0),IF(($E$34=$A17)*($I$33=$E$34),($F$34*10+$G$34*50),0),IF(($E$36=$A17)*($I$35=$E$36),($F$36*10+$G$36*50),0),IF(($E$38=$A17)*($I$37=$E$38),($F$38*10+$G$38*50),0),IF(($E$40=$A17)*($I$39=$E$40),($F$40*10+$G$40*50),0)) -> 0 | E17: =B17+C17+D17 -> 0
A18: 【G2】 | B18: =INDEX(D$3:D$10,MATCH(A18,A$3:A$10,0))*10 -> 0 | C18: =INDEX(F$3:F$10,MATCH(A18,A$3:A$10,0))*50 -> 0 | D18: =SUM(IF(($E$25=$A18)*($I$25=$E$25),($F$25*10+$G$25*50),0),IF(($E$27=$A18)*($I$27=$E$27),($F$27*10+$G$27*50),0),IF(($E$29=$A18)*($I$29=$E$29),($F$29*10+$G$29*50),0),IF(($E$31=$A18)*($I$31=$E$31),($F$31*10+$G$31*50),0),IF(($E$33=$A18)*($I$33=$E$33),($F$33*10+$G$33*50),0),IF(($E$35=$A18)*($I$35=$E$35),($F$35*10+$G$35*50),0),IF(($E$37=$A18)*($I$37=$E$37),($F$37*10+$G$37*50),0),IF(($E$39=$A18)*($I$39=$E$39),($F$39*10+$G$39*50),0),IF(($E$26=$A18)*($I$25=$E$26),($F$26*10+$G$26*50),0),IF(($E$28=$A18)*($I$27=$E$28),($F$28*10+$G$28*50),0),IF(($E$30=$A18)*($I$29=$E$30),($F$30*10+$G$30*50),0),IF(($E$32=$A18)*($I$31=$E$32),($F$32*10+$G$32*50),0),IF(($E$34=$A18)*($I$33=$E$34),($F$34*10+$G$34*50),0),IF(($E$36=$A18)*($I$35=$E$36),($F$36*10+$G$36*50),0),IF(($E$38=$A18)*($I$37=$E$38),($F$38*10+$G$38*50),0),IF(($E$40=$A18)*($I$39=$E$40),($F$40*10+$G$40*50),0)) -> 0 | E18: =B18+C18+D18 -> 0
A19: 【TV】 | B19: =INDEX(D$3:D$10,MATCH(A19,A$3:A$10,0))*10 -> 0 | C19: =INDEX(F$3:F$10,MATCH(A19,A$3:A$10,0))*50 -> 0 | D19: =SUM(IF(($E$25=$A19)*($I$25=$E$25),($F$25*10+$G$25*50),0),IF(($E$27=$A19)*($I$27=$E$27),($F$27*10+$G$27*50),0),IF(($E$29=$A19)*($I$29=$E$29),($F$29*10+$G$29*50),0),IF(($E$31=$A19)*($I$31=$E$31),($F$31*10+$G$31*50),0),IF(($E$33=$A19)*($I$33=$E$33),($F$33*10+$G$33*50),0),IF(($E$35=$A19)*($I$35=$E$35),($F$35*10+$G$35*50),0),IF(($E$37=$A19)*($I$37=$E$37),($F$37*10+$G$37*50),0),IF(($E$39=$A19)*($I$39=$E$39),($F$39*10+$G$39*50),0),IF(($E$26=$A19)*($I$25=$E$26),($F$26*10+$G$26*50),0),IF(($E$28=$A19)*($I$27=$E$28),($F$28*10+$G$28*50),0),IF(($E$30=$A19)*($I$29=$E$30),($F$30*10+$G$30*50),0),IF(($E$32=$A19)*($I$31=$E$32),($F$32*10+$G$32*50),0),IF(($E$34=$A19)*($I$33=$E$34),($F$34*10+$G$34*50),0),IF(($E$36=$A19)*($I$35=$E$36),($F$36*10+$G$36*50),0),IF(($E$38=$A19)*($I$37=$E$38),($F$38*10+$G$38*50),0),IF(($E$40=$A19)*($I$39=$E$40),($F$40*10+$G$40*50),0)) -> 0 | E19: =B19+C19+D19 -> 0
A20: 【Miniworld】 | B20: =INDEX(D$3:D$10,MATCH(A20,A$3:A$10,0))*10 -> 0 | C20: =INDEX(F$3:F$10,MATCH(A20,A$3:A$10,0))*50 -> 0 | D20: =SUM(IF(($E$25=$A20)*($I$25=$E$25),($F$25*10+$G$25*50),0),IF(($E$27=$A20)*($I$27=$E$27),($F$27*10+$G$27*50),0),IF(($E$29=$A20)*($I$29=$E$29),($F$29*10+$G$29*50),0),IF(($E$31=$A20)*($I$31=$E$31),($F$31*10+$G$31*50),0),IF(($E$33=$A20)*($I$33=$E$33),($F$33*10+$G$33*50),0),IF(($E$35=$A20)*($I$35=$E$35),($F$35*10+$G$35*50),0),IF(($E$37=$A20)*($I$37=$E$37),($F$37*10+$G$37*50),0),IF(($E$39=$A20)*($I$39=$E$39),($F$39*10+$G$39*50),0),IF(($E$26=$A20)*($I$25=$E$26),($F$26*10+$G$26*50),0),IF(($E$28=$A20)*($I$27=$E$28),($F$28*10+$G$28*50),0),IF(($E$30=$A20)*($I$29=$E$30),($F$30*10+$G$30*50),0),IF(($E$32=$A20)*($I$31=$E$32),($F$32*10+$G$32*50),0),IF(($E$34=$A20)*($I$33=$E$34),($F$34*10+$G$34*50),0),IF(($E$36=$A20)*($I$35=$E$36),($F$36*10+$G$36*50),0),IF(($E$38=$A20)*($I$37=$E$38),($F$38*10+$G$38*50),0),IF(($E$40=$A20)*($I$39=$E$40),($F$40*10+$G$40*50),0)) -> 0 | E20: =B20+C20+D20 -> 0
A21: 【NikoFC】 | B21: =INDEX(D$3:D$10,MATCH(A21,A$3:A$10,0))*10 -> 0 | C21: =INDEX(F$3:F$10,MATCH(A21,A$3:A$10,0))*50 -> 0 | D21: =SUM(IF(($E$25=$A21)*($I$25=$E$25),($F$25*10+$G$25*50),0),IF(($E$27=$A21)*($I$27=$E$27),($F$27*10+$G$27*50),0),IF(($E$29=$A21)*($I$29=$E$29),($F$29*10+$G$29*50),0),IF(($E$31=$A21)*($I$31=$E$31),($F$31*10+$G$31*50),0),IF(($E$33=$A21)*($I$33=$E$33),($F$33*10+$G$33*50),0),IF(($E$35=$A21)*($I$35=$E$35),($F$35*10+$G$35*50),0),IF(($E$37=$A21)*($I$37=$E$37),($F$37*10+$G$37*50),0),IF(($E$39=$A21)*($I$39=$E$39),($F$39*10+$G$39*50),0),IF(($E$26=$A21)*($I$25=$E$26),($F$26*10+$G$26*50),0),IF(($E$28=$A21)*($I$27=$E$28),($F$28*10+$G$28*50),0),IF(($E$30=$A21)*($I$29=$E$30),($F$30*10+$G$30*50),0),IF(($E$32=$A21)*($I$31=$E$32),($F$32*10+$G$32*50),0),IF(($E$34=$A21)*($I$33=$E$34),($F$34*10+$G$34*50),0),IF(($E$36=$A21)*($I$35=$E$36),($F$36*10+$G$36*50),0),IF(($E$38=$A21)*($I$37=$E$38),($F$38*10+$G$38*50),0),IF(($E$40=$A21)*($I$39=$E$40),($F$40*10+$G$40*50),0)) -> 0 | E21: =B21+C21+D21 -> 0
A23: 对战表
A24: 比赛时间 | B24: 比赛服务器 | C24: 比赛裁判 | D24: 比赛轮次 | E24: 队伍 | F24: 得分 | G24: 胜利图数 | H24: 队伍总身价 | I24: 身价劣势队 | J24: 图一对战国家 | K24: 图二对战国家 | L24: 队伍上场人员1 | M24: 队伍上场人员2 | N24: 队伍上场人员3 | O24: 队伍上场人员4 | P24: 队伍上场人员5 | Q24: 队伍上场人员6 | R24: 队伍上场人员7 | S24: 队伍上场人员8 | T24: 队伍上场人员9 | U24: 队伍上场人员10 | V24: 队伍上场人员11 | W24: 队伍上场人员12 | X24: 队伍上场人员13 | Y24: 队伍上场人员14 | Z24: 队伍上场人员15
A25: 2024年8月9日 21:30:00 | B25: CFWL_1 | D25: 比赛1 | E25: 【Cbhz】 | H25: =SUMPRODUCT(SUMIF(队伍总览!B4:B19,L25:Z25,队伍总览!C4:C19)) -> 0 | I25: =IF(ABS(H25-H26)>200,IF(H25<H26,E25,E26),"均势") -> 均势 | J25: 诺德 Nord | K25: 萨兰德 Sarranid
E26: 【SSR】 | H26: {=SUMPRODUCT(SUMIF(队伍总览!F4:F19,L26:Z26,队伍总览!G4:G19))} -> 0 | J26: 罗多克 Rhodok | K26: 斯瓦迪亚 Swadia
A27: 2024年8月9日 21:30:00 | B27: CFWL_2 | D27: 比赛2 | E27: 【OldH】 | H27: {=SUMPRODUCT(SUMIF(队伍总览!J4:J19,L27:Z27,队伍总览!K4:K19))} -> 0 | I27: =IF(ABS(H27-H28)>200,IF(H27<H28,E27,E28),"均势") -> 均势 | J27: 诺德 Nord | K27: 萨兰德 Sarranid
E28: 【AWO】 | H28: {=SUMPRODUCT(SUMIF(队伍总览!N4:N19,L28:Z28,队伍总览!O4:O19))} -> 0 | J28: 罗多克 Rhodok | K28: 斯瓦迪亚 Swadia
A29: 2024年8月9日 21:30:00 | B29: CFWL_3 | D29: 比赛3 | E29: 【G2】 | H29: =SUMPRODUCT(SUMIF(队伍总览!B36:B51,L29:Z29,队伍总览!C36:C51)) -> 0 | I29: =IF(ABS(H29-H30)>200,IF(H29<H30,E29,E30),"均势") -> 均势 | J29: 诺德 Nord | K29: 萨兰德 Sarranid
E30: 【TV】 | H30: {=SUMPRODUCT(SUMIF(队伍总览!F36:F51,L30:Z30,队伍总览!G36:G51))} -> 0 | J30: 罗多克 Rhodok | K30: 斯瓦迪亚 Swadia
A31: 2024年8月9日 21:30:00 | B31: CFWL_4 | D31: 比赛4 | E31: 【Miniworld】 | H31: {=SUMPRODUCT(SUMIF(队伍总览!J36:J51,L31:Z31,队伍总览!K36:K51))} -> 0 | I31: =IF(ABS(H31-H32)>200,IF(H31<H32,E31,E32),"均势") -> 均势 | J31: 诺德 Nord | K31: 萨兰德 Sarranid
E32: 【NikoFC】 | H32: {=SUMPRODUCT(SUMIF(队伍总览!N36:N51,L32:Z32,队伍总览!O36:O51))} -> 0 | J32: 罗多克 Rhodok | K32: 斯瓦迪亚 Swadia
A33: 2024年8月10日 20:30:00 | B33: CFWL_1 | D33: 比赛5 | E33: =IF(AND(NOT(ISBLANK(F25)),NOT(ISBLANK(F26))),IF(F25>F26,E25,E26),"待定") -> 待定 | H33: =SUMPRODUCT(SUMIF(队伍总览!B4:B19,L33:Z33,队伍总览!C4:C19)) -> 0 | I33: =IF(ABS(H33-H34)>200,IF(H33<H34,E33,E34),"均势") -> 均势 | J33: 斯瓦迪亚 Swadia | K33: 萨兰德 Sarranid
E34: =IF(AND(NOT(ISBLANK(F27)),NOT(ISBLANK(F28))),IF(F27>F28,E27,E28),"待定") -> 待定 | H34: =SUMPRODUCT(SUMIF(队伍总览!F4:F19,L34:Z34,队伍总览!F4:F19)) -> 0 | J34: 维基亚 Veagir | K34: 诺德 Nord
A35: 2024年8月10日 20:30:00 | B35: CFWL_2 | D35: 比赛6 | E35: =IF(AND(NOT(ISBLANK(F25)),NOT(ISBLANK(F26))),IF(F25<=F26,E25,E26),"待定") -> 待定 | H35: =SUMPRODUCT(SUMIF(队伍总览!J4:J19,L35:Z35,队伍总览!J4:J19)) -> 0 | I35: =IF(ABS(H35-H36)>200,IF(H35<H36,E35,E36),"均势") -> 均势 | J35: 斯瓦迪亚 Swadia | K35: 萨兰德 Sarranid
E36: =IF(AND(NOT(ISBLANK(F27)),NOT(ISBLANK(F28))),IF(F27<=F28,E27,E28),"待定") -> 待定 | H36: =SUMPRODUCT(SUMIF(队伍总览!N4:N19,L36:Z36,队伍总览!N4:N19)) -> 0 | J36: 维基亚 Veagir | K36: 诺德 Nord
A37: 2024年8月10日 21:30:00 | B37: CFWL_1 | D37: 比赛7 | E37: =IF(AND(NOT(ISBLANK(F29)),NOT(ISBLANK(F30))),IF(F29>F30,E29,E30),"待定") -> 待定 | H37: =SUMPRODUCT(SUMIF(队伍总览!B36:B51,L37:Z37,队伍总览!C36:C51)) -> 0 | I37: =IF(ABS(H37-H38)>200,IF(H37<H38,E37,E38),"均势") -> 均势 | J37: 斯瓦迪亚 Swadia | K37: 萨兰德 Sarranid
E38: =IF(AND(NOT(ISBLANK(F31)),NOT(ISBLANK(F32))),IF(F31>F32,E31,E32),"待定") -> 待定 | H38: =SUMPRODUCT(SUMIF(队伍总览!F36:F51,L38:Z38,队伍总览!F36:F51)) -> 0 | J38: 维基亚 Veagir | K38: 诺德 Nord
A39: 2024年8月10日 21:30:00 | B39: CFWL_2 | D39: 比赛8 | E39: =IF(AND(NOT(ISBLANK(F29)),NOT(ISBLANK(F30))),IF(F29<=F30,E29,E30),"待定") -> 待定 | H39: =SUMPRODUCT(SUMIF(队伍总览!J36:J51,L39:Z39,队伍总览!J36:J51)) -> 0 | I39: =IF(ABS(H39-H40)>200,IF(H39<H40,E39,E40),"均势") -> 均势 | J39: 斯瓦迪亚 Swadia | K39: 萨兰德 Sarranid
E40: =IF(AND(NOT(ISBLANK(F31)),NOT(ISBLANK(F32))),IF(F31<=F32,E31,E32),"待定") -> 待定 | H40: =SUMPRODUCT(SUMIF(队伍总览!N36:N51,L40:Z40,队伍总览!N36:N51)) -> 0 | J40: 维基亚 Veagir | K40: 诺德 Nord

Sheet 报名表
